Workbook

Sheet UPSTREAM
A1: ZONA | B1: 45962 | C1: =+B1+1 -> 45963 | D1: =+C1+1 -> 45964 | E1: ACUMULADO S1 | F1: =+D1+1 -> 45965 | G1: =+F1+1 -> 45966 | H1: =+G1+1 -> 45967 | I1: =+H1+1 -> 45968 | J1: =+I1+1 -> 45969 | K1: =+J1+1 -> 45970 | L1: ACUMULADO S2 | M1: =+K1+1 -> 45971 | N1: =+M1+1 -> 45972 | O1: =+N1+1 -> 45973 | P1: =+O1+1 -> 45974 | Q1: =+P1+1 -> 45975 | R1: =+Q1+1 -> 45976 | S1: =+R1+1 -> 45977 | T1: =+S1+1 -> 45978 | U1: ACUMULADO S3 | V1: =+T1+1 -> 45979 | W1: =+V1+1 -> 45980 | X1: =+W1+1 -> 45981 | Y1: =+X1+1 -> 45982 | Z1: =+Y1+1 -> 45983 | AA1: =+Z1+1 -> 45984 | AB1: ACUMULADO S4 | AC1: =+AA1+1 -> 45985 | AD1: =+AC1+1 -> 45986 | AE1: =+AD1+1 -> 45987 | AF1: =+AE1+1 -> 45988 | AG1: =+AF1+1 -> 45989 | AH1: =+AG1+1 -> 45990 | AI1: =+AH1+1 -> 45991 | AJ1: ACUMULADO NOV 25
A2: Codazzi Proyección | B2: 660 | C2: 400 | D2: 100 | E2: =+SUM(B2:D2) -> 1160 | F2: 660 | G2: 766 | H2: 833 | I2: 829 | J2: 939 | K2: 505 | L2: =+E2+SUM(F2:K2) -> 5692 | M2: 750 | N2: 786 | O2: 861 | P2: 858 | Q2: 835 | R2: 881 | S2: 522 | T2: 100 | U2: =+L2+SUM(M2:T2) -> 11285 | V2: 660 | W2: 722 | X2: 793 | Y2: 800 | Z2: 825 | AA2: 485 | AB2: =+U2+SUM(V2:AA2) -> 15570 | AC2: 660 | AD2: 730 | AE2: 777 | AF2: 817 | AG2: 894 | AH2: 895 | AI2: 622 | AJ2: =+AB2+SUM(AC2:AI2) -> 20965
A3: Codazzi Real | B3: 468.94 | C3: 199.96 | D3: 100.83 | E3: =(+SUM(B3:D3))+0 -> 769.73 | F3: 622.96 | G3: 645.1 | H3: 909.68 | I3: 822.09 | J3: 727.1 | K3: 518.48 | L3: =(+E3+SUM(F3:K3))+0 -> 5015.14 | M3: 411.46 | N3: 637.91 | O3: 812.65 | P3: 698.12 | Q3: 727.82 | R3: 751.74 | S3: 206.05 | T3: 131.71 | U3: =+L3+SUM(M3:T3) -> 9392.6 | V3: 505.53 | W3: 598.18 | X3: 739.8 | Y3: 600.62 | Z3: 834.36 | AA3: 437.85 | AB3: =+U3+SUM(V3:AA3) -> 13108.94 | AC3: 281.57 | AD3: 768.8 | AE3: 708.92 | AF3: 798.89 | AG3: 694.12 | AH3: 743.4 | AI3: 0 | AJ3: =+AB3+SUM(AC3:AI3) -> 17104.64
A4: % Cumplimiento | B4: =IFERROR(+B3/B2,0) -> 0.71051515 | C4: =IFERROR(+C3/C2,0) -> 0.4999 | D4: =IFERROR(+D3/D2,0) -> 1.0083 | E4: =IFERROR(+E3/E2,0) -> 0.66356034 | F4: =IFERROR(+F3/F2,0) -> 0.94387879 | G4: =IFERROR(+G3/G2,0) -> 0.8421671 | H4: =IFERROR(+H3/H2,0) -> 1.0920528 | I4: =IFERROR(+I3/I2,0) -> 0.99166466 | ... AJ4: =IFERROR(+AJ3/AJ2,0) -> 0.81586644
A5: Ext Codazzi Proy | B5: 750 | C5: 600 | D5: 0 | E5: =+SUM(B5:D5) -> 1350 | F5: 400 | G5: 800 | H5: 800 | I5: 800 | J5: 800 | K5: 800 | L5: =+E5+SUM(F5:K5) -> 5750 | M5: 800 | N5: 800 | O5: 800 | P5: 800 | Q5: 800 | R5: 800 | S5: 800 | T5: 300 | U5: =+L5+SUM(M5:T5) -> 11650 | V5: 400 | W5: 800 | X5: 800 | Y5: 800 | Z5: 800 | AA5: 550 | AB5: =+U5+SUM(V5:AA5) -> 15800 | AC5: 400 | AD5: 800 | AE5: 800 | AF5: 800 | AG5: 800 | AH5: 800 | AI5: 800 | AJ5: =+AB5+SUM(AC5:AI5) -> 21000
A6: Ext Codazzi Real | B6: 792 | C6: 445.5 | D6: 82.5 | E6: =+SUM(B6:D6) -> 1320 | F6: 440 | G6: 770 | H6: 748 | I6: 770 | J6: 704 | K6: 756.25 | L6: =+E6+SUM(F6:K6) -> 5508.25 | M6: 484 | N6: 467.5 | O6: 715 | P6: 750.75 | Q6: 715 | R6: 761.75 | S6: 434.5 | T6: 66 | U6: =+L6+SUM(M6:T6) -> 9902.75 | V6: 448.25 | W6: 748 | X6: 717.75 | Y6: 739.75 | Z6: 783.75 | AA6: 698.5 | AB6: =+U6+SUM(V6:AA6) -> 14038.75 | AC6: 283.25 | AD6: 701.25 | AE6: 778.25 | AF6: 794.75 | AG6: 687.5 | AH6: 759 | AI6: 827.75 | AJ6: =+AB6+SUM(AC6:AI6) -> 18870.5 | AK6: =+AB6/AB5 -> 0.88852848 | AL6: =1-15% -> 0.85
A7: CPO | B7: 178.404 | C7: 129.388 | D7: 15.82 | E7: =+SUM(B7:D7) -> 323.612 | F7: 94.732 | G7: 173.188 | H7: 162.704 | I7: 167.148 | J7: 152.336 | K7: 165.82 | L7: =+E7+SUM(F7:K7) -> 1239.54 | M7: 118.468 | N7: 102.124 | O7: 158.132 | P7: 166.368 | Q7: 158.728 | R7: 172.136 | S7: 117.828 | T7: 7.204 | U7: =+L7+SUM(M7:T7) -> 2240.528 | V7: 105.896 | W7: 169.504 | X7: 159.052 | Y7: 156.82 | Z7: 171.728 | AA7: 152.332 | AB7: =+U7+SUM(V7:AA7) -> 3155.86 | AC7: 55.408 | AD7: 150.586 | AE7: 168.97 | AF7: 179.94 | AG7: 149.088 | AH7: 162.844 | AI7: 172.188 | AJ7: =+AB7+SUM(AC7:AI7) -> 4194.884
A8: =+_xlfn.CONCAT("TEA% ", B44,"%") -> TEA% 21.6% | B8: =IFERROR(+B7/B6,0) -> 0.22525758 | C8: =IFERROR(+C7/C6,0) -> 0.29043322 | D8: =IFERROR(+D7/D6,0) -> 0.19175758 | E8: =IFERROR(+E7/E6,0) -> 0.24516061 | F8: =IFERROR(+F7/F6,0) -> 0.2153 | G8: =IFERROR(+G7/G6,0) -> 0.22491948 | H8: =IFERROR(+H7/H6,0) -> 0.21751872 | I8: =IFERROR(+I7/I6,0) -> 0.21707532 | ... Y8: =IFERROR(+Y7/Y6,0) -> 0.21199054 | Z8: 0.216 | AA8: 0.216 | AB8: =IFERROR(+AB7/AB6,0) -> 0.22479637 | AC8: =IFERROR(+AC7/AC6,0) -> 0.19561518 | AD8: =IFERROR(+AD7/AD6,0) -> 0.21473939 | AE8: =IFERROR(+AE7/AE6,0) -> 0.21711532 | AF8: =IFERROR(+AF7/AF6,0) -> 0.22641082 | AG8: =IFERROR(+AG7/AG6,0) -> 0.21685527 | AH8: =IFERROR(+AH7/AH6,0) -> 0.21455072 | AI8: =IFERROR(+AI7/AI6,0) -> 0.20801933 | AJ8: =IFERROR(+AJ7/AJ6,0) -> 0.22229851
A9: MLB Proyección | B9: 94.655487 | C9: 14.173436 | D9: 32.637431 | E9: =+SUM(B9:D9) -> 141.46635 | F9: 166.05883 | G9: 169.35209 | H9: 249.83405 | I9: 256.49977 | J9: 235.237 | K9: 54.058434 | L9: =+E9+SUM(F9:K9) -> 1272.5065 | M9: 136.57775 | N9: 321.81108 | O9: 232.29977 | P9: 338.11913 | Q9: 349.59113 | R9: 208.25801 | S9: 51.497012 | T9: 36 | U9: =+L9+SUM(M9:T9) -> 2946.6604 | V9: 218.77072 | W9: 299.30221 | X9: 259.20953 | Y9: 263.83789 | Z9: 230.56908 | AA9: 52.604654 | AB9: =+U9+SUM(V9:AA9) -> 4270.9545 | AC9: 93.597293 | AD9: 253.12739 | AE9: 290.43119 | AF9: 228.73949 | AG9: 299.1242 | AH9: 352.67671 | AI9: 111.34923 | AJ9: =+AB9+SUM(AC9:AI9) -> 5900
A10: MLB Real | B10: 145.379 | C10: 19.21 | D10: 43.35 | E10: =+SUM(B10:D10) -> 207.939 | F10: 164.193 | G10: 164.606 | H10: 222.894 | I10: 240.759 | J10: 222.351 | K10: 21.47 | L10: =+E10+SUM(F10:K10) -> 1244.212 | M10: 112.081 | N10: 238.419 | O10: 250.165 | P10: 219.426 | Q10: 305.847 | R10: 299.673 | S10: 41.21 | T10: 92.33 | U10: =+L10+SUM(M10:T10) -> 2803.363 | V10: 128.446 | W10: 228.079 | X10: 217.448 | Y10: 310.473 | Z10: 301.944 | AA10: 36.65 | AB10: =+U10+SUM(V10:AA10) -> 4026.403 | AC10: 114.74 | AD10: 187.489 | AE10: 321.125 | AF10: 300.012 | AG10: 333.916 | AH10: 345.856 | AI10: 0 | AJ10: =+AB10+SUM(AC10:AI10) -> 5629.541
A11: % Cumplimiento | B11: =IFERROR(+B10/B9,0) -> 1.535875 | C11: =IFERROR(+C10/C9,0) -> 1.3553523 | D11: =IFERROR(+D10/D9,0) -> 1.3282295 | E11: =IFERROR(+E10/E9,0) -> 1.4698831 | F11: =IFERROR(+F10/F9,0) -> 0.98876405 | G11: =IFERROR(+G10/G9,0) -> 0.97197504 | H11: =IFERROR(+H10/H9,0) -> 0.89216822 | I11: =IFERROR(+I10/I9,0) -> 0.93863243 | ... AJ11: =IFERROR(+AJ10/AJ9,0) -> 0.95415949
A12: Ext MLB Proy | B12: 150 | C12: 50 | D12: 0 | E12: =+SUM(B12:D12) -> 200 | F12: 0 | G12: 0 | H12: 0 | I12: 0 | J12: 0 | K12: 0 | L12: =+E12+SUM(F12:K12) -> 200 | M12: 0 | N12: 0 | O12: 0 | P12: 200 | Q12: 350 | R12: 350 | S12: 350 | T12: 0 | U12: =+L12+SUM(M12:T12) -> 1450 | V12: 300 | W12: 300 | X12: 300 | Y12: 350 | Z12: 350 | AA12: 0 | AB12: =+U12+SUM(V12:AA12) -> 3050 | AC12: 100 | AD12: 300 | AE12: 300 | AF12: 300 | AG12: 300 | AH12: 300 | AI12: 250 | AJ12: =+AB12+SUM(AC12:AI12) -> 4900
A13: Ext MLB Real | B13: 300.9 | C13: 0 | D13: 0 | E13: =+SUM(B13:D13) -> 300.9 | F13: 0 | G13: 0 | H13: 0 | I13: 0 | J13: 0 | K13: 0 | L13: =+E13+SUM(F13:K13) -> 300.9 | M13: 0 | N13: 0 | O13: 0 | P13: 0 | Q13: 484.5 | R13: 402.9 | S13: 321.3 | T13: 147.9 | U13: =+L13+SUM(M13:T13) -> 1657.5 | V13: 0 | W13: 260.1 | X13: 321.3 | Y13: 372.3 | Z13: 326.4 | AA13: 0 | AB13: =+U13+SUM(V13:AA13) -> 2937.6 | AC13: 0 | AD13: 321.3 | AE13: 362.1 | AF13: 336.6 | AG13: 326.4 | AH13: 275.4 | AI13: 132.6 | AJ13: =+AB13+SUM(AC13:AI13) -> 4692 | AK13: =+AB13/AB12 -> 0.96314754
A14: CPO | B14: 57.126 | C14: 0 | D14: 0 | E14: =+SUM(B14:D14) -> 57.126 | F14: 0 | G14: 0 | H14: 0 | I14: 0 | J14: 0 | K14: 0 | L14: =+E14+SUM(F14:K14) -> 57.126 | M14: 0 | N14: 0 | O14: 0 | P14: 0 | Q14: 85.274 | R14: 71.203 | S14: 60.051 | T14: 28.189 | U14: =+L14+SUM(M14:T14) -> 301.843 | V14: 0 | W14: 54.326 | X14: 55.141 | Y14: 78.318 | Z14: 58.251 | AA14: 0 | AB14: =+U14+SUM(V14:AA14) -> 547.879 | AC14: 0 | AD14: 60.032 | AE14: 75.548 | AF14: 63.188 | AG14: 61.455 | AH14: 38.824 | AI14: 25.205 | AJ14: =+AB14+SUM(AC14:AI14) -> 872.131
A15: =+_xlfn.CONCAT("TEA% ", B45,"%") -> TEA% 18.8% | B15: =IFERROR(+B14/B13,0) -> 0.18985045 | C15: =IFERROR(+C14/C13,0) -> 0 | D15: =IFERROR(+D14/D13,0) -> 0 | E15: =IFERROR(+E14/E13,0) -> 0.18985045 | F15: =IFERROR(+F14/F13,0) -> 0 | G15: =IFERROR(+G14/G13,0) -> 0 | H15: =IFERROR(+H14/H13,0) -> 0 | I15: =IFERROR(+I14/I13,0) -> 0 | ... N15: =IFERROR(+N14/N13,0) -> 0 | O15: 0.1964 | P15: =IFERROR(+P14/P13,0) -> 0 | Q15: =IFERROR(+Q14/Q13,0) -> 0.17600413 | R15: =IFERROR(+R14/R13,0) -> 0.17672623 | S15: =IFERROR(+S14/S13,0) -> 0.18690009 | T15: =IFERROR(+T14/T13,0) -> 0.190595 | U15: =IFERROR(+U14/U13,0) -> 0.18210739 | V15: =IFERROR(+V14/V13,0) -> 0 | W15: =IFERROR(+W14/W13,0) -> 0.20886582 | ... Y15: =IFERROR(+Y14/Y13,0) -> 0.21036261 | Z15: 0.188 | AA15: =IFERROR(+AA14/AA13,0) -> 0 | AB15: =IFERROR(+AB14/AB13,0) -> 0.18650565 | AC15: =IFERROR(+AC14/AC13,0) -> 0 | AD15: =IFERROR(+AD14/AD13,0) -> 0.18684096 | AE15: =IFERROR(+AE14/AE13,0) -> 0.2086385 | AF15: =IFERROR(+AF14/AF13,0) -> 0.1877243 | AG15: =IFERROR(+AG14/AG13,0) -> 0.18828125 | AH15: =IFERROR(+AH14/AH13,0) -> 0.14097313 | ... AJ15: =IFERROR(+AJ14/AJ13,0) -> 0.18587617
A16: Córdoba Proyección | B16: 150 | C16: 20 | D16: 30 | E16: =+SUM(B16:D16) -> 200 | F16: 240 | G16: 260 | H16: 280 | I16: 280 | J16: 290 | K16: 30 | L16: =+E16+SUM(F16:K16) -> 1580 | M16: 90 | N16: 200 | O16: 260 | P16: 97.724 | Q16: 270 | R16: 300 | S16: 30 | T16: 50 | U16: =+L16+SUM(M16:T16) -> 2877.724 | V16: 260 | W16: 270 | X16: 280 | Y16: 290 | Z16: 300 | AA16: 40 | AB16: =+U16+SUM(V16:AA16) -> 4317.724 | AC16: 90 | AD16: 250 | AE16: 260 | AF16: 280 | AG16: 290 | AH16: 330 | AI16: 60 | AJ16: =+AB16+SUM(AC16:AI16) -> 5877.724
A17: Córdoba Real | B17: 229.91 | C17: 33.44 | D17: 10.21 | E17: =+SUM(B17:D17) -> 273.56 | F17: 88.88 | G17: 206.9 | H17: 298.24 | I17: 232.48 | J17: 302.01 | K17: 32.44 | L17: =+E17+SUM(F17:K17) -> 1434.51 | M17: 107.63 | N17: 227.73 | O17: 347.96 | P17: 266.59 | Q17: 291.67 | R17: 319.93 | S17: 64.03 | T17: 12.43 | U17: =+L17+SUM(M17:T17) -> 3072.48 | V17: 135.35 | W17: 232.14 | X17: 315.83 | Y17: 289.95 | Z17: 356.46 | AA17: 28.5 | AB17: =+U17+SUM(V17:AA17) -> 4430.71 | AC17: 81.84 | AD17: 307.27 | AE17: 302.04 | AF17: 270.98 | AG17: 255.17 | AH17: 320.61 | AI17: 0 | AJ17: =+AB17+SUM(AC17:AI17) -> 5968.62
A18: % Cumplimiento | B18: =IFERROR(+B17/B16,0) -> 1.5327333 | C18: =IFERROR(+C17/C16,0) -> 1.672 | D18: =IFERROR(+D17/D16,0) -> 0.34033333 | E18: =IFERROR(+E17/E16,0) -> 1.3678 | F18: =IFERROR(+F17/F16,0) -> 0.37033333 | G18: =IFERROR(+G17/G16,0) -> 0.79576923 | H18: =IFERROR(+H17/H16,0) -> 1.0651429 | I18: =IFERROR(+I17/I16,0) -> 0.83028571 | ... L18: =IFERROR(+L17/L16,0) -> 0.90791772 | M18: 0.51 | N18: =IFERROR(+N17/N16,0) -> 1.13865 | O18: =IFERROR(+O17/O16,0) -> 1.3383077 | P18: =IFERROR(+P17/P16,0) -> 2.727989 | Q18: =IFERROR(+Q17/Q16,0) -> 1.0802593 | R18: =IFERROR(+R17/R16,0) -> 1.0664333 | S18: =IFERROR(+S17/S16,0) -> 2.1343333 | T18: =IFERROR(+T17/T16,0) -> 0.2486 | U18: =IFERROR(+U17/U16,0) -> 1.0676771 | ... AJ18: =IFERROR(+AJ17/AJ16,0) -> 1.0154645
A19: Ext SINÚ Proy | B19: 300 | C19: 0 | D19: 0 | E19: =+SUM(B19:D19) -> 300 | F19: 200 | G19: 340 | H19: 340 | I19: 340 | J19: 340 | K19: 0 | L19: =+E19+SUM(F19:K19) -> 1860 | M19: 200 | N19: 320 | O19: 320 | P19: 320 | Q19: 320 | R19: 320 | S19: 140 | T19: 0 | U19: =+L19+SUM(M19:T19) -> 3800 | V19: 100 | W19: 300 | X19: 300 | Y19: 300 | Z19: 300 | AA19: 0 | AB19: =+U19+SUM(V19:AA19) -> 5100 | AC19: 100 | AD19: 250 | AE19: 250 | AF19: 270 | AG19: 270 | AH19: 300 | AI19: 0 | AJ19: =+AB19+SUM(AC19:AI19) -> 6540
A20: Ext SINÚ Real | B20: 324 | C20: 0 | D20: 0 | E20: =+SUM(B20:D20) -> 324 | F20: 256.5 | G20: 297 | H20: 297 | I20: 324 | J20: 378 | K20: 256.5 | L20: =+E20+SUM(F20:K20) -> 2133 | M20: 108 | N20: 256.5 | O20: 364.5 | P20: 283.5 | Q20: 270 | R20: 283.5 | S20: 0 | T20: 0 | U20: =+L20+SUM(M20:T20) -> 3699 | V20: 189 | W20: 256.5 | X20: 270 | Y20: 297 | Z20: 324 | AA20: 0 | AB20: =+U20+SUM(V20:AA20) -> 5035.5 | AC20: 0 | AD20: 337.5 | AE20: 283.5 | AF20: 283.5 | AG20: 270 | AH20: 310.5 | AI20: 0 | AJ20: =+AB20+SUM(AC20:AI20) -> 6520.5 | AK20: =+AB20/AB19 -> 0.98735294
A21: CPO | B21: 79.723 | C21: 0 | D21: 0 | E21: =+SUM(B21:D21) -> 79.723 | F21: 58.423 | G21: 61.553 | H21: 62.169 | I21: 71.149 | J21: 78.271 | K21: 57.357 | L21: =+E21+SUM(F21:K21) -> 468.645 | M21: 25.05 | N21: 50.855 | O21: 80.737 | P21: 76.18 | Q21: 64.752 | R21: 55.966 | S21: 0 | T21: 0 | U21: =+L21+SUM(M21:T21) -> 822.185 | V21: 40.316 | W21: 56.864 | X21: 55.694 | Y21: 64.006 | Z21: 71.571 | AA21: 0 | AB21: =+U21+SUM(V21:AA21) -> 1110.636 | AC21: 0 | AD21: 62.039 | AE21: 63.568 | AF21: 68.909 | AG21: 62.672 | AH21: 68.671 | AI21: 0 | AJ21: =+AB21+SUM(AC21:AI21) -> 1436.495
A22: =+_xlfn.CONCAT("TEA% ", B47,"%") -> TEA% 22% | B22: =IFERROR(+B21/B20,0) -> 0.24605864 | C22: =IFERROR(+C21/C20,0) -> 0 | D22: =IFERROR(+D21/D20,0) -> 0 | E22: =IFERROR(+E21/E20,0) -> 0.24605864 | F22: =IFERROR(+F21/F20,0) -> 0.22776998 | G22: =IFERROR(+G21/G20,0) -> 0.20724916 | H22: =IFERROR(+H21/H20,0) -> 0.20932323 | I22: =IFERROR(+I21/I20,0) -> 0.21959568 | ... AJ22: =IFERROR(+AJ21/AJ20,0) -> 0.22030442
A23: A&G Proyección | B23: 620 | C23: 140 | D23: 300 | E23: =+SUM(B23:D23) -> 1060 | F23: 680 | G23: 840 | H23: 860 | I23: 810 | J23: 770 | K23: 140 | L23: =+E23+SUM(F23:K23) -> 5160 | M23: 270 | N23: 710 | O23: 870 | P23: 960 | Q23: 900 | R23: 910 | S23: 140 | T23: 350 | U23: =+L23+SUM(M23:T23) -> 10270 | V23: 740 | W23: 1020 | X23: 970 | Y23: 970 | Z23: 870 | AA23: 170 | AB23: =+U23+SUM(V23:AA23) -> 15010 | AC23: 470 | AD23: 720 | AE23: 1000 | AF23: 1020 | AG23: 1030 | AH23: 950 | AI23: 300 | AJ23: =+AB23+SUM(AC23:AI23) -> 20500
A24: A&G Real | B24: 834.63 | C24: 441.4 | D24: 184.62 | E24: =+SUM(B24:D24) -> 1460.65 | F24: 931.38 | G24: 1028.96 | H24: 988.72 | I24: 955.49 | J24: 787.16 | K24: 211.26 | L24: =+E24+SUM(F24:K24) -> 6363.62 | M24: 534.96 | N24: 997.82 | O24: 821.3 | P24: 909.22 | Q24: 695.48 | R24: 783.92 | S24: 517.98 | T24: 190.51 | U24: =+L24+SUM(M24:T24) -> 11814.81 | V24: 833.41 | W24: 981.51 | X24: 1148.39 | Y24: 952.72 | Z24: 686.56 | AA24: 352.29 | AB24: =+U24+SUM(V24:AA24) -> 16769.69 | AC24: 586.63 | AD24: 813.66 | AE24: 577.01 | AF24: 826.88 | AG24: 820.93 | AH24: 893.84 | AI24: 0 | AJ24: =+AB24+SUM(AC24:AI24) -> 21288.64
A25: % Cumplimiento | B25: =IFERROR(+B24/B23,0) -> 1.3461774 | C25: =IFERROR(+C24/C23,0) -> 3.1528571 | D25: =IFERROR(+D24/D23,0) -> 0.6154 | E25: =IFERROR(+E24/E23,0) -> 1.3779717 | F25: =IFERROR(+F24/F23,0) -> 1.3696765 | G25: =IFERROR(+G24/G23,0) -> 1.2249524 | H25: =IFERROR(+H24/H23,0) -> 1.1496744 | I25: =IFERROR(+I24/I23,0) -> 1.1796173 | ... AJ25: =IFERROR(+AJ24/AJ23,0) -> 1.0384702
A26: Ext A&GC Proy | B26: 750 | C26: 250 | D26: 0 | E26: =+SUM(B26:D26) -> 1000 | F26: 800 | G26: 800 | H26: 800 | I26: 800 | J26: 800 | K26: 300 | L26: =+E26+SUM(F26:K26) -> 5300 | M26: 400 | N26: 700 | O26: 800 | P26: 800 | Q26: 800 | R26: 900 | S26: 400 | T26: 400 | U26: =+L26+SUM(M26:T26) -> 10500 | V26: 700 | W26: 900 | X26: 900 | Y26: 900 | Z26: 900 | AA26: 300 | AB26: =+U26+SUM(V26:AA26) -> 15100 | AC26: 400 | AD26: 900 | AE26: 900 | AF26: 900 | AG26: 900 | AH26: 900 | AI26: 700 | AJ26: =+AB26+SUM(AC26:AI26) -> 20700
A27: Ext A&GC Real | B27: 761.007 | C27: 865.344 | D27: 202.5 | E27: =+SUM(B27:D27) -> 1828.851 | F27: 814.5 | G27: 814.45 | H27: 933.57 | I27: 790.064 | J27: 852.242 | K27: 512.848 | L27: =+E27+SUM(F27:K27) -> 6546.525 | M27: 709.483 | N27: 749.822 | O27: 889.59 | P27: 278.46 | Q27: 794.816 | R27: 830.088 | S27: 904.256 | T27: 128.072 | U27: =+L27+SUM(M27:T27) -> 11831.112 | V27: 789.399 | W27: 903.474 | X27: 890.37 | Y27: 809.067 | Z27: 842.12 | AA27: 632.311 | AB27: =+U27+SUM(V27:AA27) -> 16697.853 | AC27: 158.305 | AD27: 622.117 | AE27: 789.36 | AF27: 751.15 | AG27: 846.362 | AH27: 935.446 | AI27: 817.939 | AJ27: =+AB27+SUM(AC27:AI27) -> 21618.532 | AK27: =+AB27/AB26 -> 1.1058181
A28: CPO | B28: 175.641 | C28: 211.041 | D28: 54.123 | E28: =+SUM(B28:D28) -> 440.805 | F28: 184.801 | G28: 195.577 | H28: 208.157 | I28: 172.813 | J28: 216.767 | K28: 119.003 | L28: =+E28+SUM(F28:K28) -> 1537.923 | M28: 164.663 | N28: 196.83 | O28: 191.908 | P28: 64.728 | Q28: 154.547 | R28: 205.935 | S28: 210.373 | T28: 58.131 | U28: =+L28+SUM(M28:T28) -> 2785.038 | V28: 163.661 | W28: 223.703 | X28: 216.324 | Y28: 193.262 | Z28: 190.17 | AA28: 137.317 | AB28: =+U28+SUM(V28:AA28) -> 3909.475 | AC28: 44.347 | AD28: 124.756 | AE28: 190.364 | AF28: 169.712 | AG28: 211.454 | AH28: 229.004 | AI28: 178.503 | AJ28: =+AB28+SUM(AC28:AI28) -> 5057.615
A29: =+_xlfn.CONCAT("TEA% ", B46,"%") -> TEA% 23.5% | B29: =IFERROR(+B28/B27,0) -> 0.23080077 | C29: =IFERROR(+C28/C27,0) -> 0.24388105 | D29: =IFERROR(+D28/D27,0) -> 0.26727407 | E29: =IFERROR(+E28/E27,0) -> 0.24102838 | F29: =IFERROR(+F28/F27,0) -> 0.22688889 | G29: =IFERROR(+G28/G27,0) -> 0.24013383 | H29: =IFERROR(+H28/H27,0) -> 0.22296882 | I29: =IFERROR(+I28/I27,0) -> 0.21873291 | ... Y29: =IFERROR(+Y28/Y27,0) -> 0.2388702 | Z29: =+U29 -> 0.23539951 | AA29: =+U29 -> 0.23539951 | AB29: =IFERROR(+AB28/AB27,0) -> 0.2341304 | AC29: =IFERROR(+AC28/AC27,0) -> 0.28013645 | AD29: =IFERROR(+AD28/AD27,0) -> 0.20053463 | AE29: =IFERROR(+AE28/AE27,0) -> 0.24116246 | AF29: =IFERROR(+AF28/AF27,0) -> 0.22593623 | AG29: =IFERROR(+AG28/AG27,0) -> 0.24983872 | AH29: =IFERROR(+AH28/AH27,0) -> 0.24480729 | AI29: =IFERROR(+AI28/AI27,0) -> 0.2182351 | AJ29: =IFERROR(+AJ28/AJ27,0) -> 0.23394812
A30: TOTAL Proyección | B30: =B2+B9+B16+B23 -> 1524.6555 | C30: =C2+C9+C16+C23 -> 574.17344 | D30: =D2+D9+D16+D23 -> 462.63743 | E30: =+SUM(B30:D30) -> 2561.4664 | F30: =F2+F9+F16+F23 -> 1746.0588 | G30: =G2+G9+G16+G23 -> 2035.3521 | H30: =H2+H9+H16+H23 -> 2222.8341 | I30: =I2+I9+I16+I23 -> 2175.4998 | J30: =J2+J9+J16+J23 -> 2234.237 | K30: =K2+K9+K16+K23 -> 729.05843 | L30: =+E30+SUM(F30:K30) -> 13704.507 | M30: =M2+M9+M16+M23 -> 1246.5778 | N30: =N2+N9+N16+N23 -> 2017.8111 | O30: =O2+O9+O16+O23 -> 2223.2998 | P30: =P2+P9+P16+P23 -> 2253.8431 | Q30: =Q2+Q9+Q16+Q23 -> 2354.5911 | R30: =R2+R9+R16+R23 -> 2299.258 | S30: =S2+S9+S16+S23 -> 743.49701 | T30: =T2+T9+T16+T23 -> 536 | U30: =+L30+SUM(M30:S30) -> 26843.384 | V30: =V2+V9+V16+V23 -> 1878.7707 | W30: =W2+W9+W16+W23 -> 2311.3022 | X30: =X2+X9+X16+X23 -> 2302.2095 | Y30: =Y2+Y9+Y16+Y23 -> 2323.8379 | Z30: =Z2+Z9+Z16+Z23 -> 2225.5691 | AA30: =AA2+AA9+AA16+AA23 -> 747.60465 | AB30: =+U30+SUM(V30:AA30) -> 38632.678 | AC30: =AC2+AC9+AC16+AC23 -> 1313.5973 | AD30: =AD2+AD9+AD16+AD23 -> 1953.1274 | AE30: =AE2+AE9+AE16+AE23 -> 2327.4312 | AF30: =AF2+AF9+AF16+AF23 -> 2345.7395 | AG30: =AG2+AG9+AG16+AG23 -> 2513.1242 | AH30: =AH2+AH9+AH16+AH23 -> 2527.6767 | AI30: =AI2+AI9+AI16+AI23 -> 1093.3492 | AJ30: =+AB30+SUM(AC30:AI30) -> 52706.724 | AK30: =+AJ33-AJ19 -> 46600 | AL30: Proyección inicio mes Fruta procesada sin Sinú
A31: TOTAL Real | B31: =B3+B10+B17+B24 -> 1678.859 | C31: =C3+C10+C17+C24 -> 694.01 | D31: =D3+D10+D17+D24 -> 339.01 | E31: =+SUM(B31:D31) -> 2711.879 | F31: =F3+F10+F17+F24 -> 1807.413 | G31: =G3+G10+G17+G24 -> 2045.566 | H31: =H3+H10+H17+H24 -> 2419.534 | I31: =I3+I10+I17+I24 -> 2250.819 | J31: =J3+J10+J17+J24 -> 2038.621 | K31: =K3+K10+K17+K24 -> 783.65 | L31: =+E31+SUM(F31:K31) -> 14057.482 | M31: =M3+M10+M17+M24 -> 1166.131 | N31: =N3+N10+N17+N24 -> 2101.879 | O31: =O3+O10+O17+O24 -> 2232.075 | P31: =P3+P10+P17+P24 -> 2093.356 | Q31: =Q3+Q10+Q17+Q24 -> 2020.817 | R31: =R3+R10+R17+R24 -> 2155.263 | S31: =S3+S10+S17+S24 -> 829.27 | T31: =T3+T10+T17+T24 -> 426.98 | U31: =+L31+SUM(M31:T31) -> 27083.253 | V31: =V3+V10+V17+V24 -> 1602.736 | W31: =W3+W10+W17+W24 -> 2039.909 | X31: =X3+X10+X17+X24 -> 2421.468 | Y31: =Y3+Y10+Y17+Y24 -> 2153.763 | Z31: =Z3+Z10+Z17+Z24 -> 2179.324 | AA31: =AA3+AA10+AA17+AA24 -> 855.29 | AB31: =+U31+SUM(V31:AA31) -> 38335.743 | AC31: =AC3+AC10+AC17+AC24 -> 1064.78 | AD31: =AD3+AD10+AD17+AD24 -> 2077.219 | AE31: =AE3+AE10+AE17+AE24 -> 1909.095 | AF31: =AF3+AF10+AF17+AF24 -> 2196.762 | AG31: =AG3+AG10+AG17+AG24 -> 2104.136 | AH31: =AH3+AH10+AH17+AH24 -> 2303.706 | AI31: =AI3+AI10+AI17+AI24 -> 0 | AJ31: =+AB31+SUM(AC31:AI31) -> 49991.441 | AK31: =+AJ34-AJ20 -> 45181.032 | AL31: Cierre Fruta procesada sin Sinú
A32: % Cumplimiento | B32: =IFERROR(+B31/B30,0) -> 1.1011399 | C32: =IFERROR(+C31/C30,0) -> 1.2087114 | D32: =IFERROR(+D31/D30,0) -> 0.73277685 | E32: =IFERROR(+E31/E30,0) -> 1.0587213 | F32: =IFERROR(+F31/F30,0) -> 1.0351387 | G32: =IFERROR(+G31/G30,0) -> 1.0050183 | H32: =IFERROR(+H31/H30,0) -> 1.0884906 | I32: =IFERROR(+I31/I30,0) -> 1.0346216 | ... AJ32: =IFERROR(+AJ31/AJ30,0) -> 0.94848318 | AK32: =+AK31-AK30 -> -1418.968 | AL32: Diferencia
A33: TOTAL Proyección | B33: =B5+B12+B19+B26 -> 1950 | C33: =C5+C12+C19+C26 -> 900 | D33: =D5+D12+D19+D26 -> 0 | E33: =+SUM(B33:D33) -> 2850 | F33: =F5+F12+F19+F26 -> 1400 | G33: =G5+G12+G19+G26 -> 1940 | H33: =H5+H12+H19+H26 -> 1940 | I33: =I5+I12+I19+I26 -> 1940 | J33: =J5+J12+J19+J26 -> 1940 | K33: =K5+K12+K19+K26 -> 1100 | L33: =+E33+SUM(F33:K33) -> 13110 | M33: =M5+M12+M19+M26 -> 1400 | N33: =N5+N12+N19+N26 -> 1820 | O33: =O5+O12+O19+O26 -> 1920 | P33: =P5+P12+P19+P26 -> 2120 | Q33: =Q5+Q12+Q19+Q26 -> 2270 | R33: =R5+R12+R19+R26 -> 2370 | S33: =S5+S12+S19+S26 -> 1690 | T33: =T5+T12+T19+T26 -> 700 | U33: =+L33+SUM(M33:T33) -> 27400 | V33: =V5+V12+V19+V26 -> 1500 | W33: =W5+W12+W19+W26 -> 2300 | X33: =X5+X12+X19+X26 -> 2300 | Y33: =Y5+Y12+Y19+Y26 -> 2350 | Z33: =Z5+Z12+Z19+Z26 -> 2350 | AA33: =AA5+AA12+AA19+AA26 -> 850 | AB33: =+U33+SUM(V33:AA33) -> 39050 | AC33: =AC5+AC12+AC19+AC26 -> 1000 | AD33: =AD5+AD12+AD19+AD26 -> 2250 | AE33: =AE5+AE12+AE19+AE26 -> 2250 | AF33: =AF5+AF12+AF19+AF26 -> 2270 | AG33: =AG5+AG12+AG19+AG26 -> 2270 | AH33: =AH5+AH12+AH19+AH26 -> 2300 | AI33: =AI5+AI12+AI19+AI26 -> 1750 | AJ33: =+AB33+SUM(AC33:AI33) -> 53140 | AK33: =+AJ5+AJ12+AJ19+AJ26 -> 53140
A34: RFF Procesada | B34: =+B27+B13+B20+B6 -> 2177.907 | C34: =+C27+C13+C20+C6 -> 1310.844 | D34: =+D27+D13+D20+D6 -> 285 | E34: =+SUM(B34:D34) -> 3773.751 | F34: =+F27+F13+F20+F6 -> 1511 | G34: =+G27+G13+G20+G6 -> 1881.45 | H34: =+H27+H13+H20+H6 -> 1978.57 | I34: =+I27+I13+I20+I6 -> 1884.064 | J34: =+J27+J13+J20+J6 -> 1934.242 | K34: =+K27+K13+K20+K6 -> 1525.598 | L34: =+E34+SUM(F34:K34) -> 14488.675 | M34: =+M27+M13+M20+M6 -> 1301.483 | N34: =+N27+N13+N20+N6 -> 1473.822 | O34: =+O27+O13+O20+O6 -> 1969.09 | P34: =+P27+P13+P20+P6 -> 1312.71 | Q34: =+Q27+Q13+Q20+Q6 -> 2264.316 | R34: =+R27+R13+R20+R6 -> 2278.238 | S34: =+S27+S13+S20+S6 -> 1660.056 | T34: =+T27+T13+T20+T6 -> 341.972 | U34: =+L34+SUM(M34:T34) -> 27090.362 | V34: =+V27+V13+V20+V6 -> 1426.649 | W34: =+W27+W13+W20+W6 -> 2168.074 | X34: =+X27+X13+X20+X6 -> 2199.42 | Y34: =+Y27+Y13+Y20+Y6 -> 2218.117 | Z34: =+Z27+Z13+Z20+Z6 -> 2276.27 | AA34: =+AA27+AA13+AA20+AA6 -> 1330.811 | AB34: =+U34+SUM(V34:AA34) -> 38709.703 | AC34: =+AC27+AC13+AC20+AC6 -> 441.555 | AD34: =+AD27+AD13+AD20+AD6 -> 1982.167 | AE34: =+AE27+AE13+AE20+AE6 -> 2213.21 | AF34: =+AF27+AF13+AF20+AF6 -> 2166 | AG34: =+AG27+AG13+AG20+AG6 -> 2130.262 | AH34: =+AH27+AH13+AH20+AH6 -> 2280.346 | AI34: =+AI27+AI13+AI20+AI6 -> 1778.289 | AJ34: =+AB34+SUM(AC34:AI34) -> 51701.532 | AK34: =+AJ6+AJ13+AJ20+AJ27 -> 51701.532
A35: CPO Real | B35: =B7+B14+B21+B28 -> 490.894 | C35: =C7+C14+C21+C28 -> 340.429 | D35: =D7+D14+D21+D28 -> 69.943 | E35: =+SUM(B35:D35) -> 901.266 | F35: =F7+F14+F21+F28 -> 337.956 | G35: =G7+G14+G21+G28 -> 430.318 | H35: =H7+H14+H21+H28 -> 433.03 | I35: =I7+I14+I21+I28 -> 411.11 | J35: =J7+J14+J21+J28 -> 447.374 | K35: =K7+K14+K21+K28 -> 342.18 | L35: =+E35+SUM(F35:K35) -> 3303.234 | M35: =M7+M14+M21+M28 -> 308.181 | N35: =N7+N14+N21+N28 -> 349.809 | O35: =O7+O14+O21+O28 -> 430.777 | P35: =P7+P14+P21+P28 -> 307.276 | Q35: =Q7+Q14+Q21+Q28 -> 463.301 | R35: =R7+R14+R21+R28 -> 505.24 | S35: =S7+S14+S21+S28 -> 388.252 | T35: =T7+T14+T21+T28 -> 93.524 | U35: =+L35+SUM(M35:T35) -> 6149.594 | V35: =V7+V14+V21+V28 -> 309.873 | W35: =W7+W14+W21+W28 -> 504.397 | X35: =X7+X14+X21+X28 -> 486.211 | Y35: =Y7+Y14+Y21+Y28 -> 492.406 | Z35: =Z7+Z14+Z21+Z28 -> 491.72 | AA35: =AA7+AA14+AA21+AA28 -> 289.649 | AB35: =+U35+SUM(V35:AA35) -> 8723.85 | AC35: =AC7+AC14+AC21+AC28 -> 99.755 | AD35: =AD7+AD14+AD21+AD28 -> 397.413 | AE35: =AE7+AE14+AE21+AE28 -> 498.45 | AF35: =AF7+AF14+AF21+AF28 -> 481.749 | AG35: =AG7+AG14+AG21+AG28 -> 484.669 | AH35: =AH7+AH14+AH21+AH28 -> 499.343 | AI35: =AI7+AI14+AI21+AI28 -> 375.896 | AJ35: =+AB35+SUM(AC35:AI35) -> 11561.125 | AK35: =+AJ7+AJ14+AJ21+AJ28 -> 11561.125
A36: TEA% 21,5% | B36: =IFERROR(+B35/B34,0) -> 0.22539714 | C36: =IFERROR(+C35/C34,0) -> 0.25970215 | D36: =IFERROR(+D35/D34,0) -> 0.24541404 | E36: =IFERROR(+E35/E34,0) -> 0.23882498 | F36: =IFERROR(+F35/F34,0) -> 0.2236638 | G36: =IFERROR(+G35/G34,0) -> 0.22871615 | H36: =IFERROR(+H35/H34,0) -> 0.21886009 | I36: =IFERROR(+I35/I34,0) -> 0.21820384 | ... AJ36: =IFERROR(+AJ35/AJ34,0) -> 0.22361281
A37: Proyección CPO | B37: =+B26*$A$42+B12*$A$41+B19*$A$43+B5*$A$40 -> 432.45 | C37: =+C26*$A$42+C12*$A$41+C19*$A$43+C5*$A$40 -> 197.75 | D37: =+D26*$A$42+D12*$A$41+D19*$A$43+D5*$A$40 -> 0 | E37: =+E26*$A$42+E12*$A$41+E19*$A$43+E5*$A$40 -> 630.2 | F37: =+F26*$A$42+F12*$A$41+F19*$A$43+F5*$A$40 -> 318.4 | G37: =+G26*$A$42+G12*$A$41+G19*$A$43+G5*$A$40 -> 435.6 | H37: =+H26*$A$42+H12*$A$41+H19*$A$43+H5*$A$40 -> 435.6 | I37: =+I26*$A$42+I12*$A$41+I19*$A$43+I5*$A$40 -> 435.6 | ... AJ37: =+AJ26*$A$42+AJ12*$A$41+AJ19*$A$43+AJ5*$A$40 -> 11760.5
C38: PLANTA | D38: CPO ME | E38: CPO REAL | F38: % CUMPL | G38: DIF TM | J38: PLANTA | K38: CPO ME | L38: CPO REAL | M38: % CUMPL | N38: DIF TM | S38: PLANTA | T38: CPO ME | U38: CPO REAL | V38: % CUMPL | W38: DIF TM | Z38: PLANTA | AA38: CPO ME | AB38: CPO REAL | AC38: % CUMPL | AD38: DIF TM | AH38: PLANTA | AI38: CPO ME | AJ38: CPO REAL | AK38: % CUMPL | AL38: DIF TM
A39: TEA ME | C39: Ext. Codazzi | D39: =+(SUM($E5))*$A$40 -> 291.6 | E39: =E7 -> 323.612 | F39: =+E39/D39 -> 1.1097805 | G39: =+E39-D39 -> 32.012 | J39: Ext. Codazzi | K39: =(L5)*$A$40 -> 1242 | L39: =L7 -> 1239.54 | M39: =+L39/K39 -> 0.99801932 | N39: =+L39-K39 -> -2.46 | S39: Ext. Codazzi | T39: =(U5)*$A$40 -> 2516.4 | U39: =U7 -> 2240.528 | V39: =+U39/T39 -> 0.89037037 | W39: =+U39-T39 -> -275.872 | Z39: Ext. Codazzi | AA39: =+AB5*$A$40 -> 3412.8 | AB39: =AB7 -> 3155.86 | AC39: =+AB39/AA39 -> 0.92471285 | AD39: =+AB39-AA39 -> -256.94 | AH39: Ext. Codazzi | AI39: =+AJ5*$A$40 -> 4536 | AJ39: =AJ7 -> 4194.884 | AK39: =+AJ39/AI39 -> 0.92479806 | AL39: =+AJ39-AI39 -> -341.116
A40: 0.216 | B40: Ext. Codazzi | C40: Ext. MLB | D40: =+(SUM($E12))*$A$41 -> 37.6 | E40: =E14 -> 57.126 | F40: =+E40/D40 -> 1.5193085 | G40: =+E40-D40 -> 19.526 | J40: Ext. MLB | K40: =(L12)*$A$41 -> 37.6 | L40: =L14 -> 57.126 | M40: =+L40/K40 -> 1.5193085 | N40: =+L40-K40 -> 19.526 | S40: Ext. MLB | T40: =+(U12)*$A$41 -> 272.6 | U40: =U14 -> 301.843 | V40: =+U40/T40 -> 1.1072744 | W40: =+U40-T40 -> 29.243 | Z40: Ext. MLB | AA40: =+AB12*$A$41 -> 573.4 | AB40: =AB14 -> 547.879 | AC40: =+AB40/AA40 -> 0.9554918 | AD40: =+AB40-AA40 -> -25.521 | AH40: Ext. MLB | AI40: =+AJ12*$A$41 -> 921.2 | AJ40: =AJ14 -> 872.131 | AK40: =+AJ40/AI40 -> 0.94673361 | AL40: =+AJ40-AI40 -> -49.069
...

Sheet Resumen UPSTREAM
B3: RFF Procesada | D3: ACUMULADO NOV 25 | J3: CPO | R3: TAE% | X3: ALMENDRA Y KPO
C4: 1
B5: PLANTA | C5: ME | D5: Real | E5: Dif | F5: % | J5: PLANTA | K5: CPO ME | L5: CPO REAL | M5: DIF TM | N5: % CUMPL | R5: PLANTA | S5: TEA ME | T5: TEA REAL | U5: DIF | Y5: ME | Z5: Real | AA5: Dif | AB5: % | AC5: =+DAY(TODAY()-1) -> 2
B6: Ext. Codazzi | C6: =+HLOOKUP($D$3,UPSTREAM!$A$1:$AJ$37,5,0)*$C$4 -> 21000 | D6: =+HLOOKUP($D$3,UPSTREAM!$A$1:$AJ$37,6,0) -> 18870.5 | E6: =+D6-C6 -> -2129.5 | F6: =+D6/C6 -> 0.89859524 | J6: Ext. Codazzi | K6: =+HLOOKUP($D$3,UPSTREAM!$A$1:$AJ$37,5,0)*UPSTREAM!$A$40*C4 -> 4536 | L6: =+HLOOKUP($D$3,UPSTREAM!$A$1:$AJ$37,7,0) -> 4194.884 | M6: =+L6-K6 -> -341.116 | N6: =+L6/K6 -> 0.92479806 | R6: Ext. Codazzi | S6: =+UPSTREAM!A40 -> 0.216 | T6: =+HLOOKUP($D$3,UPSTREAM!$A$1:$AJ$37,8,0) -> 0.22229851 | U6: =+T6-S6 -> 0.0062985083 | X6: ALMENDRA | Y6: =+HLOOKUP($D$3,UPSTREAM!$A$1:$BC$60,53,0) -> 2850 | Z6: =+HLOOKUP($D$3,UPSTREAM!$A$1:$BC$60,54,0) -> 2742.951 | AA6: =+Z6-Y6 -> -107.049 | AB6: =+Z6/Y6 -> 0.96243895 | AC6: =+Z6/AC5 -> 1371.4755 | AD6: Promedio díario
B7: Ext. MLB | C7: =+HLOOKUP($D$3,UPSTREAM!$A$1:$AJ$37,12,0)*C4 -> 4900 | D7: =+HLOOKUP($D$3,UPSTREAM!$A$1:$AJ$37,13,0) -> 4692 | E7: =+D7-C7 -> -208 | F7: =+D7/C7 -> 0.95755102 | J7: Ext. MLB | K7: =+HLOOKUP($D$3,UPSTREAM!$A$1:$AJ$37,12,0)*UPSTREAM!$A$41*C4 -> 921.2 | L7: =+HLOOKUP($D$3,UPSTREAM!$A$1:$AJ$37,14,0) -> 872.131 | M7: =+L7-K7 -> -49.069 | N7: =+L7/K7 -> 0.94673361 | R7: Ext. MLB | S7: =+UPSTREAM!A41 -> 0.188 | T7: =+HLOOKUP($D$3,UPSTREAM!$A$1:$AJ$37,15,0) -> 0.18587617 | U7: =+T7-S7 -> -0.0021238278 | X7: KPO | Y7: =+Y6*Y8 -> 1168.5 | Z7: =+HLOOKUP($D$3,UPSTREAM!$A$1:$BC$60,55,0) -> 1132.077 | AA7: =+Z7-Y7 -> -36.423 | AB7: =+Z7/Y7 -> 0.96882927
B8: Ext. A&G | C8: =+HLOOKUP($D$3,UPSTREAM!$A$1:$AJ$37,26,0)*C4 -> 20700 | D8: =+HLOOKUP($D$3,UPSTREAM!$A$1:$AJ$37,27,0) -> 21618.532 | E8: =+D8-C8 -> 918.532 | F8: =+D8/C8 -> 1.0443735 | J8: Ext. A&G | K8: =+HLOOKUP($D$3,UPSTREAM!$A$1:$AJ$37,26,0)*UPSTREAM!$A$42*C4 -> 4864.5 | L8: =+HLOOKUP($D$3,UPSTREAM!$A$1:$AJ$37,28,0) -> 5057.615 | M8: =+L8-K8 -> 193.115 | N8: =+L8/K8 -> 1.0396988 | R8: Ext. A&G | S8: =+UPSTREAM!A42 -> 0.235 | T8: =+HLOOKUP($D$3,UPSTREAM!$A$1:$AJ$37,29,0) -> 0.23394812 | U8: =+T8-S8 -> -0.0010518762 | X8: EXTRACCIÓN | Y8: =+UPSTREAM!AI51 -> 0.41 | Z8: =+Z7/Z6 -> 0.41272228 | AA8: =+Z8-Y8 -> 0.0027222834 | AB8: =+Z8/Y8 -> 1.0066397
B9: Ext. Sinú | C9: =+HLOOKUP($D$3,UPSTREAM!$A$1:$AJ$37,19,0)*C4 -> 6540 | D9: =+HLOOKUP($D$3,UPSTREAM!$A$1:$AJ$37,20,0) -> 6520.5 | E9: =+D9-C9 -> -19.5 | F9: =+IFERROR(D9/C9,0) -> 0.99701835 | J9: Ext. Sinú | K9: =+HLOOKUP($D$3,UPSTREAM!$A$1:$AJ$37,19,0)*UPSTREAM!$A$43*C4 -> 1438.8 | L9: =+HLOOKUP($D$3,UPSTREAM!$A$1:$AJ$37,21,0) -> 1436.495 | M9: =+L9-K9 -> -2.305 | N9: =+L9/K9 -> 0.99839797 | R9: Ext. Sinú | S9: =+UPSTREAM!A43 -> 0.22 | T9: =+HLOOKUP($D$3,UPSTREAM!$A$1:$AJ$37,22,0) -> 0.22030442 | U9: =+T9-S9 -> 0.00030442451
B11: TOTAL | C11: =+SUM(C6:C9) -> 53140 | D11: =+SUM(D6:D9) -> 51701.532 | E11: =+D11-C11 -> -1438.468 | F11: =+D11/C11 -> 0.9729306 | J11: TOTAL | K11: =+SUM(K6:K9) -> 11760.5 | L11: =+SUM(L6:L9) -> 11561.125 | M11: =+L11-K11 -> -199.375 | N11: =+L11/K11 -> 0.98304706 | R11: TOTAL | S11: =+K11/C11 -> 0.22131163 | T11: =+L11/D11 -> 0.22361281 | U11: =+T11-S11 -> 0.0023011832
B13: PLANTA | C13: ME | D13: Real | E13: Dif | F13: % | J13: PLANTA | K13: ME | L13: Real | M13: Dif | N13: %
B14: RFF Producción sin Sinú | C14: =+C6+C7+C8 -> 46600 | D14: =+D6+D7+D8 -> 45181.032 | E14: =+D14-C14 -> -1418.968 | F14: =+D14/C14 -> 0.96955004 | J14: CPO PROD sin Sinú | K14: =+K6+K7+K8 -> 10321.7 | L14: =+L6+L7+L8 -> 10124.63 | M14: =+L14-K14 -> -197.07 | N14: =+L14/K14 -> 0.98090721
X18: RECUPERACIÓN DE ALMENDRA
C19: Fruta Inventario | J19: INVENTARIO CPO
B20: Ext. Codazzi | C20: 0 | K20: =+TODAY()-1 -> 45993 | X20: PLANTA | Y20: ME PK | Z20: Real PK | AA20: % CUMPL | AB20: DIF TM
B21: Ext. MLB | C21: 0 | J21: PLANTA | K21: TM | X21: Ext. Codazzi | Y21: 0.055 | Z21: 0.0614 | AA21: =+Z21/Y21 -> 1.1163636 | AB21: =+Z21-Y21 -> 0.0064
B22: Ext. A&G | C22: 0 | J22: Ext. Codazzi | K22: 480.631 | X22: Ext. MLB | Y22: 0.05 | Z22: 0.061 | AA22: =+Z22/Y22 -> 1.22 | AB22: =+Z22-Y22 -> 0.011
B23: Ext. Sinú | C23: 0 | J23: Ext. MLB | K23: 169.128 | X23: Ext. A&G | Y23: 0.05 | Z23: 0.0438 | AA23: =+Z23/Y23 -> 0.876 | AB23: =+Z23-Y23 -> -0.0062
J24: Ext. A&G | K24: 280.522
J25: Ext. Sinú | K25: 50.379
J27: TOTAL | K27: =+SUM(K22:K25) -> 980.66 | X27: INVENTARIO ALMENDRA
J29: Venta CPO | X29: PLANTA | Y29: TM
X30: Ext. Codazzi | Y30: 235
J31: Cliente | K31: Objetivo | L31: Real | M31: Dif | N31: % | X31: Ext. MLB | Y31: 0.5
J32: CI CARIBBEAN | K32: 0 | L32: 0 | M32: =+K32-L32 -> 0 | N32: =+IFERROR(L32/K32,"") | X32: Ext. A&G | Y32: 60
J33: Prestamo Acepalma | K33: 166 | L33: 171 | M33: =+K33-L33 -> -5 | N33: =+IFERROR(L33/K33,"") -> 1.0301205 | X33: Ext. Sinú* | Y33: 400
J34: Golden Agri 1 | K34: 0 | L34: 0 | M34: =+K34-L34 -> 0 | N34: =+IFERROR(L34/K34,"") | X34: Ext. Codazzi* | Y34: 83
J35: CPO Alto Estearico | K35: 0 | L35: 0 | M35: =+K35-L35 -> 0 | N35: =+IFERROR(L35/K35,"") | X35: Ext. MLB* | Y35: 157
N36: =+IFERROR(L36/K36,"") | X36: *Nuez
J37: TOTAL | K37: =+SUM(K32:K35) -> 166 | L37: =+SUM(L32:L35) -> 171 | M37: =+SUM(M32:M35) -> -5 | N37: =+IFERROR(L37/K37,"") -> 1.0301205
J42: Prestamo Acepalma CPO
K43: ME | L43: REAL
J44: Ingreso CPO | K44: 0 | L44: 0
J45: Despacho CPO | K45: 700 | L45: 0

Sheet DOWNSTREAM
A1: ZONA | B1: 45962 | C1: =+B1+1 -> 45963 | D1: =+C1+1 -> 45964 | E1: ACUMULADO S1 | F1: =+D1+1 -> 45965 | G1: =+F1+1 -> 45966 | H1: =+G1+1 -> 45967 | I1: =+H1+1 -> 45968 | J1: =+I1+1 -> 45969 | K1: =+J1+1 -> 45970 | L1: ACUMULADO S2 | M1: =+K1+1 -> 45971 | N1: =+M1+1 -> 45972 | O1: =+N1+1 -> 45973 | P1: =+O1+1 -> 45974 | Q1: =+P1+1 -> 45975 | R1: =+Q1+1 -> 45976 | S1: =+R1+1 -> 45977 | T1: =+S1+1 -> 45978 | U1: ACUMULADO S3 | V1: =+T1+1 -> 45979 | W1: =+V1+1 -> 45980 | X1: =+W1+1 -> 45981 | Y1: =+X1+1 -> 45982 | Z1: =+Y1+1 -> 45983 | AA1: =+Z1+1 -> 45984 | AB1: ACUMULADO S4 | AC1: =+AA1+1 -> 45985 | AD1: =+AC7+1 -> 45986 | AE1: =+AD1+1 -> 45987 | AF1: =+AE1+1 -> 45988 | AG1: =+AF1+1 -> 45989 | AH1: =+AG1+1 -> 45990 | AI1: =+AH1+1 -> 45991 | AJ1: ACUMULADO NOV 25
A2: Refinería 1 ME | B2: 0 | C2: 0 | D2: 150 | E2: =+SUM(B2:D2) -> 150 | F2: 330 | G2: 330 | H2: 330 | I2: 330 | J2: 330 | K2: 240 | L2: =+SUM(F2:K2)+E2 -> 2040 | M2: 330 | N2: 330 | O2: 330 | P2: 330 | Q2: 330 | R2: 330 | S2: 240 | T2: 330 | U2: =+L2+SUM(M2:T2) -> 4590 | V2: 330 | W2: 330 | X2: 330 | Y2: 330 | Z2: 330 | AA2: 240 | AB2: =+U2+SUM(V2:AA2) -> 6480 | AC2: 330 | AD2: 330 | AE2: 330 | AF2: 330 | AG2: 330 | AH2: 330 | AI2: 210 | AJ2: =+AB2+SUM(AC2:AI2) -> 8670
A3: Refinería 1 Real | B3: 0 | C3: 0 | D3: 341.205 | E3: =+SUM(B3:D3) -> 341.205 | F3: 329.986 | G3: 334.101 | H3: 335.221 | I3: 333.516 | J3: 330.121 | K3: 335.257 | L3: =+SUM(F3:K3)+E3 -> 2339.407 | M3: 350.33 | N3: 328.561 | O3: 352.605 | P3: 372.497 | Q3: 251.148 | R3: 232.856 | S3: 360.985 | T3: 359.342 | U3: =+L3+SUM(M3:T3) -> 4947.731 | V3: 340.817 | W3: 354.108 | X3: 367.168 | Y3: 351.868 | Z3: 359.622 | AA3: 356.151 | AB3: =+U3+SUM(V3:AA3) -> 7077.465 | AC3: 357.073 | AD3: 371.071 | AE3: 342.749 | AF3: 365.903 | AG3: 201.005 | AH3: 243.65 | AI3: 322.388 | AJ3: =+AB3+SUM(AC3:AI3) -> 9281.304
A4: % Cumplimiento | B4: =IFERROR(B3/B2,0) -> 0 | C4: =IFERROR(C3/C2,0) -> 0 | D4: =IFERROR(D3/D2,0) -> 2.2747 | E4: =IFERROR(E3/E2,0) -> 2.2747 | F4: =IFERROR(F3/F2,0) -> 0.99995758 | G4: =IFERROR(G3/G2,0) -> 1.0124273 | H4: =IFERROR(H3/H2,0) -> 1.0158212 | I4: =IFERROR(I3/I2,0) -> 1.0106545 | ... AJ4: =IFERROR(AJ3/AJ2,0) -> 1.070508
A5: Rendimiento (94,5%)
A6: Acidez Ingreso
A7: Rojo Recepción | AC7: =+AA1+1 -> 45985
A8: Rojo Saponif | AC8: 360
A9: Inventario Inicio
A10: Refinería 2 ME | B10: 0 | C10: 0 | D10: 10 | E10: =+SUM(B10:D10) -> 10 | F10: 35 | G10: 35 | H10: 20 | I10: 10 | J10: 30 | K10: 30 | L10: =+SUM(F10:K10)+E10 -> 170 | M10: 30 | N10: 30 | O10: 30 | P10: 30 | Q10: 10 | R10: 35 | S10: 35 | T10: 35 | U10: =+L10+SUM(M10:T10) -> 405 | V10: 35 | W10: 35 | X10: 35 | Y10: 35 | Z10: 35 | AA10: 10 | AB10: =+U10+SUM(V10:AA10) -> 590 | AC10: 10 | AD10: 30 | AE10: 30 | AF10: 30 | AG10: 30 | AH10: 30 | AI10: 20 | AJ10: =+AB10+SUM(AC10:AI10) -> 770
A11: Refineria 2 Real | B11: =+SUM(B12:B13) -> 0 | C11: =+SUM(C12:C13) -> 0 | D11: =+SUM(D12:D13) -> 2.22 | E11: =+SUM(B11:D11) -> 2.22 | F11: =+SUM(F12:F13) -> 22.254 | G11: =+SUM(G12:G13) -> 35.884 | H11: =+SUM(H12:H13) -> 31.203 | I11: =+SUM(I12:I13) -> 24.608 | J11: =+SUM(J12:J13) -> 37.287 | K11: =+SUM(K12:K13) -> 38.815 | L11: =+SUM(F11:K11)+E11 -> 192.271 | M11: =+SUM(M12:M13) -> 39.971 | N11: =+SUM(N12:N13) -> 37.152 | O11: =+SUM(O12:O13) -> 39.657 | P11: =+SUM(P12:P13) -> 34.556 | Q11: =+SUM(Q12:Q13) -> 21.922 | R11: =+SUM(R12:R13) -> 13.185 | S11: =+SUM(S12:S13) -> 41.448 | T11: =+SUM(T12:T13) -> 23.611 | U11: =+L11+SUM(M11:T11) -> 443.773 | V11: =+SUM(V12:V13) -> 13.193 | W11: =+SUM(W12:W13) -> 28.345 | X11: =+SUM(X12:X13) -> 26.5 | Y11: =+SUM(Y12:Y13) -> 31.225 | Z11: =+SUM(Z12:Z13) -> 33.7 | AA11: =+SUM(AA12:AA13) -> 31.235 | AB11: =+U11+SUM(V11:AA11) -> 607.971 | AC11: =+SUM(AC12:AC13) -> 32.557 | AD11: =+SUM(AD12:AD13) -> 33.5 | AE11: =+SUM(AE12:AE13) -> 33.389 | AF11: =+SUM(AF12:AF13) -> 33.156 | AG11: =+SUM(AG12:AG13) -> 22.333 | AH11: =+SUM(AH12:AH13) -> 19.567 | AI11: =+SUM(AI12:AI13) -> 32.33 | AJ11: =+AB11+SUM(AC11:AI11) -> 814.803
A12: RBD Palma | B12: 0 | C12: 0 | D12: 0 | E12: =+SUM(B12:D12) -> 0 | L12: =+SUM(F12:K12)+E12 -> 0 | U12: =+L12+SUM(M12:T12) -> 0 | V12: 13.193 | W12: 28.345 | X12: 26.5 | Y12: 31.225 | Z12: 33.7 | AA12: 31.235 | AB12: =+U12+SUM(V12:AA12) -> 164.198 | AC12: 32.557 | AD12: 33.5 | AE12: 33.389 | AF12: 33.156 | AG12: 22.333 | AH12: 19.567 | AI12: 32.33 | AJ12: =+AB12+SUM(AC12:AI12) -> 371.03
A13: RBD Palmiste | D13: 2.22 | E13: =+SUM(B13:D13) -> 2.22 | F13: 22.254 | G13: 35.884 | H13: 31.203 | I13: 24.608 | J13: 37.287 | K13: 38.815 | L13: =+SUM(F13:K13)+E13 -> 192.271 | M13: 39.971 | N13: 37.152 | O13: 39.657 | P13: 34.556 | Q13: 21.922 | R13: 13.185 | S13: 41.448 | T13: 23.611 | U13: =+L13+SUM(M13:T13) -> 443.773 | AB13: =+U13+SUM(V13:AA13) -> 443.773 | AJ13: =+AB13+SUM(AC13:AI13) -> 443.773
A14: % Cumplimiento | B14: =IFERROR(+B11/B10,0) -> 0 | C14: =IFERROR(+C11/C10,0) -> 0 | D14: =IFERROR(+D11/D10,0) -> 0.222 | E14: =IFERROR(+E11/E10,0) -> 0.222 | F14: =IFERROR(+F11/F10,0) -> 0.63582857 | G14: =IFERROR(+G11/G10,0) -> 1.0252571 | H14: =IFERROR(+H11/H10,0) -> 1.56015 | I14: =IFERROR(+I11/I10,0) -> 2.4608 | ... AJ14: =IFERROR(+AJ11/AJ10,0) -> 1.0581857
A15: Rendimiento (93,5%)
A16: Rojo Recepción
A17: Rojo Saponif
A18: Inventario Inicio | AC18: 36
A19: Fracc 1 ME | B19: 0 | C19: 0 | D19: 0 | E19: =+SUM(B19:D19) -> 0 | F19: 0 | G19: 80 | H19: 80 | I19: 80 | J19: 80 | K19: 40 | L19: =+SUM(F19:K19)+E19 -> 360 | M19: 80 | N19: 80 | O19: 80 | P19: 80 | Q19: 80 | R19: 80 | S19: 60 | T19: 80 | U19: =+L19+SUM(M19:T19) -> 980 | V19: 80 | W19: 80 | X19: 80 | Y19: 80 | Z19: 80 | AA19: 0 | AB19: =+U19+SUM(V19:AA19) -> 1380 | AC19: 80 | AD19: 80 | AE19: 80 | AF19: 80 | AG19: 80 | AH19: 80 | AI19: 40 | AJ19: =+AB19+SUM(AC19:AI19) -> 1900
A20: Fracc 1 Real | B20: 0 | C20: 0 | D20: 100.605 | E20: =+SUM(B20:D20) -> 100.605 | F20: 23.298 | G20: 87.73 | H20: 131.84 | I20: 99.36 | J20: 104.17 | K20: 95.04 | L20: =+SUM(F20:K20)+E20 -> 642.043 | M20: 103.96 | N20: 104.05 | O20: 47.94 | P20: 62.62 | Q20: 63.8 | R20: 56.2 | S20: 95.83 | T20: 90.2 | U20: =+L20+SUM(M20:T20) -> 1266.643 | V20: 102.25 | W20: 94.55 | X20: 78.5 | Y20: 89.45 | Z20: 92.915 | AA20: 87.16 | AB20: =+U20+SUM(V20:AA20) -> 1811.468 | AC20: 77.5 | AD20: 84.289 | AE20: 95.65 | AF20: 92.25 | AG20: 91.86 | AH20: 50.9 | AI20: 89.6 | AJ20: =+AB20+SUM(AC20:AI20) -> 2393.517
A21: % Cumplimiento | B21: =IFERROR(+B20/B19,0) -> 0 | C21: =IFERROR(+C20/C19,0) -> 0 | D21: =IFERROR(+D20/D19,0) -> 0 | E21: =IFERROR(+E20/E19,0) -> 0 | F21: =IFERROR(+F20/F19,0) -> 0 | G21: =IFERROR(+G20/G19,0) -> 1.096625 | H21: =IFERROR(+H20/H19,0) -> 1.648 | I21: =IFERROR(+I20/I19,0) -> 1.242 | ... AJ21: =IFERROR(+AJ20/AJ19,0) -> 1.2597458
A22: Rendimiento (75,2%)
A23: Rojo Recepción
A24: Rojo Saponif
A25: Fracc 2 ME | B25: 0 | C25: 0 | D25: 60 | E25: =+SUM(B25:D25) -> 60 | F25: 120 | G25: 120 | H25: 120 | I25: 120 | J25: 120 | K25: 80 | L25: =+SUM(F25:K25)+E25 -> 740 | M25: 120 | N25: 120 | O25: 120 | P25: 120 | Q25: 120 | R25: 120 | S25: 80 | T25: 120 | U25: =+L25+SUM(M25:T25) -> 1660 | V25: 120 | W25: 120 | X25: 120 | Y25: 120 | Z25: 120 | AA25: 80 | AB25: =+U25+SUM(V25:AA25) -> 2340 | AC25: 120 | AD25: 120 | AE25: 120 | AF25: 120 | AG25: 120 | AH25: 120 | AI25: 40 | AJ25: =+AB25+SUM(AC25:AI25) -> 3100
A26: Fracc 2 Real | B26: 82 | C26: 129 | D26: 131 | E26: =+SUM(B26:D26) -> 342 | F26: 132.31 | G26: 132.925 | H26: 131.84 | I26: 134.48 | J26: 130.77 | K26: 129.785 | L26: =+SUM(F26:K26)+E26 -> 1134.11 | M26: 132.81 | N26: 131.25 | O26: 87.804 | P26: 103.08 | Q26: 116.65 | R26: 57.71 | S26: 86.9 | T26: 132.49 | U26: =+L26+SUM(M26:T26) -> 1982.804 | V26: 115.4 | W26: 115.9 | X26: 83.47 | Y26: 111.16 | Z26: 116.5 | AA26: 119.61 | AB26: =+U26+SUM(V26:AA26) -> 2644.844 | AC26: 115.56 | AD26: 117.3 | AE26: 100.15 | AF26: 113.32 | AG26: 91.11 | AH26: 78.6 | AI26: 97.75 | AJ26: =+AB26+SUM(AC26:AI26) -> 3358.634
A27: % Cumplimiento | B27: =IFERROR(+B26/B25,0) -> 0 | C27: =IFERROR(+C26/C25,0) -> 0 | D27: =IFERROR(+D26/D25,0) -> 2.1833333 | E27: =IFERROR(+E26/E25,0) -> 5.7 | F27: =IFERROR(+F26/F25,0) -> 1.1025833 | G27: =IFERROR(+G26/G25,0) -> 1.1077083 | H27: =IFERROR(+H26/H25,0) -> 1.0986667 | I27: =IFERROR(+I26/I25,0) -> 1.1206667 | ... AJ27: =IFERROR(+AJ26/AJ25,0) -> 1.0834303
A28: Rendimiento (77,3%)
A29: Cold Test
A30: Rojo
A31: Inventario Inicio | AC31: 125
A32: Margarinas ME | B32: =+B33 -> 0 | C32: =+C33 -> 53.55 | D32: =+D33 -> 56.7 | E32: =+SUM(B32:D32) -> 110.25 | F32: =+F33 -> 63 | G32: =+G33 -> 66.15 | H32: =+H33 -> 66.15 | I32: =+I33 -> 63 | J32: =+J33 -> 69.3 | K32: =+K33 -> 50.854 | L32: =+SUM(F32:K32)+E32 -> 488.704 | M32: =+M33 -> 56.925 | N32: =+N33 -> 63 | O32: 63 | P32: 63 | Q32: 66.15 | R32: 66.15 | S32: 63 | T32: 63 | U32: =+L32+SUM(M32:T32) -> 992.929 | V32: 63 | W32: 63 | X32: 63 | Y32: 66.15 | Z32: 63 | AA32: 63 | AB32: =+U32+SUM(V32:AA32) -> 1374.079 | AC32: 63 | AD32: 63 | AE32: 63 | AF32: 63 | AG32: 63 | AH32: 63 | AI32: 63 | AJ32: =+AB32+SUM(AC32:AI32) -> 1815.079
A33: Margarinas Real | B33: 0 | C33: 53.55 | D33: 56.7 | E33: =+SUM(B33:D33) -> 110.25 | F33: 63 | G33: 66.15 | H33: 66.15 | I33: 63 | J33: 69.3 | K33: 50.854 | L33: =+SUM(F33:K33)+E33 -> 488.704 | M33: 56.925 | N33: 63 | O33: 66.15 | P33: 69.3 | Q33: 40.95 | R33: 34.65 | S33: 44.1 | T33: 0 | U33: =+L33+SUM(M33:T33) -> 863.779 | V33: 0 | W33: 31.5 | X33: 56.7 | Y33: 50.4 | Z33: 44.1 | AA33: 53.55 | AB33: =+U33+SUM(V33:AA33) -> 1100.029 | AC33: 63 | AD33: 69.3 | AE33: 59.85 | AF33: 63 | AG33: 53.55 | AH33: 59.85 | AI33: 63 | AJ33: =+AB33+SUM(AC33:AI33) -> 1531.579
A34: % Cumplimiento | B34: =IFERROR(B33/B32,0) -> 0 | C34: =IFERROR(C33/C32,0) -> 1 | D34: =IFERROR(D33/D32,0) -> 1 | E34: =IFERROR(E33/E32,0) -> 1 | F34: =IFERROR(F33/F32,0) -> 1 | G34: =IFERROR(G33/G32,0) -> 1 | H34: =IFERROR(H33/H32,0) -> 1 | I34: =IFERROR(I33/I32,0) -> 1 | ... AJ34: =IFERROR(AJ33/AJ32,0) -> 0.84380845
A35: TOTAL PALMA RBD ME | B35: =+B2 -> 0 | C35: =+C2 -> 0 | D35: =+D2 -> 150 | E35: =+E2 -> 150 | F35: =+F2 -> 330 | G35: =+G3 -> 334.101 | H35: =+H2 -> 330 | I35: =+I2 -> 330 | J35: =+J2 -> 330 | K35: =+K2 -> 240 | L35: =+L2 -> 2040 | M35: =+M2 -> 330 | N35: =+N2 -> 330 | O35: =+O2 -> 330 | ... AJ35: =+AJ2 -> 8670
A36: TOTAL PALMA RBD Real | B36: =+B3 -> 0 | C36: =+C3 -> 0 | D36: =+D3 -> 341.205 | E36: =+E3 -> 341.205 | F36: =+F3 -> 329.986 | G36: =+G3 -> 334.101 | H36: =+H3 -> 335.221 | I36: =+I3 -> 333.516 | ... AJ36: =+AJ3 -> 9281.304
A37: % Cumplimiento | B37: =IFERROR(+B36/B35,0) -> 0 | C37: =IFERROR(+C36/C35,0) -> 0 | D37: =IFERROR(+D36/D35,0) -> 2.2747 | E37: =IFERROR(+E36/E35,0) -> 2.2747 | F37: =IFERROR(+F36/F35,0) -> 0.99995758 | G37: =IFERROR(+G36/G35,0) -> 1 | H37: =IFERROR(+H36/H35,0) -> 1.0158212 | I37: =IFERROR(+I36/I35,0) -> 1.0106545 | ... AJ37: =IFERROR(+AJ36/AJ35,0) -> 1.070508
A38: TOTAL PALMISTE RBD ME | B38: =+B10 -> 0 | C38: =+C10 -> 0 | D38: =+D10 -> 10 | E38: =+E10 -> 10 | F38: =+F10 -> 35 | G38: =+G10 -> 35 | H38: =+H10 -> 20 | I38: =+I10 -> 10 | ... AJ38: =+AJ10 -> 770
A39: TOTAL PALMISTE RBD Real | B39: =+B11 -> 0 | C39: =+C11 -> 0 | D39: =+D11 -> 2.22 | E39: =+E11 -> 2.22 | F39: =+F11 -> 22.254 | G39: =+G11 -> 35.884 | H39: =+H11 -> 31.203 | I39: =+I11 -> 24.608 | ... AJ39: =+AJ11 -> 814.803
A40: % Cumplimiento | B40: =IFERROR(+B39/B38,0) -> 0 | C40: =IFERROR(+C39/C38,0) -> 0 | D40: =IFERROR(+D39/D38,0) -> 0.222 | E40: =IFERROR(+E39/E38,0) -> 0.222 | F40: =IFERROR(+F39/F38,0) -> 0.63582857 | G40: =IFERROR(+G39/G38,0) -> 1.0252571 | H40: =IFERROR(+H39/H38,0) -> 1.56015 | I40: =IFERROR(+I39/I38,0) -> 2.4608 | ... AB40: =IFERROR(+AB39/AB38,0) -> 1.0304593 | AC40: =IFERROR(AC39/AC38,0) -> 3.2557 | AD40: =IFERROR(+AD39/AD38,0) -> 1.1166667 | AE40: =IFERROR(+AE39/AE38,0) -> 1.1129667 | AF40: =IFERROR(+AF39/AF38,0) -> 1.1052 | AG40: =IFERROR(+AG39/AG38,0) -> 0.74443333 | AH40: =IFERROR(+AH39/AH38,0) -> 0.65223333 | AI40: =IFERROR(+AI39/AI38,0) -> 1.6165 | AJ40: =IFERROR(+AJ39/AJ38,0) -> 1.0581857
...

Sheet DOWNSTREAM (2)
A1: ZONA | B1: 45689 | C1: =+B1+1 -> 45690 | D1: ACUMULADO S1 | E1: =+C1+1 -> 45691 | F1: =+E1+1 -> 45692 | G1: =+F1+1 -> 45693 | H1: =+G1+1 -> 45694 | I1: =+H1+1 -> 45695 | J1: =+I1+1 -> 45696 | K1: =+J1+1 -> 45697 | L1: ACUMULADO S2 | M1: =+K1+1 -> 45698 | N1: =+M1+1 -> 45699 | O1: =+N1+1 -> 45700 | P1: =+O1+1 -> 45701 | Q1: =+P1+1 -> 45702 | R1: =+Q1+1 -> 45703 | S1: =+R1+1 -> 45704 | T1: ACUMULADO S3 | U1: =+S1+1 -> 45705 | V1: =+U1+1 -> 45706 | W1: =+V1+1 -> 45707 | X1: =+W1+1 -> 45708 | Y1: =+X1+1 -> 45709 | Z1: =+Y1+1 -> 45710 | AA1: =+Z1+1 -> 45711 | AB1: ACUMULADO S4 | AC1: =+AA1+1 -> 45712 | AD1: =+AC1+1 -> 45713 | AE1: =+AD1+1 -> 45714 | AF1: =+AE1+1 -> 45715 | AG1: =+AF1+1 -> 45716 | AH1: Acumulado FEB 25 | BE1: TOTAL
A2: Refinería 1 ME | B2: =+B3 -> 340.249 | C2: =+C3 -> 265.73 | D2: =+SUM(B2:C2) -> 605.979 | E2: =+E3 -> 371.199 | F2: =+F3 -> 311.248 | G2: =+G3 -> 345.552 | H2: =+H3 -> 347.101 | I2: =+I3 -> 331.205 | J2: =+J3 -> 374.989 | K2: =+K3 -> 371.824 | L2: =+D2+SUM(E2:K2) -> 3059.097 | M2: =+M3 -> 356.436 | N2: =+N3 -> 379.614 | O2: =+O3 -> 373.846 | P2: =+P3 -> 358.372 | Q2: =+Q3 -> 368.394 | R2: =+R3 -> 368.394 | S2: =+S3 -> 371.182 | T2: =+L2+SUM(M2:S2) -> 5635.335 | U2: =+U3 -> 340.927 | V2: =+V3 -> 366.377 | W2: 250 | X2: 365 | Y2: 365 | Z2: 365 | AA2: 350 | AB2: =+T2+SUM(U2:AA2) -> 8037.639 | AC2: 365 | AD2: 365 | AE2: 365 | AF2: 365 | AG2: 365 | AH2: =+AB2+SUM(AC2:AG2) -> 9862.639 | BE2: 9790
A3: Refinería 1 Real | B3: 340.249 | C3: 265.73 | D3: =+SUM(B3:C3) -> 605.979 | E3: 371.199 | F3: 311.248 | G3: 345.552 | H3: 347.101 | I3: 331.205 | J3: 374.989 | K3: 371.824 | L3: =+D3+SUM(E3:K3) -> 3059.097 | M3: 356.436 | N3: 379.614 | O3: 373.846 | P3: 358.372 | Q3: 368.394 | R3: 368.394 | S3: 371.182 | T3: =+L3+SUM(M3:S3) -> 5635.335 | U3: 340.927 | V3: 366.377 | W3: 275.672 | X3: =+DOWNSTREAM!X3 -> 367.168 | Y3: =+DOWNSTREAM!Y3 -> 351.868 | Z3: =+DOWNSTREAM!Z3 -> 359.622 | AA3: =+DOWNSTREAM!AA3 -> 356.151 | AB3: =+T3+SUM(U3:AA3) -> 8053.12 | AC3: =+AC2 -> 365 | AD3: =+AD2 -> 365 | AE3: =+AE2 -> 365 | AF3: =+AF2 -> 365 | AG3: =+AG2 -> 365 | AH3: =+AB3+SUM(AC3:AG3) -> 9878.12
A4: % Cumplimiento | B4: =IFERROR(B3/B2,0) -> 1 | C4: =IFERROR(C3/C2,0) -> 1 | D4: =IFERROR(D3/D2,0) -> 1 | E4: =IFERROR(E3/E2,0) -> 1 | F4: =IFERROR(F3/F2,0) -> 1 | G4: =IFERROR(G3/G2,0) -> 1 | H4: =IFERROR(H3/H2,0) -> 1 | I4: =IFERROR(I3/I2,0) -> 1 | ... AH4: =IFERROR(AH3/AH2,0) -> 1.0015697
A5: Rendimiento (94,5%)
A6: Acidez Ingreso
A7: Rojo Recepción
A8: Rojo Saponif
A9: Inventario Inicio
A10: Refinería 2 ME | B10: =+B11 -> 32.222 | C10: =+C11 -> 24.335 | D10: =+SUM(B10:C10) -> 56.557 | E10: =+E11 -> 33.44 | F10: =+F11 -> 33.214 | G10: =+G11 -> 33.459 | H10: =+H11 -> 43.639 | I10: =+I11 -> 21.359 | J10: =+J11 -> 33.855 | K10: =+K11 -> 14.175 | L10: =+D10+SUM(E10:K10) -> 269.698 | M10: =+M11 -> 32.997 | N10: =+N11 -> 21.72 | O10: =+O11 -> 40.732 | P10: =+P11 -> 39.725 | Q10: =+Q11 -> 36.232 | R10: =+R11 -> 36.232 | S10: =+S11 -> 44.209 | T10: =+L10+SUM(M10:S10) -> 521.545 | U10: =+U11 -> 36.284 | V10: =+V11 -> 33.594 | W10: 41 | X10: 41 | Y10: 41 | Z10: 41 | AA10: 41 | AB10: =+T10+SUM(U10:AA10) -> 796.423 | AC10: 41 | AD10: 41 | AE10: 41 | AF10: 41 | AG10: 41 | AH10: =+AB10+SUM(AC10:AG10) -> 1001.423 | BE10: 370
A11: Refineria 2 Real | B11: 32.222 | C11: 24.335 | D11: =+SUM(B11:C11) -> 56.557 | E11: 33.44 | F11: 33.214 | G11: 33.459 | H11: 43.639 | I11: 21.359 | J11: 33.855 | K11: 14.175 | L11: =+D11+SUM(E11:K11) -> 269.698 | M11: 32.997 | N11: 21.72 | O11: 40.732 | P11: 39.725 | Q11: 36.232 | R11: 36.232 | S11: 44.209 | T11: =+L11+SUM(M11:S11) -> 521.545 | U11: 36.284 | V11: 33.594 | W11: 24.873 | X11: =+DOWNSTREAM!X11 -> 26.5 | Y11: =+DOWNSTREAM!Y11 -> 31.225 | Z11: =+DOWNSTREAM!Z11 -> 33.7 | AA11: =+DOWNSTREAM!AA11 -> 31.235 | AB11: =+T11+SUM(U11:AA11) -> 738.956 | AC11: =+AC10 -> 41 | AD11: =+AD10 -> 41 | AE11: =+AE10 -> 41 | AF11: =+AF10 -> 41 | AG11: =+AG10 -> 41 | AH11: =+AB11+SUM(AC11:AG11) -> 943.956
A12: % Cumplimiento | B12: =IFERROR(+B11/B10,0) -> 1 | C12: =IFERROR(+C11/C10,0) -> 1 | D12: =IFERROR(+D11/D10,0) -> 1 | E12: =IFERROR(+E11/E10,0) -> 1 | F12: =IFERROR(+F11/F10,0) -> 1 | G12: =IFERROR(+G11/G10,0) -> 1 | H12: =IFERROR(+H11/H10,0) -> 1 | I12: =IFERROR(+I11/I10,0) -> 1 | ... AH12: =IFERROR(+AH11/AH10,0) -> 0.94261466
A13: Rendimiento (93,5%)
A14: Rojo Recepción
A15: Rojo Saponif
A16: Inventario Inicio
A17: Fracc 1 ME | B17: =+B18 -> 97.9 | C17: =+C18 -> 90 | D17: =+SUM(B17:C17) -> 187.9 | E17: =+E18 -> 96.17 | F17: =+F18 -> 88.5 | G17: =+G18 -> 88.365 | H17: =+H18 -> 96.44 | I17: =+I18 -> 75.83 | J17: =+J18 -> 100.66 | K17: =+K18 -> 90.39 | L17: =+D17+SUM(E17:K17) -> 824.255 | M17: =+M18 -> 91.11 | N17: =+N18 -> 96.25 | O17: =+O18 -> 35.8 | P17: =+P18 -> 57 | Q17: =+Q18 -> 49.9 | R17: =+R18 -> 49.9 | S17: =+S18 -> 63.46 | T17: =+L17+SUM(M17:S17) -> 1267.675 | U17: =+U18 -> 94.67 | V17: =+V18 -> 28.63 | W17: 90 | X17: 90 | Y17: 90 | Z17: 90 | AA17: - | AB17: =+T17+SUM(U17:AA17) -> 1750.975 | AC17: 90 | AD17: 90 | AE17: 90 | AF17: 90 | AG17: 90 | AH17: =+AB17+SUM(AC17:AG17) -> 2200.975 | BE17: 3578.9474
A18: Fracc 1 Real | B18: 97.9 | C18: 90 | D18: =+SUM(B18:C18) -> 187.9 | E18: 96.17 | F18: 88.5 | G18: 88.365 | H18: 96.44 | I18: 75.83 | J18: 100.66 | K18: 90.39 | L18: =+D18+SUM(E18:K18) -> 824.255 | M18: 91.11 | N18: 96.25 | O18: 35.8 | P18: 57 | Q18: 49.9 | R18: 49.9 | S18: 63.46 | T18: =+L18+SUM(M18:S18) -> 1267.675 | U18: 94.67 | V18: 28.63 | W18: 87.7 | X18: =+DOWNSTREAM!X20 -> 78.5 | Y18: =+DOWNSTREAM!Y20 -> 89.45 | Z18: =+DOWNSTREAM!Z20 -> 92.915 | AA18: =+DOWNSTREAM!AA20 -> 87.16 | AB18: =+T18+SUM(U18:AA18) -> 1826.7 | AC18: =+AC17 -> 90 | AD18: =+AD17 -> 90 | AE18: =+AE17 -> 90 | AF18: =+AF17 -> 90 | AG18: =+AG17 -> 90 | AH18: =+AB18+SUM(AC18:AG18) -> 2276.7
A19: % Cumplimiento | B19: =IFERROR(+B18/B17,0) -> 1 | C19: =IFERROR(+C18/C17,0) -> 1 | D19: =IFERROR(+D18/D17,0) -> 1 | E19: =IFERROR(+E18/E17,0) -> 1 | F19: =IFERROR(+F18/F17,0) -> 1 | G19: =IFERROR(+G18/G17,0) -> 1 | H19: =IFERROR(+H18/H17,0) -> 1 | I19: =IFERROR(+I18/I17,0) -> 1 | ... AH19: =IFERROR(+AH18/AH17,0) -> 1.0344052
A20: Rendimiento (75,2%)
A21: Rojo Recepción
A22: Rojo Saponif
A23: Fracc 2 ME | B23: =+B24 -> 131.07 | C23: =+C24 -> 130.51 | D23: =+SUM(B23:C23) -> 261.58 | E23: =+E24 -> 134.739 | F23: =+F24 -> 130.27 | G23: =+G24 -> 130.35 | H23: =+H24 -> 130.77 | I23: =+I24 -> 130.6 | J23: =+J24 -> 139.86 | K23: =+K24 -> 130.05 | L23: =+D23+SUM(E23:K23) -> 1188.219 | M23: =+M24 -> 129.34 | N23: =+N24 -> 132.6 | O23: =+O24 -> 85.62 | P23: =+P24 -> 100.524 | Q23: =+Q24 -> 90.287 | R23: =+R24 -> 90.287 | S23: =+S24 -> 102.544 | T23: =+L23+SUM(M23:S23) -> 1919.421 | U23: =+U24 -> 135.43 | V23: =+V24 -> 87.23 | W23: 120 | X23: 120 | Y23: 120 | Z23: 120 | AA23: 100 | AB23: =+T23+SUM(U23:AA23) -> 2722.081 | AC23: 120 | AD23: 120 | AE23: 120 | AF23: 120 | AG23: 120 | AH23: =+AB23+SUM(AC23:AG23) -> 3322.081 | BE23: 4636.3636
A24: Fracc 2 Real | B24: 131.07 | C24: 130.51 | D24: =+SUM(B24:C24) -> 261.58 | E24: 134.739 | F24: 130.27 | G24: 130.35 | H24: 130.77 | I24: 130.6 | J24: 139.86 | K24: 130.05 | L24: =+D24+SUM(E24:K24) -> 1188.219 | M24: 129.34 | N24: 132.6 | O24: 85.62 | P24: 100.524 | Q24: 90.287 | R24: 90.287 | S24: 102.544 | T24: =+L24+SUM(M24:S24) -> 1919.421 | U24: 135.43 | V24: 87.23 | W24: 112.59 | X24: =+DOWNSTREAM!X26 -> 83.47 | Y24: =+DOWNSTREAM!Y26 -> 111.16 | Z24: =+DOWNSTREAM!Z26 -> 116.5 | AA24: =+DOWNSTREAM!AA26 -> 119.61 | AB24: =+T24+SUM(U24:AA24) -> 2685.411 | AC24: =+AC23 -> 120 | AD24: =+AD23 -> 120 | AE24: =+AE23 -> 120 | AF24: =+AF23 -> 120 | AG24: =+AG23 -> 120 | AH24: =+AB24+SUM(AC24:AG24) -> 3285.411
A25: % Cumplimiento | B25: =IFERROR(+B24/B23,0) -> 1 | C25: =IFERROR(+C24/C23,0) -> 1 | D25: =IFERROR(+D24/D23,0) -> 1 | E25: =IFERROR(+E24/E23,0) -> 1 | F25: =IFERROR(+F24/F23,0) -> 1 | G25: =IFERROR(+G24/G23,0) -> 1 | H25: =IFERROR(+H24/H23,0) -> 1 | I25: =IFERROR(+I24/I23,0) -> 1 | ... AH25: =IFERROR(+AH24/AH23,0) -> 0.98896174
A26: Rendimiento (77,3%)
A27: Cold Test
A28: Rojo
A29: Inventario Inicio
A30: Margarinas ME | B30: #N/A | C30: #N/A | D30: =+SUM(B30:C30) -> #N/A | E30: #N/A | F30: #N/A | G30: #N/A | H30: #N/A | I30: #N/A | J30: #N/A | K30: #N/A | L30: =+D30+SUM(E30:K30) -> #N/A | M30: #N/A | N30: #N/A | O30: #N/A | P30: #N/A | Q30: #N/A | R30: #N/A | S30: #N/A | T30: =+L30+SUM(M30:S30) -> #N/A | U30: #N/A | V30: 63 | W30: 63 | X30: 63 | Y30: 63 | Z30: 63 | AA30: 59.85 | AB30: =+T30+SUM(U30:AA30) -> #N/A | AC30: 59.85 | AD30: 63 | AE30: 63 | AF30: 56.7 | AG30: 0 | AH30: =+AB30+SUM(AC30:AG30) -> #N/A | BE30: 645
A31: Margarinas Real | B31: 22.05 | C31: 72.45 | D31: =+SUM(B31:C31) -> 94.5 | E31: 72.45 | F31: 44.1 | G31: 63 | H31: 12.48 | I31: 50.52 | J31: 53.52 | K31: 0 | L31: =+D31+SUM(E31:K31) -> 390.57 | M31: 28.35 | N31: 66.15 | O31: 66.15 | P31: 66.15 | Q31: 69.3 | R31: 50.4 | S31: 15.75 | T31: =+L31+SUM(M31:S31) -> 752.82 | U31: 47.25 | V31: 63 | W31: 63 | X31: =+DOWNSTREAM!X33 -> 56.7 | Y31: =+DOWNSTREAM!Y33 -> 50.4 | Z31: =+DOWNSTREAM!Z33 -> 44.1 | AA31: =+DOWNSTREAM!AA33 -> 53.55 | AB31: =+T31+SUM(U31:AA31) -> 1130.82 | AC31: 59.85 | AD31: 63 | AE31: 63 | AF31: 56.7 | AG31: 0 | AH31: =+AB31+SUM(AC31:AG31) -> 1373.37
A32: % Cumplimiento | B32: =IFERROR(B31/B30,0) -> 0 | C32: =IFERROR(C31/C30,0) -> 0 | D32: =IFERROR(D31/D30,0) -> 0 | E32: =IFERROR(E31/E30,0) -> 0 | F32: =IFERROR(F31/F30,0) -> 0 | G32: =IFERROR(G31/G30,0) -> 0 | H32: =IFERROR(H31/H30,0) -> 0 | I32: =IFERROR(I31/I30,0) -> 0 | ... AH32: =IFERROR(AH31/AH30,0) -> 0
A33: TOTAL PALMA RBD ME | B33: =+B2 -> 340.249 | C33: =+C2 -> 265.73 | D33: =+D2 -> 605.979 | E33: =+E2 -> 371.199 | F33: =+F2 -> 311.248 | G33: =+G3 -> 345.552 | H33: =+H2 -> 347.101 | I33: =+I2 -> 331.205 | J33: =+J2 -> 374.989 | K33: =+K2 -> 371.824 | L33: =+L2 -> 3059.097 | M33: =+M2 -> 356.436 | N33: =+N2 -> 379.614 | O33: =+O2 -> 373.846 | ... AH33: =+AH2 -> 9862.639
A34: TOTAL PALMA RBD Real | B34: =+B3 -> 340.249 | C34: =+C3 -> 265.73 | D34: =+D3 -> 605.979 | E34: =+E3 -> 371.199 | F34: =+F3 -> 311.248 | G34: =+G3 -> 345.552 | H34: =+H3 -> 347.101 | I34: =+I3 -> 331.205 | ... AH34: =+AH3 -> 9878.12
A35: % Cumplimiento | B35: =IFERROR(+B34/B33,0) -> 1 | C35: =IFERROR(+C34/C33,0) -> 1 | D35: =IFERROR(+D34/D33,0) -> 1 | E35: =IFERROR(+E34/E33,0) -> 1 | F35: =IFERROR(+F34/F33,0) -> 1 | G35: =IFERROR(+G34/G33,0) -> 1 | H35: =IFERROR(+H34/H33,0) -> 1 | I35: =IFERROR(+I34/I33,0) -> 1 | ... AH35: =IFERROR(+AH34/AH33,0) -> 1.0015697
A36: TOTAL PALMISTE RBD ME | B36: =+B10 -> 32.222 | C36: =+C10 -> 24.335 | D36: =+D10 -> 56.557 | E36: =+E10 -> 33.44 | F36: =+F10 -> 33.214 | G36: =+G10 -> 33.459 | H36: =+H10 -> 43.639 | I36: =+I10 -> 21.359 | ... AH36: =+AH10 -> 1001.423
A37: TOTAL PALMISTE RBD Real | B37: =+B11 -> 32.222 | C37: =+C11 -> 24.335 | D37: =+D11 -> 56.557 | E37: =+E11 -> 33.44 | F37: =+F11 -> 33.214 | G37: =+G11 -> 33.459 | H37: =+H11 -> 43.639 | I37: =+I11 -> 21.359 | ... AH37: =+AH11 -> 943.956
A38: % Cumplimiento | B38: =IFERROR(+B37/B36,0) -> 1 | C38: =IFERROR(+C37/C36,0) -> 1 | D38: =IFERROR(+D37/D36,0) -> 1 | E38: =IFERROR(+E37/E36,0) -> 1 | F38: =IFERROR(+F37/F36,0) -> 1 | G38: =IFERROR(+G37/G36,0) -> 1 | H38: =IFERROR(+H37/H36,0) -> 1 | I38: =IFERROR(+I37/I36,0) -> 1 | ... AH38: =IFERROR(+AH37/AH36,0) -> 0.94261466
A39: TOTAL OLEINA ME | B39: =+B17+B23 -> 228.97 | C39: =+C17+C23 -> 220.51 | D39: =+D17+D23 -> 449.48 | E39: =+E17+E23 -> 230.909 | F39: =+F17+F23 -> 218.77 | G39: =+G17+G23 -> 218.715 | H39: =+H17+H23 -> 227.21 | I39: =+I17+I23 -> 206.43 | ... AH39: =+AH17+AH23 -> 5523.056
A40: TOTAL OLEINA Real | B40: =+B18+B24 -> 228.97 | C40: =+C18+C24 -> 220.51 | D40: =+D18+D24 -> 449.48 | E40: =+E18+E24 -> 230.909 | F40: =+F18+F24 -> 218.77 | G40: =+G18+G24 -> 218.715 | H40: =+H18+H24 -> 227.21 | I40: =+I18+I24 -> 206.43 | ... AH40: =+AH18+AH24 -> 5562.111
...

Sheet DOWNSTREAM mod
A1: ZONA | B1: 45717 | C1: =+B1+1 -> 45718 | D1: ACUMULADO S1 | E1: =+C1+1 -> 45719 | F1: =+E1+1 -> 45720 | G1: =+F1+1 -> 45721 | H1: =+G1+1 -> 45722 | I1: =+H1+1 -> 45723 | J1: =+I1+1 -> 45724 | K1: =+J1+1 -> 45725 | L1: ACUMULADO S2 | M1: =+K1+1 -> 45726 | N1: =+M1+1 -> 45727 | O1: =+N1+1 -> 45728 | P1: =+O1+1 -> 45729 | Q1: =+P1+1 -> 45730 | R1: =+Q1+1 -> 45731 | S1: =+R1+1 -> 45732 | T1: ACUMULADO S3 | U1: =+S1+1 -> 45733 | V1: =+U1+1 -> 45734 | W1: =+V1+1 -> 45735 | X1: =+W1+1 -> 45736 | Y1: =+X1+1 -> 45737 | Z1: =+Y1+1 -> 45738 | AA1: =+Z1+1 -> 45739 | AB1: =+AA1+1 -> 45740 | AC1: ACUMULADO S4 | AD1: =+AB1+1 -> 45741 | AE1: =+AD1+1 -> 45742 | AF1: =+AE1+1 -> 45743 | AG1: =+AF1+1 -> 45744 | AH1: =+AG1+1 -> 45745 | AI1: =+AH1+1 -> 45746 | AJ1: Acumulado ABR 25 | BG1: TOTAL
A2: Refinería 1 ME | B2: 346.75809 | C2: 346.75809 | D2: =+SUM(B2:C2) -> 693.51618 | E2: 346.75809 | F2: 346.75809 | G2: 346.75809 | H2: 346.75809 | I2: 346.75809 | J2: 346.75809 | K2: 346.75809 | L2: =+D2+SUM(E2:K2) -> 3120.8228 | M2: 346.75809 | N2: 346.75809 | O2: 360 | P2: 360 | Q2: 360 | R2: 360 | S2: 360 | T2: =+L2+SUM(M2:S2) -> 5614.339 | U2: 360 | V2: 360 | W2: 360 | X2: 360 | Y2: 360 | Z2: 360 | AA2: 360 | AB2: 360 | AC2: =+T2+SUM(U2:AB2) -> 8494.339 | AD2: 360 | AE2: 360 | AF2: 360 | AG2: 360 | AH2: 360 | AI2: 360 | AJ2: =+AC2+SUM(AD2:AI2) -> 10654.339 | BG2: 9790
A3: Refinería 1 Real | B3: 355.951 | C3: 359.386 | D3: =+SUM(B3:C3) -> 715.337 | E3: 353.159 | F3: 355.097 | G3: 337.639 | H3: 358.699 | I3: 334.065 | J3: 363.063 | K3: 357.838 | L3: =+D3+SUM(E3:K3) -> 3174.897 | M3: 317.698 | N3: 321.804 | O3: 343.592 | P3: 323.922 | Q3: 311.948 | R3: 331.465 | S3: 337.165 | T3: =+L3+SUM(M3:S3) -> 5462.491 | U3: =+DOWNSTREAM!T3 -> 359.342 | V3: =+DOWNSTREAM!V3 -> 340.817 | W3: =+DOWNSTREAM!W3 -> 354.108 | X3: =+DOWNSTREAM!X3 -> 367.168 | Y3: =+DOWNSTREAM!Y3 -> 351.868 | Z3: =+DOWNSTREAM!Z3 -> 359.622 | AA3: =+DOWNSTREAM!AA3 -> 356.151 | AB3: =+DOWNSTREAM!AC3 -> 357.073 | AC3: =+T3+SUM(U3:AB3) -> 8308.64 | AD3: =+DOWNSTREAM!AD3 -> 371.071 | AE3: =+DOWNSTREAM!AE3 -> 342.749 | AF3: =+DOWNSTREAM!AF3 -> 365.903 | AG3: =+DOWNSTREAM!AG3 -> 201.005 | AH3: =+DOWNSTREAM!AH3 -> 243.65 | AI3: =+DOWNSTREAM!AI3 -> 322.388 | AJ3: =+AC3+SUM(AD3:AI3) -> 10155.406
A4: % Cumplimiento | B4: =IFERROR(B3/B2,0) -> 1.026511 | C4: =IFERROR(C3/C2,0) -> 1.0364171 | D4: =IFERROR(D3/D2,0) -> 1.031464 | E4: =IFERROR(E3/E2,0) -> 1.0184593 | F4: =IFERROR(F3/F2,0) -> 1.0240482 | G4: =IFERROR(G3/G2,0) -> 0.97370187 | H4: =IFERROR(H3/H2,0) -> 1.0344358 | I4: =IFERROR(I3/I2,0) -> 0.96339497 | ... AJ4: =IFERROR(AJ3/AJ2,0) -> 0.95317091
A5: Rendimiento (94,5%)
A6: Acidez Ingreso
A7: Rojo Recepción
A8: Rojo Saponif
A9: Inventario Inicio
A10: Refinería 2 ME | B10: 22.32 | C10: 22.32 | D10: =+SUM(B10:C10) -> 44.64 | E10: 22.32 | F10: 22.32 | G10: 22.32 | H10: 22.32 | I10: 22.32 | J10: 22.32 | K10: 22.32 | L10: =+D10+SUM(E10:K10) -> 200.88 | M10: 22.32 | N10: 22.32 | O10: 37 | P10: 37 | Q10: 37 | R10: 37 | S10: 37 | T10: =+L10+SUM(M10:S10) -> 430.52 | U10: 10 | V10: 30 | W10: 30 | X10: 30 | Y10: 30 | Z10: 10 | AA10: 10 | AB10: 36 | AC10: =+T10+SUM(U10:AB10) -> 616.52 | AD10: 36 | AE10: 36 | AF10: 36 | AG10: 20 | AH10: 10 | AI10: 30 | AJ10: =+AC10+SUM(AD10:AI10) -> 784.52 | BG10: 370
