Workbook

Sheet UPSTREAM
A1: ZONA | B1: 45992 | C1: =+B1+1 -> 45993 | D1: =+C1+1 -> 45994 | E1: =+D1+1 -> 45995 | F1: =+E1+1 -> 45996 | G1: =+F1+1 -> 45997 | H1: =+G1+1 -> 45998 | I1: =+H1+1 -> 45999 | J1: ACUMULADO S1 | K1: =+I1+1 -> 46000 | L1: =+K1+1 -> 46001 | M1: =+L1+1 -> 46002 | N1: =+M1+1 -> 46003 | O1: =+N1+1 -> 46004 | P1: =+O1+1 -> 46005 | Q1: ACUMULADO S2 | R1: =+P1+1 -> 46006 | S1: =+R1+1 -> 46007 | T1: =+S1+1 -> 46008 | U1: =+T1+1 -> 46009 | V1: =+U1+1 -> 46010 | W1: =+V1+1 -> 46011 | X1: =+W1+1 -> 46012 | Y1: ACUMULADO S3 | Z1: =+X1+1 -> 46013 | AA1: =+Z1+1 -> 46014 | AB1: =+AA1+1 -> 46015 | AC1: =+AB1+1 -> 46016 | AD1: =+AC1+1 -> 46017 | AE1: =+AD1+1 -> 46018 | AF1: =+AE1+1 -> 46019 | AG1: ACUMULADO S4 | AH1: =+AF1+1 -> 46020 | AI1: =+AH1+1 -> 46021 | AJ1: =+AI1+1 -> 46022 | AK1: ACUMULADO DIC 25
A2: Codazzi Proyección | B2: =+HLOOKUP(B$1,'[1]RFF Resumen'!$C$16:$AG$153,3,0)+HLOOKUP(B$1,'[1]RFF Resumen'!$C$16:$AG$153,6,0) -> 525 | C2: =+HLOOKUP(C$1,'[1]RFF Resumen'!$C$16:$AG$153,3,0)+HLOOKUP(C$1,'[1]RFF Resumen'!$C$16:$AG$153,6,0) -> 597 | D2: =+HLOOKUP(D$1,'[1]RFF Resumen'!$C$16:$AG$153,3,0)+HLOOKUP(D$1,'[1]RFF Resumen'!$C$16:$AG$153,6,0) -> 659 | E2: =+HLOOKUP(E$1,'[1]RFF Resumen'!$C$16:$AG$153,3,0)+HLOOKUP(E$1,'[1]RFF Resumen'!$C$16:$AG$153,6,0) -> 675 | F2: =+HLOOKUP(F$1,'[1]RFF Resumen'!$C$16:$AG$153,3,0)+HLOOKUP(F$1,'[1]RFF Resumen'!$C$16:$AG$153,6,0) -> 743 | G2: =+HLOOKUP(G$1,'[1]RFF Resumen'!$C$16:$AG$153,3,0)+HLOOKUP(G$1,'[1]RFF Resumen'!$C$16:$AG$153,6,0) -> 789 | H2: =+HLOOKUP(H$1,'[1]RFF Resumen'!$C$16:$AG$153,3,0)+HLOOKUP(H$1,'[1]RFF Resumen'!$C$16:$AG$153,6,0) -> 300 | I2: =+HLOOKUP(I$1,'[1]RFF Resumen'!$C$16:$AG$153,3,0)+HLOOKUP(I$1,'[1]RFF Resumen'!$C$16:$AG$153,6,0) -> 50 | J2: =+SUM(B2:I2) -> 4338 | K2: =+HLOOKUP(K$1,'[1]RFF Resumen'!$C$16:$AG$153,3,0)+HLOOKUP(K$1,'[1]RFF Resumen'!$C$16:$AG$153,6,0) -> 560 | L2: =+HLOOKUP(L$1,'[1]RFF Resumen'!$C$16:$AG$153,3,0)+HLOOKUP(L$1,'[1]RFF Resumen'!$C$16:$AG$153,6,0) -> 669 | M2: =+HLOOKUP(M$1,'[1]RFF Resumen'!$C$16:$AG$153,3,0)+HLOOKUP(M$1,'[1]RFF Resumen'!$C$16:$AG$153,6,0) -> 655 | N2: =+HLOOKUP(N$1,'[1]RFF Resumen'!$C$16:$AG$153,3,0)+HLOOKUP(N$1,'[1]RFF Resumen'!$C$16:$AG$153,6,0) -> 729 | O2: =+HLOOKUP(O$1,'[1]RFF Resumen'!$C$16:$AG$153,3,0)+HLOOKUP(O$1,'[1]RFF Resumen'!$C$16:$AG$153,6,0) -> 740 | P2: =+HLOOKUP(P$1,'[1]RFF Resumen'!$C$16:$AG$153,3,0)+HLOOKUP(P$1,'[1]RFF Resumen'!$C$16:$AG$153,6,0) -> 510 | Q2: =+J2+SUM(K2:P2) -> 8201 | R2: =+HLOOKUP(R$1,'[1]RFF Resumen'!$C$16:$AG$153,3,0)+HLOOKUP(R$1,'[1]RFF Resumen'!$C$16:$AG$153,6,0) -> 715 | S2: =+HLOOKUP(S$1,'[1]RFF Resumen'!$C$16:$AG$153,3,0)+HLOOKUP(S$1,'[1]RFF Resumen'!$C$16:$AG$153,6,0) -> 629 | T2: =+HLOOKUP(T$1,'[1]RFF Resumen'!$C$16:$AG$153,3,0)+HLOOKUP(T$1,'[1]RFF Resumen'!$C$16:$AG$153,6,0) -> 638 | U2: =+HLOOKUP(U$1,'[1]RFF Resumen'!$C$16:$AG$153,3,0)+HLOOKUP(U$1,'[1]RFF Resumen'!$C$16:$AG$153,6,0) -> 654 | V2: =+HLOOKUP(V$1,'[1]RFF Resumen'!$C$16:$AG$153,3,0)+HLOOKUP(V$1,'[1]RFF Resumen'!$C$16:$AG$153,6,0) -> 729 | W2: =+HLOOKUP(W$1,'[1]RFF Resumen'!$C$16:$AG$153,3,0)+HLOOKUP(W$1,'[1]RFF Resumen'!$C$16:$AG$153,6,0) -> 710 | X2: =+HLOOKUP(X$1,'[1]RFF Resumen'!$C$16:$AG$153,3,0)+HLOOKUP(X$1,'[1]RFF Resumen'!$C$16:$AG$153,6,0) -> 384 | Y2: =+Q2+SUM(R2:X2) -> 12660 | Z2: =+HLOOKUP(Z$1,'[1]RFF Resumen'!$C$16:$AG$153,3,0)+HLOOKUP(Z$1,'[1]RFF Resumen'!$C$16:$AG$153,6,0) -> 700 | AA2: =+HLOOKUP(AA$1,'[1]RFF Resumen'!$C$16:$AG$153,3,0)+HLOOKUP(AA$1,'[1]RFF Resumen'!$C$16:$AG$153,6,0) -> 840 | AB2: =+HLOOKUP(AB$1,'[1]RFF Resumen'!$C$16:$AG$153,3,0)+HLOOKUP(AB$1,'[1]RFF Resumen'!$C$16:$AG$153,6,0) -> 219 | AC2: =+HLOOKUP(AC$1,'[1]RFF Resumen'!$C$16:$AG$153,3,0)+HLOOKUP(AC$1,'[1]RFF Resumen'!$C$16:$AG$153,6,0) -> 0 | AD2: =+HLOOKUP(AD$1,'[1]RFF Resumen'!$C$16:$AG$153,3,0)+HLOOKUP(AD$1,'[1]RFF Resumen'!$C$16:$AG$153,6,0) -> 590 | AE2: =+HLOOKUP(AE$1,'[1]RFF Resumen'!$C$16:$AG$153,3,0)+HLOOKUP(AE$1,'[1]RFF Resumen'!$C$16:$AG$153,6,0) -> 690 | AF2: =+HLOOKUP(AF$1,'[1]RFF Resumen'!$C$16:$AG$153,3,0)+HLOOKUP(AF$1,'[1]RFF Resumen'!$C$16:$AG$153,6,0) -> 569 | AG2: =+Y2+SUM(Z2:AF2) -> 16268 | AH2: =+HLOOKUP(AH$1,'[1]RFF Resumen'!$C$16:$AG$153,3,0)+HLOOKUP(AH$1,'[1]RFF Resumen'!$C$16:$AG$153,6,0) -> 740 | AI2: =+HLOOKUP(AI$1,'[1]RFF Resumen'!$C$16:$AG$153,3,0)+HLOOKUP(AI$1,'[1]RFF Resumen'!$C$16:$AG$153,6,0) -> 922 | AJ2: =+HLOOKUP(AJ$1,'[1]RFF Resumen'!$C$16:$AG$153,3,0)+HLOOKUP(AJ$1,'[1]RFF Resumen'!$C$16:$AG$153,6,0) -> 70 | AK2: =+AG2+SUM(AH2:AJ2) -> 18000
A3: Codazzi Real | B3: =(IFERROR(VLOOKUP(B$1,[2]Hoja1!$A$2:$E$32,2,0)/1000,0)) -> 359.35 | C3: =(IFERROR(VLOOKUP(C$1,[2]Hoja1!$A$2:$E$32,2,0)/1000,0)) -> 412.66 | D3: =(IFERROR(VLOOKUP(D$1,[2]Hoja1!$A$2:$E$32,2,0)/1000,0)) -> 832.23 | E3: =(IFERROR(VLOOKUP(E$1,[2]Hoja1!$A$2:$E$32,2,0)/1000,0)) -> 757.85 | F3: =(IFERROR(VLOOKUP(F$1,[2]Hoja1!$A$2:$E$32,2,0)/1000,0)) -> 824.73 | G3: =(IFERROR(VLOOKUP(G$1,[2]Hoja1!$A$2:$E$32,2,0)/1000,0)) -> 511.17 | H3: =(IFERROR(VLOOKUP(H$1,[2]Hoja1!$A$2:$E$32,2,0)/1000,0)) -> 694.46 | I3: =(IFERROR(VLOOKUP(I$1,[2]Hoja1!$A$2:$E$32,2,0)/1000,0)) -> 192.89 | J3: =+SUM(B3:I3) -> 4585.34 | K3: =(IFERROR(VLOOKUP(K$1,[2]Hoja1!$A$2:$E$32,2,0)/1000,0)) -> 367.07 | L3: =(IFERROR(VLOOKUP(L$1,[2]Hoja1!$A$2:$E$32,2,0)/1000,0)) -> 588.51 | M3: =(IFERROR(VLOOKUP(M$1,[2]Hoja1!$A$2:$E$32,2,0)/1000,0)) -> 750.68 | N3: =(IFERROR(VLOOKUP(N$1,[2]Hoja1!$A$2:$E$32,2,0)/1000,0)) -> 0 | O3: =(IFERROR(VLOOKUP(O$1,[2]Hoja1!$A$2:$E$32,2,0)/1000,0)) -> 0 | P3: =(IFERROR(VLOOKUP(P$1,[2]Hoja1!$A$2:$E$32,2,0)/1000,0)) -> 0 | Q3: =+J3+SUM(K3:P3) -> 6291.6 | R3: =(IFERROR(VLOOKUP(R$1,[2]Hoja1!$A$2:$E$32,2,0)/1000,0)) -> 0 | S3: =(IFERROR(VLOOKUP(S$1,[2]Hoja1!$A$2:$E$32,2,0)/1000,0)) -> 0 | T3: =(IFERROR(VLOOKUP(T$1,[2]Hoja1!$A$2:$E$32,2,0)/1000,0)) -> 0 | U3: =IFERROR(VLOOKUP(U$1,[2]Hoja1!$A$2:$E$32,2,0)/1000,0) -> 0 | V3: =IFERROR(VLOOKUP(V$1,[2]Hoja1!$A$2:$E$32,2,0)/1000,0) -> 0 | W3: =IFERROR(VLOOKUP(W$1,[2]Hoja1!$A$2:$E$32,2,0)/1000,0) -> 0 | X3: =IFERROR(VLOOKUP(X$1,[2]Hoja1!$A$2:$E$32,2,0)/1000,0) -> 0 | Y3: =+Q3+SUM(R3:X3) -> 6291.6 | Z3: =IFERROR(VLOOKUP(Z$1,[2]Hoja1!$A$2:$E$32,2,0)/1000,0) -> 0 | AA3: =IFERROR(VLOOKUP(AA$1,[2]Hoja1!$A$2:$E$32,2,0)/1000,0) -> 0 | AB3: =(IFERROR(VLOOKUP(AB$1,[2]Hoja1!$A$2:$E$32,2,0)/1000,0)) -> 0 | AC3: =(IFERROR(VLOOKUP(AC$1,[2]Hoja1!$A$2:$E$32,2,0)/1000,0)) -> 0 | AD3: =(IFERROR(VLOOKUP(AD$1,[2]Hoja1!$A$2:$E$32,2,0)/1000,0)) -> 0 | AE3: =(IFERROR(VLOOKUP(AE$1,[2]Hoja1!$A$2:$E$32,2,0)/1000,0)) -> 0 | AF3: =(IFERROR(VLOOKUP(AF$1,[2]Hoja1!$A$2:$E$32,2,0)/1000,0)) -> 0 | AG3: =+Y3+SUM(Z3:AF3) -> 6291.6 | AH3: =(IFERROR(VLOOKUP(AH$1,[2]Hoja1!$A$2:$E$32,2,0)/1000,0)) -> 0 | AI3: =(IFERROR(VLOOKUP(AI$1,[2]Hoja1!$A$2:$E$32,2,0)/1000,0)) -> 0 | AJ3: =(IFERROR(VLOOKUP(AJ$1,[2]Hoja1!$A$2:$E$32,2,0)/1000,0)) -> 0 | AK3: =+AG3+SUM(AH3:AJ3) -> 6291.6
A4: % Cumplimiento | B4: =IFERROR(+B3/B2,0) -> 0.68447619 | C4: =IFERROR(+C3/C2,0) -> 0.69122278 | D4: =IFERROR(+D3/D2,0) -> 1.262868 | E4: =IFERROR(+E3/E2,0) -> 1.1227407 | F4: =IFERROR(+F3/F2,0) -> 1.11 | G4: =IFERROR(+G3/G2,0) -> 0.64787072 | H4: =IFERROR(+H3/H2,0) -> 2.3148667 | I4: =IFERROR(+I3/I2,0) -> 3.8578 | ... AK4: =IFERROR(+AK3/AK2,0) -> 0.34953333
A5: Ext Codazzi Proy | B5: =+HLOOKUP(B$1,[3]Resumen!$B$1:$AH$27,2,0) -> 600 | C5: =+HLOOKUP(C$1,[3]Resumen!$B$1:$AH$27,2,0) -> 600 | D5: =+HLOOKUP(D$1,[3]Resumen!$B$1:$AH$27,2,0) -> 650 | E5: =+HLOOKUP(E$1,[3]Resumen!$B$1:$AH$27,2,0) -> 700 | F5: =+HLOOKUP(F$1,[3]Resumen!$B$1:$AH$27,2,0) -> 700 | G5: =+HLOOKUP(G$1,[3]Resumen!$B$1:$AH$27,2,0) -> 800 | H5: =+HLOOKUP(H$1,[3]Resumen!$B$1:$AH$27,2,0) -> 300 | I5: =+HLOOKUP(I$1,[3]Resumen!$B$1:$AH$27,2,0) -> 0 | J5: =+SUM(B5:I5) -> 4350 | K5: =+HLOOKUP(K$1,[3]Resumen!$B$1:$AH$27,2,0) -> 400 | L5: =+HLOOKUP(L$1,[3]Resumen!$B$1:$AH$27,2,0) -> 750 | M5: =+HLOOKUP(M$1,[3]Resumen!$B$1:$AH$27,2,0) -> 750 | N5: =+HLOOKUP(N$1,[3]Resumen!$B$1:$AH$27,2,0) -> 750 | O5: =+HLOOKUP(O$1,[3]Resumen!$B$1:$AH$27,2,0) -> 750 | P5: =+HLOOKUP(P$1,[3]Resumen!$B$1:$AH$27,2,0) -> 400 | Q5: =+J5+SUM(K5:P5) -> 8150 | R5: =+HLOOKUP(R$1,[3]Resumen!$B$1:$AH$27,2,0) -> 400 | S5: =+HLOOKUP(S$1,[3]Resumen!$B$1:$AH$27,2,0) -> 750 | T5: =+HLOOKUP(T$1,[3]Resumen!$B$1:$AH$27,2,0) -> 750 | U5: =+HLOOKUP(U$1,[3]Resumen!$B$1:$AH$27,2,0) -> 750 | V5: =+HLOOKUP(V$1,[3]Resumen!$B$1:$AH$27,2,0) -> 750 | W5: =+HLOOKUP(W$1,[3]Resumen!$B$1:$AH$27,2,0) -> 750 | X5: =+HLOOKUP(X$1,[3]Resumen!$B$1:$AH$27,2,0) -> 400 | Y5: =+Q5+SUM(R5:X5) -> 12700 | Z5: =+HLOOKUP(Z$1,[3]Resumen!$B$1:$AH$27,2,0) -> 400 | AA5: =+HLOOKUP(AA$1,[3]Resumen!$B$1:$AH$27,2,0) -> 750 | AB5: =+HLOOKUP(AB$1,[3]Resumen!$B$1:$AH$27,2,0) -> 400 | AC5: =+HLOOKUP(AC$1,[3]Resumen!$B$1:$AH$27,2,0) -> 0 | AD5: =+HLOOKUP(AD$1,[3]Resumen!$B$1:$AH$27,2,0) -> 750 | AE5: =+HLOOKUP(AE$1,[3]Resumen!$B$1:$AH$27,2,0) -> 750 | AF5: =+HLOOKUP(AF$1,[3]Resumen!$B$1:$AH$27,2,0) -> 400 | AG5: =+Y5+SUM(Z5:AF5) -> 16150 | AH5: =+HLOOKUP(AH$1,[3]Resumen!$B$1:$AH$27,2,0) -> 750 | AI5: =+HLOOKUP(AI$1,[3]Resumen!$B$1:$AH$27,2,0) -> 750 | AJ5: =+HLOOKUP(AJ$1,[3]Resumen!$B$1:$AH$27,2,0) -> 600 | AK5: =+AG5+SUM(AH5:AJ5) -> 18250
A6: Ext Codazzi Real | B6: =+IFERROR(VLOOKUP(B$1,'[4]Base de Datos'!$A$5:$EI$35,36,0)/1000,0) -> 701.25 | C6: =+IFERROR(VLOOKUP(C$1,'[4]Base de Datos'!$A$5:$EI$35,36,0)/1000,0) -> 319 | D6: =+IFERROR(VLOOKUP(D$1,'[4]Base de Datos'!$A$5:$EI$35,36,0)/1000,0) -> 726 | E6: =+IFERROR(VLOOKUP(E$1,'[4]Base de Datos'!$A$5:$EI$35,36,0)/1000,0) -> 792 | F6: =+IFERROR(VLOOKUP(F$1,'[4]Base de Datos'!$A$5:$EI$35,36,0)/1000,0) -> 759 | G6: =+IFERROR(VLOOKUP(G$1,'[4]Base de Datos'!$A$5:$EI$35,36,0)/1000,0) -> 555.5 | H6: =+IFERROR(VLOOKUP(H$1,'[4]Base de Datos'!$A$5:$EI$35,36,0)/1000,0) -> 830.5 | I6: =+IFERROR(VLOOKUP(I$1,'[4]Base de Datos'!$A$5:$EI$35,36,0)/1000,0) -> 527.609 | J6: =+SUM(B6:I6) -> 5210.859 | K6: =+IFERROR(VLOOKUP(K$1,'[4]Base de Datos'!$A$5:$EI$35,36,0)/1000,0) -> 187 | L6: =+IFERROR(VLOOKUP(L$1,'[4]Base de Datos'!$A$5:$EI$35,36,0)/1000,0) -> 613.25 | M6: =+IFERROR(VLOOKUP(M$1,'[4]Base de Datos'!$A$5:$EI$35,36,0)/1000,0) -> 728.75 | N6: =+IFERROR(VLOOKUP(N$1,'[4]Base de Datos'!$A$5:$EI$35,36,0)/1000,0) -> 0 | O6: =+IFERROR(VLOOKUP(O$1,'[4]Base de Datos'!$A$5:$EI$35,36,0)/1000,0) -> 0 | P6: =+IFERROR(VLOOKUP(P$1,'[4]Base de Datos'!$A$5:$EI$35,36,0)/1000,0) -> 0 | Q6: =+J6+SUM(K6:P6) -> 6739.859 | R6: =+IFERROR(VLOOKUP(R$1,'[4]Base de Datos'!$A$5:$EI$35,36,0)/1000,0) -> 0 | S6: =+IFERROR(VLOOKUP(S$1,'[4]Base de Datos'!$A$5:$EI$35,36,0)/1000,0) -> 0 | T6: =+IFERROR(VLOOKUP(T$1,'[4]Base de Datos'!$A$5:$EI$35,36,0)/1000,0) -> 0 | U6: =+IFERROR(VLOOKUP(U$1,'[4]Base de Datos'!$A$5:$EI$35,36,0)/1000,0) -> 0 | V6: =+IFERROR(VLOOKUP(V$1,'[4]Base de Datos'!$A$5:$EI$35,36,0)/1000,0) -> 0 | W6: =+IFERROR(VLOOKUP(W$1,'[4]Base de Datos'!$A$5:$EI$35,36,0)/1000,0) -> 0 | X6: =+IFERROR(VLOOKUP(X$1,'[4]Base de Datos'!$A$5:$EI$35,36,0)/1000,0) -> 0 | Y6: =+Q6+SUM(R6:X6) -> 6739.859 | Z6: =+IFERROR(VLOOKUP(Z$1,'[4]Base de Datos'!$A$5:$EI$35,36,0)/1000,0) -> 0 | AA6: =+IFERROR(VLOOKUP(AA$1,'[4]Base de Datos'!$A$5:$EI$35,36,0)/1000,0) -> 0 | AB6: =+IFERROR(VLOOKUP(AB$1,'[4]Base de Datos'!$A$5:$EI$35,36,0)/1000,0) -> 0 | AC6: =+IFERROR(VLOOKUP(AC$1,'[4]Base de Datos'!$A$5:$EI$35,36,0)/1000,0) -> 0 | AD6: =+IFERROR(VLOOKUP(AD$1,'[4]Base de Datos'!$A$5:$EI$35,36,0)/1000,0) -> 0 | AE6: =+IFERROR(VLOOKUP(AE$1,'[4]Base de Datos'!$A$5:$EI$35,36,0)/1000,0) -> 0 | AF6: =+IFERROR(VLOOKUP(AF$1,'[4]Base de Datos'!$A$5:$EI$35,36,0)/1000,0) -> 0 | AG6: =+Y6+SUM(Z6:AF6) -> 6739.859 | AH6: =+IFERROR(VLOOKUP(AH$1,'[4]Base de Datos'!$A$5:$EI$35,36,0)/1000,0) -> 0 | AI6: =+IFERROR(VLOOKUP(AI$1,'[4]Base de Datos'!$A$5:$EI$35,36,0)/1000,0) -> 0 | AJ6: =+IFERROR(VLOOKUP(AJ$1,'[4]Base de Datos'!$A$5:$EI$35,36,0)/1000,0) -> 0 | AK6: =+AG6+SUM(AH6:AJ6) -> 6739.859 | AL6: =+AG6/AG5 -> 0.41732873 | AM6: =1-15% -> 0.85
A7: CPO | B7: =IFERROR(VLOOKUP(B$1,'[4]Base de Datos'!$A$5:$EI$35,34,0)/1000,0) -> 162.948 | C7: =IFERROR(VLOOKUP(C$1,'[4]Base de Datos'!$A$5:$EI$35,34,0)/1000,0) -> 64.56 | D7: =IFERROR(VLOOKUP(D$1,'[4]Base de Datos'!$A$5:$EI$35,34,0)/1000,0) -> 155.836 | E7: =IFERROR(VLOOKUP(E$1,'[4]Base de Datos'!$A$5:$EI$35,34,0)/1000,0) -> 158.532 | F7: =IFERROR(VLOOKUP(F$1,'[4]Base de Datos'!$A$5:$EI$35,34,0)/1000,0) -> 159.892 | G7: =IFERROR(VLOOKUP(G$1,'[4]Base de Datos'!$A$5:$EI$35,34,0)/1000,0) -> 115.172 | H7: =IFERROR(VLOOKUP(H$1,'[4]Base de Datos'!$A$5:$EI$35,34,0)/1000,0) -> 170.816 | I7: =IFERROR(VLOOKUP(I$1,'[4]Base de Datos'!$A$5:$EI$35,34,0)/1000,0) -> 122.624 | J7: =+SUM(B7:I7) -> 1110.38 | K7: =IFERROR(VLOOKUP(K$1,'[4]Base de Datos'!$A$5:$EI$35,34,0)/1000,0) -> 36.28 | L7: =IFERROR(VLOOKUP(L$1,'[4]Base de Datos'!$A$5:$EI$35,34,0)/1000,0) -> 134.408 | M7: =IFERROR(VLOOKUP(M$1,'[4]Base de Datos'!$A$5:$EI$35,34,0)/1000,0) -> 162.652 | N7: =IFERROR(VLOOKUP(N$1,'[4]Base de Datos'!$A$5:$EI$35,34,0)/1000,0) -> 0 | O7: =IFERROR(VLOOKUP(O$1,'[4]Base de Datos'!$A$5:$EI$35,34,0)/1000,0) -> 0 | P7: =IFERROR(VLOOKUP(P$1,'[4]Base de Datos'!$A$5:$EI$35,34,0)/1000,0) -> 0 | Q7: =+J7+SUM(K7:P7) -> 1443.72 | R7: =IFERROR(VLOOKUP(R$1,'[4]Base de Datos'!$A$5:$EI$35,34,0)/1000,0) -> 0 | S7: =IFERROR(VLOOKUP(S$1,'[4]Base de Datos'!$A$5:$EI$35,34,0)/1000,0) -> 0 | T7: =IFERROR(VLOOKUP(T$1,'[4]Base de Datos'!$A$5:$EI$35,34,0)/1000,0) -> 0 | U7: =IFERROR(VLOOKUP(U$1,'[4]Base de Datos'!$A$5:$EI$35,34,0)/1000,0) -> 0 | V7: =IFERROR(VLOOKUP(V$1,'[4]Base de Datos'!$A$5:$EI$35,34,0)/1000,0) -> 0 | W7: =IFERROR(VLOOKUP(W$1,'[4]Base de Datos'!$A$5:$EI$35,34,0)/1000,0) -> 0 | X7: =IFERROR(VLOOKUP(X$1,'[4]Base de Datos'!$A$5:$EI$35,34,0)/1000,0) -> 0 | Y7: =+Q7+SUM(R7:X7) -> 1443.72 | Z7: =IFERROR(VLOOKUP(Z$1,'[4]Base de Datos'!$A$5:$EI$35,34,0)/1000,0) -> 0 | AA7: =IFERROR(VLOOKUP(AA$1,'[4]Base de Datos'!$A$5:$EI$35,34,0)/1000,0) -> 0 | AB7: =IFERROR(VLOOKUP(AB$1,'[4]Base de Datos'!$A$5:$EI$35,34,0)/1000,0) -> 0 | AC7: =IFERROR(VLOOKUP(AC$1,'[4]Base de Datos'!$A$5:$EI$35,34,0)/1000,0) -> 0 | AD7: =IFERROR(VLOOKUP(AD$1,'[4]Base de Datos'!$A$5:$EI$35,34,0)/1000,0) -> 0 | AE7: =IFERROR(VLOOKUP(AE$1,'[4]Base de Datos'!$A$5:$EI$35,34,0)/1000,0) -> 0 | AF7: =IFERROR(VLOOKUP(AF$1,'[4]Base de Datos'!$A$5:$EI$35,34,0)/1000,0) -> 0 | AG7: =+Y7+SUM(Z7:AF7) -> 1443.72 | AH7: =IFERROR(VLOOKUP(AH$1,'[4]Base de Datos'!$A$5:$EI$35,34,0)/1000,0) -> 0 | AI7: =IFERROR(VLOOKUP(AI$1,'[4]Base de Datos'!$A$5:$EI$35,34,0)/1000,0) -> 12.417 | AJ7: =IFERROR(VLOOKUP(AJ$1,'[4]Base de Datos'!$A$5:$EI$35,34,0)/1000,0) -> 11.059 | AK7: =+AG7+SUM(AH7:AJ7) -> 1467.196
A8: =+_xlfn.CONCAT("TEA% ", B44,"%") -> TEA% 21.6% | B8: =IFERROR(+B7/B6,0) -> 0.23236791 | C8: =IFERROR(+C7/C6,0) -> 0.20238245 | D8: =IFERROR(+D7/D6,0) -> 0.21465014 | E8: =IFERROR(+E7/E6,0) -> 0.20016667 | F8: =IFERROR(+F7/F6,0) -> 0.2106614 | G8: =IFERROR(+G7/G6,0) -> 0.20733033 | H8: =IFERROR(+H7/H6,0) -> 0.20567851 | I8: =IFERROR(+I7/I6,0) -> 0.23241453 | ... Y8: =IFERROR(+Y7/Y6,0) -> 0.21420626 | Z8: 0.216 | AA8: 0.216 | AB8: =IFERROR(+AB7/AB6,0) -> 0 | AC8: =IFERROR(+AC7/AC6,0) -> 0 | AD8: =IFERROR(+AD7/AD6,0) -> 0 | AE8: =IFERROR(+AE7/AE6,0) -> 0 | AF8: =IFERROR(+AF7/AF6,0) -> 0 | AG8: =IFERROR(+AG7/AG6,0) -> 0.21420626 | AH8: =IFERROR(+AH7/AH6,0) -> 0 | AI8: =IFERROR(+AI7/AI6,0) -> 0 | ... AK8: =IFERROR(+AK7/AK6,0) -> 0.21768942
A9: MLB Proyección | B9: =+HLOOKUP(B$1,'[1]RFF Resumen'!$C$16:$AG$153,42,0) -> 74.194438 | C9: =+HLOOKUP(C$1,'[1]RFF Resumen'!$C$16:$AG$153,42,0) -> 131.18888 | D9: =+HLOOKUP(D$1,'[1]RFF Resumen'!$C$16:$AG$153,42,0) -> 188.1444 | E9: =+HLOOKUP(E$1,'[1]RFF Resumen'!$C$16:$AG$153,42,0) -> 185.84812 | F9: =+HLOOKUP(F$1,'[1]RFF Resumen'!$C$16:$AG$153,42,0) -> 176.54624 | G9: =+HLOOKUP(G$1,'[1]RFF Resumen'!$C$16:$AG$153,42,0) -> 187.05464 | H9: =+HLOOKUP(H$1,'[1]RFF Resumen'!$C$16:$AG$153,42,0) -> 38.67605 | I9: =+HLOOKUP(I$1,'[1]RFF Resumen'!$C$16:$AG$153,42,0) -> 14.911501 | J9: =+SUM(B9:I9) -> 996.56427 | K9: =+HLOOKUP(K$1,'[1]RFF Resumen'!$C$16:$AG$153,42,0) -> 109.66612 | L9: =+HLOOKUP(L$1,'[1]RFF Resumen'!$C$16:$AG$153,42,0) -> 213.94057 | M9: =+HLOOKUP(M$1,'[1]RFF Resumen'!$C$16:$AG$153,42,0) -> 261.61757 | N9: =+HLOOKUP(N$1,'[1]RFF Resumen'!$C$16:$AG$153,42,0) -> 334.97398 | O9: =+HLOOKUP(O$1,'[1]RFF Resumen'!$C$16:$AG$153,42,0) -> 299.2532 | P9: =+HLOOKUP(P$1,'[1]RFF Resumen'!$C$16:$AG$153,42,0) -> 100.55884 | Q9: =+J9+SUM(K9:P9) -> 2316.5746 | R9: =+HLOOKUP(R$1,'[1]RFF Resumen'!$C$16:$AG$153,42,0) -> 134.96412 | S9: =+HLOOKUP(S$1,'[1]RFF Resumen'!$C$16:$AG$153,42,0) -> 242.35995 | T9: =+HLOOKUP(T$1,'[1]RFF Resumen'!$C$16:$AG$153,42,0) -> 281.29552 | U9: =+HLOOKUP(U$1,'[1]RFF Resumen'!$C$16:$AG$153,42,0) -> 281.98829 | V9: =+HLOOKUP(V$1,'[1]RFF Resumen'!$C$16:$AG$153,42,0) -> 239.20743 | W9: =+HLOOKUP(W$1,'[1]RFF Resumen'!$C$16:$AG$153,42,0) -> 296.26415 | X9: =+HLOOKUP(X$1,'[1]RFF Resumen'!$C$16:$AG$153,42,0) -> 98.729603 | Y9: =+Q9+SUM(R9:X9) -> 3891.3836 | Z9: =+HLOOKUP(Z$1,'[1]RFF Resumen'!$C$16:$AG$153,42,0) -> 208.34388 | AA9: =+HLOOKUP(AA$1,'[1]RFF Resumen'!$C$16:$AG$153,42,0) -> 312.6806 | AB9: =+HLOOKUP(AB$1,'[1]RFF Resumen'!$C$16:$AG$153,42,0) -> 245.19333 | AC9: =+HLOOKUP(AC$1,'[1]RFF Resumen'!$C$16:$AG$153,42,0) -> 45.915169 | AD9: =+HLOOKUP(AD$1,'[1]RFF Resumen'!$C$16:$AG$153,42,0) -> 238.5925 | AE9: =+HLOOKUP(AE$1,'[1]RFF Resumen'!$C$16:$AG$153,42,0) -> 313.96496 | AF9: =+HLOOKUP(AF$1,'[1]RFF Resumen'!$C$16:$AG$153,42,0) -> 92.033268 | AG9: =+Y9+SUM(Z9:AF9) -> 5348.1073 | AH9: =+HLOOKUP(AH$1,'[1]RFF Resumen'!$C$16:$AG$153,42,0) -> 188.96172 | AI9: =+HLOOKUP(AI$1,'[1]RFF Resumen'!$C$16:$AG$153,42,0) -> 254.48742 | AJ9: =+HLOOKUP(AJ$1,'[1]RFF Resumen'!$C$16:$AG$153,42,0) -> 368.44352 | AK9: =+AG9+SUM(AH9:AJ9) -> 6160
A10: MLB Real | B10: =IFERROR(VLOOKUP(B$1,[2]Hoja1!$A$2:$E$32,4,0)/1000,0) -> 113.144 | C10: =IFERROR(VLOOKUP(C$1,[2]Hoja1!$A$2:$E$32,4,0)/1000,0) -> 191.936 | D10: =IFERROR(VLOOKUP(D$1,[2]Hoja1!$A$2:$E$32,4,0)/1000,0) -> 214.317 | E10: =IFERROR(VLOOKUP(E$1,[2]Hoja1!$A$2:$E$32,4,0)/1000,0) -> 187.637 | F10: =IFERROR(VLOOKUP(F$1,[2]Hoja1!$A$2:$E$32,4,0)/1000,0) -> 227.728 | G10: =IFERROR(VLOOKUP(G$1,[2]Hoja1!$A$2:$E$32,4,0)/1000,0) -> 275.93 | H10: =IFERROR(VLOOKUP(H$1,[2]Hoja1!$A$2:$E$32,4,0)/1000,0) -> 96.93 | I10: =IFERROR(VLOOKUP(I$1,[2]Hoja1!$A$2:$E$32,4,0)/1000,0) -> 29.045 | J10: =+SUM(B10:I10) -> 1336.667 | K10: =IFERROR(VLOOKUP(K$1,[2]Hoja1!$A$2:$E$32,4,0)/1000,0) -> 117.54 | L10: =IFERROR(VLOOKUP(L$1,[2]Hoja1!$A$2:$E$32,4,0)/1000,0) -> 226.516 | M10: =IFERROR(VLOOKUP(M$1,[2]Hoja1!$A$2:$E$32,4,0)/1000,0) -> 289.03 | N10: =IFERROR(VLOOKUP(N$1,[2]Hoja1!$A$2:$E$32,4,0)/1000,0) -> 0 | O10: =IFERROR(VLOOKUP(O$1,[2]Hoja1!$A$2:$E$32,4,0)/1000,0) -> 0 | P10: =IFERROR(VLOOKUP(P$1,[2]Hoja1!$A$2:$E$32,4,0)/1000,0) -> 0 | Q10: =+J10+SUM(K10:P10) -> 1969.753 | R10: =IFERROR(VLOOKUP(R$1,[2]Hoja1!$A$2:$E$32,4,0)/1000,0) -> 0 | S10: =IFERROR(VLOOKUP(S$1,[2]Hoja1!$A$2:$E$32,4,0)/1000,0) -> 0 | T10: =IFERROR(VLOOKUP(T$1,[2]Hoja1!$A$2:$E$32,4,0)/1000,0) -> 0 | U10: =IFERROR(VLOOKUP(U$1,[2]Hoja1!$A$2:$E$32,4,0)/1000,0) -> 0 | V10: =IFERROR(VLOOKUP(V$1,[2]Hoja1!$A$2:$E$32,4,0)/1000,0) -> 0 | W10: =IFERROR(VLOOKUP(W$1,[2]Hoja1!$A$2:$E$32,4,0)/1000,0) -> 0 | X10: =IFERROR(VLOOKUP(X$1,[2]Hoja1!$A$2:$E$32,4,0)/1000,0) -> 0 | Y10: =+Q10+SUM(R10:X10) -> 1969.753 | Z10: =IFERROR(VLOOKUP(Z$1,[2]Hoja1!$A$2:$E$32,4,0)/1000,0) -> 0 | AA10: =IFERROR(VLOOKUP(AA$1,[2]Hoja1!$A$2:$E$32,4,0)/1000,0) -> 0 | AB10: =IFERROR(VLOOKUP(AB$1,[2]Hoja1!$A$2:$E$32,4,0)/1000,0) -> 0 | AC10: =IFERROR(VLOOKUP(AC$1,[2]Hoja1!$A$2:$E$32,4,0)/1000,0) -> 0 | AD10: =IFERROR(VLOOKUP(AD$1,[2]Hoja1!$A$2:$E$32,4,0)/1000,0) -> 0 | AE10: =IFERROR(VLOOKUP(AE$1,[2]Hoja1!$A$2:$E$32,4,0)/1000,0) -> 0 | AF10: =IFERROR(VLOOKUP(AF$1,[2]Hoja1!$A$2:$E$32,4,0)/1000,0) -> 0 | AG10: =+Y10+SUM(Z10:AF10) -> 1969.753 | AH10: =IFERROR(VLOOKUP(AH$1,[2]Hoja1!$A$2:$E$32,4,0)/1000,0) -> 0 | AI10: =IFERROR(VLOOKUP(AI$1,[2]Hoja1!$A$2:$E$32,4,0)/1000,0) -> 0 | AJ10: =IFERROR(VLOOKUP(AJ$1,[2]Hoja1!$A$2:$E$32,4,0)/1000,0) -> 0 | AK10: =+AG10+SUM(AH10:AJ10) -> 1969.753
A11: % Cumplimiento | B11: =IFERROR(+B10/B9,0) -> 1.5249661 | C11: =IFERROR(+C10/C9,0) -> 1.4630508 | D11: =IFERROR(+D10/D9,0) -> 1.1391091 | E11: =IFERROR(+E10/E9,0) -> 1.0096255 | F11: =IFERROR(+F10/F9,0) -> 1.2899057 | G11: =IFERROR(+G10/G9,0) -> 1.4751305 | H11: =IFERROR(+H10/H9,0) -> 2.5062022 | I11: =IFERROR(+I10/I9,0) -> 1.9478254 | ... AK11: =IFERROR(+AK10/AK9,0) -> 0.3197651
A12: Ext MLB Proy | B12: =+HLOOKUP(B$1,[3]Resumen!$B$1:$AH$27,4,0) -> 150 | C12: =+HLOOKUP(C$1,[3]Resumen!$B$1:$AH$27,4,0) -> 150 | D12: =+HLOOKUP(D$1,[3]Resumen!$B$1:$AH$27,4,0) -> 200 | E12: =+HLOOKUP(E$1,[3]Resumen!$B$1:$AH$27,4,0) -> 200 | F12: =+HLOOKUP(F$1,[3]Resumen!$B$1:$AH$27,4,0) -> 200 | G12: =+HLOOKUP(G$1,[3]Resumen!$B$1:$AH$27,4,0) -> 200 | H12: =+HLOOKUP(H$1,[3]Resumen!$B$1:$AH$27,4,0) -> 0 | I12: =+HLOOKUP(I$1,[3]Resumen!$B$1:$AH$27,4,0) -> 0 | J12: =+SUM(B12:I12) -> 1100 | K12: =+HLOOKUP(K$1,[3]Resumen!$B$1:$AH$27,4,0) -> 100 | L12: =+HLOOKUP(L$1,[3]Resumen!$B$1:$AH$27,4,0) -> 350 | M12: =+HLOOKUP(M$1,[3]Resumen!$B$1:$AH$27,4,0) -> 350 | N12: =+HLOOKUP(N$1,[3]Resumen!$B$1:$AH$27,4,0) -> 350 | O12: =+HLOOKUP(O$1,[3]Resumen!$B$1:$AH$27,4,0) -> 350 | P12: =+HLOOKUP(P$1,[3]Resumen!$B$1:$AH$27,4,0) -> 300 | Q12: =+J12+SUM(K12:P12) -> 2900 | R12: =+HLOOKUP(R$1,[3]Resumen!$B$1:$AH$27,4,0) -> 100 | S12: =+HLOOKUP(S$1,[3]Resumen!$B$1:$AH$27,4,0) -> 250 | T12: =+HLOOKUP(T$1,[3]Resumen!$B$1:$AH$27,4,0) -> 250 | U12: =+HLOOKUP(U$1,[3]Resumen!$B$1:$AH$27,4,0) -> 300 | V12: =+HLOOKUP(V$1,[3]Resumen!$B$1:$AH$27,4,0) -> 300 | W12: =+HLOOKUP(W$1,[3]Resumen!$B$1:$AH$27,4,0) -> 300 | X12: =+HLOOKUP(X$1,[3]Resumen!$B$1:$AH$27,4,0) -> 0 | Y12: =+Q12+SUM(R12:X12) -> 4400 | Z12: =+HLOOKUP(Z$1,[3]Resumen!$B$1:$AH$27,4,0) -> 350 | AA12: =+HLOOKUP(AA$1,[3]Resumen!$B$1:$AH$27,4,0) -> 350 | AB12: =+HLOOKUP(AB$1,[3]Resumen!$B$1:$AH$27,4,0) -> 280 | AC12: =+HLOOKUP(AC$1,[3]Resumen!$B$1:$AH$27,4,0) -> 0 | AD12: =+HLOOKUP(AD$1,[3]Resumen!$B$1:$AH$27,4,0) -> 300 | AE12: =+HLOOKUP(AE$1,[3]Resumen!$B$1:$AH$27,4,0) -> 300 | AF12: =+HLOOKUP(AF$1,[3]Resumen!$B$1:$AH$27,4,0) -> 150 | AG12: =+Y12+SUM(Z12:AF12) -> 6130 | AH12: =+HLOOKUP(AH$1,[3]Resumen!$B$1:$AH$27,4,0) -> 100 | AI12: =+HLOOKUP(AI$1,[3]Resumen!$B$1:$AH$27,4,0) -> 370 | AJ12: =+HLOOKUP(AJ$1,[3]Resumen!$B$1:$AH$27,4,0) -> 400 | AK12: =+AG12+SUM(AH12:AJ12) -> 7000
A13: Ext MLB Real | B13: =+IFERROR(VLOOKUP(B$1,'[4]Base de Datos'!$A$5:$EI$35,7,0)/1000,0) -> 0 | C13: =+IFERROR(VLOOKUP(C$1,'[4]Base de Datos'!$A$5:$EI$35,7,0)/1000,0) -> 331.5 | D13: =+IFERROR(VLOOKUP(D$1,'[4]Base de Datos'!$A$5:$EI$35,7,0)/1000,0) -> 316.2 | E13: =+IFERROR(VLOOKUP(E$1,'[4]Base de Datos'!$A$5:$EI$35,7,0)/1000,0) -> 323.31 | F13: =+IFERROR(VLOOKUP(F$1,'[4]Base de Datos'!$A$5:$EI$35,7,0)/1000,0) -> 163.2 | G13: =+IFERROR(VLOOKUP(G$1,'[4]Base de Datos'!$A$5:$EI$35,7,0)/1000,0) -> 285.6 | H13: =+IFERROR(VLOOKUP(H$1,'[4]Base de Datos'!$A$5:$EI$35,7,0)/1000,0) -> 0 | I13: =+IFERROR(VLOOKUP(I$1,'[4]Base de Datos'!$A$5:$EI$35,7,0)/1000,0) -> 0 | J13: =+SUM(B13:I13) -> 1419.81 | K13: =+IFERROR(VLOOKUP(K$1,'[4]Base de Datos'!$A$5:$EI$35,7,0)/1000,0) -> 142.8 | L13: =+IFERROR(VLOOKUP(L$1,'[4]Base de Datos'!$A$5:$EI$35,7,0)/1000,0) -> 357 | M13: =+IFERROR(VLOOKUP(M$1,'[4]Base de Datos'!$A$5:$EI$35,7,0)/1000,0) -> 351.9 | N13: =+IFERROR(VLOOKUP(N$1,'[4]Base de Datos'!$A$5:$EI$35,7,0)/1000,0) -> 0 | O13: =+IFERROR(VLOOKUP(O$1,'[4]Base de Datos'!$A$5:$EI$35,7,0)/1000,0) -> 0 | P13: =+IFERROR(VLOOKUP(P$1,'[4]Base de Datos'!$A$5:$EI$35,7,0)/1000,0) -> 0 | Q13: =+J13+SUM(K13:P13) -> 2271.51 | R13: =+IFERROR(VLOOKUP(R$1,'[4]Base de Datos'!$A$5:$EI$35,7,0)/1000,0) -> 0 | S13: =+IFERROR(VLOOKUP(S$1,'[4]Base de Datos'!$A$5:$EI$35,7,0)/1000,0) -> 0 | T13: =+IFERROR(VLOOKUP(T$1,'[4]Base de Datos'!$A$5:$EI$35,7,0)/1000,0) -> 0 | U13: =+IFERROR(VLOOKUP(U$1,'[4]Base de Datos'!$A$5:$EI$35,7,0)/1000,0) -> 0 | V13: =+IFERROR(VLOOKUP(V$1,'[4]Base de Datos'!$A$5:$EI$35,7,0)/1000,0) -> 0 | W13: =+IFERROR(VLOOKUP(W$1,'[4]Base de Datos'!$A$5:$EI$35,7,0)/1000,0) -> 0 | X13: =+IFERROR(VLOOKUP(X$1,'[4]Base de Datos'!$A$5:$EI$35,7,0)/1000,0) -> 0 | Y13: =+Q13+SUM(R13:X13) -> 2271.51 | Z13: =+IFERROR(VLOOKUP(Z$1,'[4]Base de Datos'!$A$5:$EI$35,7,0)/1000,0) -> 0 | AA13: =+IFERROR(VLOOKUP(AA$1,'[4]Base de Datos'!$A$5:$EI$35,7,0)/1000,0) -> 0 | AB13: =+IFERROR(VLOOKUP(AB$1,'[4]Base de Datos'!$A$5:$EI$35,7,0)/1000,0) -> 0 | AC13: =+IFERROR(VLOOKUP(AC$1,'[4]Base de Datos'!$A$5:$EI$35,7,0)/1000,0) -> 0 | AD13: =+IFERROR(VLOOKUP(AD$1,'[4]Base de Datos'!$A$5:$EI$35,7,0)/1000,0) -> 0 | AE13: =+IFERROR(VLOOKUP(AE$1,'[4]Base de Datos'!$A$5:$EI$35,7,0)/1000,0) -> 0 | AF13: =+IFERROR(VLOOKUP(AF$1,'[4]Base de Datos'!$A$5:$EI$35,7,0)/1000,0) -> 0 | AG13: =+Y13+SUM(Z13:AF13) -> 2271.51 | AH13: =+IFERROR(VLOOKUP(AH$1,'[4]Base de Datos'!$A$5:$EI$35,7,0)/1000,0) -> 0 | AI13: =+IFERROR(VLOOKUP(AI$1,'[4]Base de Datos'!$A$5:$EI$35,7,0)/1000,0) -> 0 | AJ13: =+IFERROR(VLOOKUP(AJ$1,'[4]Base de Datos'!$A$5:$EI$35,7,0)/1000,0) -> 0 | AK13: =+AG13+SUM(AH13:AJ13) -> 2271.51 | AL13: =+AG13/AG12 -> 0.37055628
A14: CPO | B14: =+IFERROR(VLOOKUP(B$1,'[4]Base de Datos'!$A$5:$EI$35,5,0)/1000,0) -> 0 | C14: =+IFERROR(VLOOKUP(C$1,'[4]Base de Datos'!$A$5:$EI$35,5,0)/1000,0) -> 64.044 | D14: =+IFERROR(VLOOKUP(D$1,'[4]Base de Datos'!$A$5:$EI$35,5,0)/1000,0) -> 59.259 | E14: =+IFERROR(VLOOKUP(E$1,'[4]Base de Datos'!$A$5:$EI$35,5,0)/1000,0) -> 57.21 | F14: =+IFERROR(VLOOKUP(F$1,'[4]Base de Datos'!$A$5:$EI$35,5,0)/1000,0) -> 27.769 | G14: =+IFERROR(VLOOKUP(G$1,'[4]Base de Datos'!$A$5:$EI$35,5,0)/1000,0) -> 53.479 | H14: =+IFERROR(VLOOKUP(H$1,'[4]Base de Datos'!$A$5:$EI$35,5,0)/1000,0) -> 0 | I14: =+IFERROR(VLOOKUP(I$1,'[4]Base de Datos'!$A$5:$EI$35,5,0)/1000,0) -> 0 | J14: =+SUM(B14:I14) -> 261.761 | K14: =+IFERROR(VLOOKUP(K$1,'[4]Base de Datos'!$A$5:$EI$35,5,0)/1000,0) -> 26.384 | L14: =+IFERROR(VLOOKUP(L$1,'[4]Base de Datos'!$A$5:$EI$35,5,0)/1000,0) -> 68.814 | M14: =+IFERROR(VLOOKUP(M$1,'[4]Base de Datos'!$A$5:$EI$35,5,0)/1000,0) -> 67.739 | N14: =+IFERROR(VLOOKUP(N$1,'[4]Base de Datos'!$A$5:$EI$35,5,0)/1000,0) -> 0 | O14: =+IFERROR(VLOOKUP(O$1,'[4]Base de Datos'!$A$5:$EI$35,5,0)/1000,0) -> 0 | P14: =+IFERROR(VLOOKUP(P$1,'[4]Base de Datos'!$A$5:$EI$35,5,0)/1000,0) -> 0 | Q14: =+J14+SUM(K14:P14) -> 424.698 | R14: =+IFERROR(VLOOKUP(R$1,'[4]Base de Datos'!$A$5:$EI$35,5,0)/1000,0) -> 0 | S14: =+IFERROR(VLOOKUP(S$1,'[4]Base de Datos'!$A$5:$EI$35,5,0)/1000,0) -> 0 | T14: =+IFERROR(VLOOKUP(T$1,'[4]Base de Datos'!$A$5:$EI$35,5,0)/1000,0) -> 0 | U14: =+IFERROR(VLOOKUP(U$1,'[4]Base de Datos'!$A$5:$EI$35,5,0)/1000,0) -> 0 | V14: =+IFERROR(VLOOKUP(V$1,'[4]Base de Datos'!$A$5:$EI$35,5,0)/1000,0) -> 0 | W14: =+IFERROR(VLOOKUP(W$1,'[4]Base de Datos'!$A$5:$EI$35,5,0)/1000,0) -> 0 | X14: =+IFERROR(VLOOKUP(X$1,'[4]Base de Datos'!$A$5:$EI$35,5,0)/1000,0) -> 0 | Y14: =+Q14+SUM(R14:X14) -> 424.698 | Z14: =+IFERROR(VLOOKUP(Z$1,'[4]Base de Datos'!$A$5:$EI$35,5,0)/1000,0) -> 0 | AA14: =+IFERROR(VLOOKUP(AA$1,'[4]Base de Datos'!$A$5:$EI$35,5,0)/1000,0) -> 0 | AB14: =+IFERROR(VLOOKUP(AB$1,'[4]Base de Datos'!$A$5:$EI$35,5,0)/1000,0) -> 0 | AC14: =+IFERROR(VLOOKUP(AC$1,'[4]Base de Datos'!$A$5:$EI$35,5,0)/1000,0) -> 0 | AD14: =+IFERROR(VLOOKUP(AD$1,'[4]Base de Datos'!$A$5:$EI$35,5,0)/1000,0) -> 0 | AE14: =+IFERROR(VLOOKUP(AE$1,'[4]Base de Datos'!$A$5:$EI$35,5,0)/1000,0) -> 0 | AF14: =+IFERROR(VLOOKUP(AF$1,'[4]Base de Datos'!$A$5:$EI$35,5,0)/1000,0) -> 0 | AG14: =+Y14+SUM(Z14:AF14) -> 424.698 | AH14: =+IFERROR(VLOOKUP(AH$1,'[4]Base de Datos'!$A$5:$EI$35,5,0)/1000,0) -> 0 | AI14: =+IFERROR(VLOOKUP(AI$1,'[4]Base de Datos'!$A$5:$EI$35,5,0)/1000,0) -> 0 | AJ14: =+IFERROR(VLOOKUP(AJ$1,'[4]Base de Datos'!$A$5:$EI$35,5,0)/1000,0) -> 0 | AK14: =+AG14+SUM(AH14:AJ14) -> 424.698
A15: =+_xlfn.CONCAT("TEA% ", B45,"%") -> TEA% 18.6% | B15: =IFERROR(+B14/B13,0) -> 0 | C15: =IFERROR(+C14/C13,0) -> 0.19319457 | D15: =IFERROR(+D14/D13,0) -> 0.18740987 | E15: =IFERROR(+E14/E13,0) -> 0.17695091 | F15: =IFERROR(+F14/F13,0) -> 0.17015319 | G15: =IFERROR(+G14/G13,0) -> 0.1872514 | H15: =IFERROR(+H14/H13,0) -> 0 | I15: =IFERROR(+I14/I13,0) -> 0 | ... M15: =IFERROR(+M14/M13,0) -> 0.19249503 | N15: 0.1964 | O15: =IFERROR(+O14/O13,0) -> 0 | P15: =IFERROR(+P14/P13,0) -> 0 | Q15: =IFERROR(+Q14/Q13,0) -> 0.18696726 | R15: =IFERROR(+R14/R13,0) -> 0 | S15: =IFERROR(+S14/S13,0) -> 0 | T15: =IFERROR(+T14/T13,0) -> 0 | U15: =IFERROR(+U14/U13,0) -> 0 | V15: =IFERROR(+V14/V13,0) -> 0 | ... AK15: =IFERROR(+AK14/AK13,0) -> 0.18696726
A16: Córdoba Proyección | B16: =+HLOOKUP(B$1,'[1]RFF Resumen'!$C$16:$AG$153,106,0) -> 60 | C16: =+HLOOKUP(C$1,'[1]RFF Resumen'!$C$16:$AG$153,106,0) -> 130 | D16: =+HLOOKUP(D$1,'[1]RFF Resumen'!$C$16:$AG$153,106,0) -> 230 | E16: =+HLOOKUP(E$1,'[1]RFF Resumen'!$C$16:$AG$153,106,0) -> 270 | F16: =+HLOOKUP(F$1,'[1]RFF Resumen'!$C$16:$AG$153,106,0) -> 280 | G16: =+HLOOKUP(G$1,'[1]RFF Resumen'!$C$16:$AG$153,106,0) -> 290 | H16: =+HLOOKUP(H$1,'[1]RFF Resumen'!$C$16:$AG$153,106,0) -> 30 | I16: =+HLOOKUP(I$1,'[1]RFF Resumen'!$C$16:$AG$153,106,0) -> 20 | J16: =+SUM(B16:I16) -> 1310 | K16: =+HLOOKUP(K$1,'[1]RFF Resumen'!$C$16:$AG$153,106,0) -> 180 | L16: =+HLOOKUP(L$1,'[1]RFF Resumen'!$C$16:$AG$153,106,0) -> 230 | M16: =+HLOOKUP(M$1,'[1]RFF Resumen'!$C$16:$AG$153,106,0) -> 260 | N16: =+HLOOKUP(N$1,'[1]RFF Resumen'!$C$16:$AG$153,106,0) -> 280 | O16: 97.724 | P16: =+HLOOKUP(P$1,'[1]RFF Resumen'!$C$16:$AG$153,106,0) -> 50 | Q16: =+J16+SUM(K16:P16) -> 2407.724 | R16: =+HLOOKUP(R$1,'[1]RFF Resumen'!$C$16:$AG$153,106,0) -> 100 | S16: =+HLOOKUP(S$1,'[1]RFF Resumen'!$C$16:$AG$153,106,0) -> 230 | T16: =+HLOOKUP(T$1,'[1]RFF Resumen'!$C$16:$AG$153,106,0) -> 270 | U16: =+HLOOKUP(U$1,'[1]RFF Resumen'!$C$16:$AG$153,106,0) -> 280 | V16: =+HLOOKUP(V$1,'[1]RFF Resumen'!$C$16:$AG$153,106,0) -> 290 | W16: =+HLOOKUP(W$1,'[1]RFF Resumen'!$C$16:$AG$153,106,0) -> 300 | X16: =+HLOOKUP(X$1,'[1]RFF Resumen'!$C$16:$AG$153,106,0) -> 40 | Y16: =+Q16+SUM(R16:X16) -> 3917.724 | Z16: =+HLOOKUP(Z$1,'[1]RFF Resumen'!$C$16:$AG$153,106,0) -> 120 | AA16: =+HLOOKUP(AA$1,'[1]RFF Resumen'!$C$16:$AG$153,106,0) -> 230 | AB16: =+HLOOKUP(AB$1,'[1]RFF Resumen'!$C$16:$AG$153,106,0) -> 260 | AC16: =+HLOOKUP(AC$1,'[1]RFF Resumen'!$C$16:$AG$153,106,0) -> 20 | AD16: =+HLOOKUP(AD$1,'[1]RFF Resumen'!$C$16:$AG$153,106,0) -> 240 | AE16: =+HLOOKUP(AE$1,'[1]RFF Resumen'!$C$16:$AG$153,106,0) -> 270 | AF16: =+HLOOKUP(AF$1,'[1]RFF Resumen'!$C$16:$AG$153,106,0) -> 50 | AG16: =+Y16+SUM(Z16:AF16) -> 5107.724 | AH16: =+HLOOKUP(AH$1,'[1]RFF Resumen'!$C$16:$AG$153,106,0) -> 160 | AI16: =+HLOOKUP(AI$1,'[1]RFF Resumen'!$C$16:$AG$153,106,0) -> 270 | AJ16: =+HLOOKUP(AJ$1,'[1]RFF Resumen'!$C$16:$AG$153,106,0) -> 70 | AK16: =+AG16+SUM(AH16:AJ16) -> 5607.724
A17: Córdoba Real | B17: =IFERROR(VLOOKUP(B$1,[2]Hoja1!$A$2:$E$32,5,0)/1000,0) -> 70.1 | C17: =IFERROR(VLOOKUP(C$1,[2]Hoja1!$A$2:$E$32,5,0)/1000,0) -> 231.41 | D17: =IFERROR(VLOOKUP(D$1,[2]Hoja1!$A$2:$E$32,5,0)/1000,0) -> 284.59 | E17: =IFERROR(VLOOKUP(E$1,[2]Hoja1!$A$2:$E$32,5,0)/1000,0) -> 342.6 | F17: =IFERROR(VLOOKUP(F$1,[2]Hoja1!$A$2:$E$32,5,0)/1000,0) -> 380.72 | G17: =IFERROR(VLOOKUP(G$1,[2]Hoja1!$A$2:$E$32,5,0)/1000,0) -> 420.65 | H17: =IFERROR(VLOOKUP(H$1,[2]Hoja1!$A$2:$E$32,5,0)/1000,0) -> 0 | I17: =IFERROR(VLOOKUP(I$1,[2]Hoja1!$A$2:$E$32,5,0)/1000,0) -> 0 | J17: =+SUM(B17:I17) -> 1730.07 | K17: =IFERROR(VLOOKUP(K$1,[2]Hoja1!$A$2:$E$32,5,0)/1000,0) -> 37.81 | L17: =IFERROR(VLOOKUP(L$1,[2]Hoja1!$A$2:$E$32,5,0)/1000,0) -> 248.7 | M17: =IFERROR(VLOOKUP(M$1,[2]Hoja1!$A$2:$E$32,5,0)/1000,0) -> 361.91 | N17: =IFERROR(VLOOKUP(N$1,[2]Hoja1!$A$2:$E$32,5,0)/1000,0) -> 0 | O17: =IFERROR(VLOOKUP(O$1,[2]Hoja1!$A$2:$E$32,5,0)/1000,0) -> 0 | P17: =IFERROR(VLOOKUP(P$1,[2]Hoja1!$A$2:$E$32,5,0)/1000,0) -> 0 | Q17: =+J17+SUM(K17:P17) -> 2378.49 | R17: =IFERROR(VLOOKUP(R$1,[2]Hoja1!$A$2:$E$32,5,0)/1000,0) -> 0 | S17: =IFERROR(VLOOKUP(S$1,[2]Hoja1!$A$2:$E$32,5,0)/1000,0) -> 0 | T17: =IFERROR(VLOOKUP(T$1,[2]Hoja1!$A$2:$E$32,5,0)/1000,0) -> 0 | U17: =IFERROR(VLOOKUP(U$1,[2]Hoja1!$A$2:$E$32,5,0)/1000,0) -> 0 | V17: =IFERROR(VLOOKUP(V$1,[2]Hoja1!$A$2:$E$32,5,0)/1000,0) -> 0 | W17: =IFERROR(VLOOKUP(W$1,[2]Hoja1!$A$2:$E$32,5,0)/1000,0) -> 0 | X17: =IFERROR(VLOOKUP(X$1,[2]Hoja1!$A$2:$E$32,5,0)/1000,0) -> 0 | Y17: =+Q17+SUM(R17:X17) -> 2378.49 | Z17: =IFERROR(VLOOKUP(Z$1,[2]Hoja1!$A$2:$E$32,5,0)/1000,0) -> 0 | AA17: =IFERROR(VLOOKUP(AA$1,[2]Hoja1!$A$2:$E$32,5,0)/1000,0) -> 0 | AB17: =IFERROR(VLOOKUP(AB$1,[2]Hoja1!$A$2:$E$32,5,0)/1000,0) -> 0 | AC17: =IFERROR(VLOOKUP(AC$1,[2]Hoja1!$A$2:$E$32,5,0)/1000,0) -> 0 | AD17: =IFERROR(VLOOKUP(AD$1,[2]Hoja1!$A$2:$E$32,5,0)/1000,0) -> 0 | AE17: =IFERROR(VLOOKUP(AE$1,[2]Hoja1!$A$2:$E$32,5,0)/1000,0) -> 0 | AF17: =IFERROR(VLOOKUP(AF$1,[2]Hoja1!$A$2:$E$32,5,0)/1000,0) -> 0 | AG17: =+Y17+SUM(Z17:AF17) -> 2378.49 | AH17: =IFERROR(VLOOKUP(AH$1,[2]Hoja1!$A$2:$E$32,5,0)/1000,0) -> 0 | AI17: =IFERROR(VLOOKUP(AI$1,[2]Hoja1!$A$2:$E$32,5,0)/1000,0) -> 0 | AJ17: =IFERROR(VLOOKUP(AJ$1,[2]Hoja1!$A$2:$E$32,5,0)/1000,0) -> 0 | AK17: =+AG17+SUM(AH17:AJ17) -> 2378.49
A18: % Cumplimiento | B18: =IFERROR(+B17/B16,0) -> 1.1683333 | C18: =IFERROR(+C17/C16,0) -> 1.7800769 | D18: =IFERROR(+D17/D16,0) -> 1.2373478 | E18: =IFERROR(+E17/E16,0) -> 1.2688889 | F18: =IFERROR(+F17/F16,0) -> 1.3597143 | G18: =IFERROR(+G17/G16,0) -> 1.4505172 | H18: =IFERROR(+H17/H16,0) -> 0 | I18: =IFERROR(+I17/I16,0) -> 0 | ... K18: =IFERROR(+K17/K16,0) -> 0.21005556 | L18: 0.51 | M18: =IFERROR(+M17/M16,0) -> 1.3919615 | N18: =IFERROR(+N17/N16,0) -> 0 | O18: =IFERROR(+O17/O16,0) -> 0 | P18: =IFERROR(+P17/P16,0) -> 0 | Q18: =IFERROR(+Q17/Q16,0) -> 0.98785824 | R18: =IFERROR(+R17/R16,0) -> 0 | S18: =IFERROR(+S17/S16,0) -> 0 | T18: =IFERROR(+T17/T16,0) -> 0 | ... AK18: =IFERROR(+AK17/AK16,0) -> 0.42414534
A19: Ext SINÚ Proy | B19: =+HLOOKUP(B$1,[3]Resumen!$B$1:$AH$27,6,0) -> 100 | C19: =+HLOOKUP(C$1,[3]Resumen!$B$1:$AH$27,6,0) -> 200 | D19: =+HLOOKUP(D$1,[3]Resumen!$B$1:$AH$27,6,0) -> 200 | E19: =+HLOOKUP(E$1,[3]Resumen!$B$1:$AH$27,6,0) -> 250 | F19: =+HLOOKUP(F$1,[3]Resumen!$B$1:$AH$27,6,0) -> 250 | G19: =+HLOOKUP(G$1,[3]Resumen!$B$1:$AH$27,6,0) -> 300 | H19: =+HLOOKUP(H$1,[3]Resumen!$B$1:$AH$27,6,0) -> 0 | I19: =+HLOOKUP(I$1,[3]Resumen!$B$1:$AH$27,6,0) -> 0 | J19: =+SUM(B19:I19) -> 1300 | K19: =+HLOOKUP(K$1,[3]Resumen!$B$1:$AH$27,6,0) -> 0 | L19: =+HLOOKUP(L$1,[3]Resumen!$B$1:$AH$27,6,0) -> 0 | M19: =+HLOOKUP(M$1,[3]Resumen!$B$1:$AH$27,6,0) -> 150 | N19: =+HLOOKUP(N$1,[3]Resumen!$B$1:$AH$27,6,0) -> 320 | O19: =+HLOOKUP(O$1,[3]Resumen!$B$1:$AH$27,6,0) -> 320 | P19: =+HLOOKUP(P$1,[3]Resumen!$B$1:$AH$27,6,0) -> 0 | Q19: =+J19+SUM(K19:P19) -> 2090 | R19: =+HLOOKUP(R$1,[3]Resumen!$B$1:$AH$27,6,0) -> 250 | S19: =+HLOOKUP(S$1,[3]Resumen!$B$1:$AH$27,6,0) -> 200 | T19: =+HLOOKUP(T$1,[3]Resumen!$B$1:$AH$27,6,0) -> 250 | U19: =+HLOOKUP(U$1,[3]Resumen!$B$1:$AH$27,6,0) -> 250 | V19: =+HLOOKUP(V$1,[3]Resumen!$B$1:$AH$27,6,0) -> 250 | W19: =+HLOOKUP(W$1,[3]Resumen!$B$1:$AH$27,6,0) -> 250 | X19: =+HLOOKUP(X$1,[3]Resumen!$B$1:$AH$27,6,0) -> 0 | Y19: =+Q19+SUM(R19:X19) -> 3540 | Z19: =+HLOOKUP(Z$1,[3]Resumen!$B$1:$AH$27,6,0) -> 100 | AA19: =+HLOOKUP(AA$1,[3]Resumen!$B$1:$AH$27,6,0) -> 250 | AB19: =+HLOOKUP(AB$1,[3]Resumen!$B$1:$AH$27,6,0) -> 250 | AC19: =+HLOOKUP(AC$1,[3]Resumen!$B$1:$AH$27,6,0) -> 0 | AD19: =+HLOOKUP(AD$1,[3]Resumen!$B$1:$AH$27,6,0) -> 270 | AE19: =+HLOOKUP(AE$1,[3]Resumen!$B$1:$AH$27,6,0) -> 270 | AF19: =+HLOOKUP(AF$1,[3]Resumen!$B$1:$AH$27,6,0) -> 0 | AG19: =+Y19+SUM(Z19:AF19) -> 4680 | AH19: =+HLOOKUP(AH$1,[3]Resumen!$B$1:$AH$27,6,0) -> 100 | AI19: =+HLOOKUP(AI$1,[3]Resumen!$B$1:$AH$27,6,0) -> 250 | AJ19: =+HLOOKUP(AJ$1,[3]Resumen!$B$1:$AH$27,6,0) -> 100 | AK19: =+AG19+SUM(AH19:AJ19) -> 5130
A20: Ext SINÚ Real | B20: =+IFERROR(VLOOKUP(B$1,'[4]BD Sinu'!$A$5:$EI$35,7,0)/1000,0) -> 0 | C20: =+IFERROR(VLOOKUP(C$1,'[4]BD Sinu'!$A$5:$EI$35,7,0)/1000,0) -> 324 | D20: =+IFERROR(VLOOKUP(D$1,'[4]BD Sinu'!$A$5:$EI$35,7,0)/1000,0) -> 148.5 | E20: =+IFERROR(VLOOKUP(E$1,'[4]BD Sinu'!$A$5:$EI$35,7,0)/1000,0) -> 391.5 | F20: =+IFERROR(VLOOKUP(F$1,'[4]BD Sinu'!$A$5:$EI$35,7,0)/1000,0) -> 351 | G20: =+IFERROR(VLOOKUP(G$1,'[4]BD Sinu'!$A$5:$EI$35,7,0)/1000,0) -> 351 | H20: =+IFERROR(VLOOKUP(H$1,'[4]BD Sinu'!$A$5:$EI$35,7,0)/1000,0) -> 0 | I20: =+IFERROR(VLOOKUP(I$1,'[4]BD Sinu'!$A$5:$EI$35,7,0)/1000,0) -> 0 | J20: =+SUM(B20:I20) -> 1566 | K20: =+IFERROR(VLOOKUP(K$1,'[4]BD Sinu'!$A$5:$EI$35,7,0)/1000,0) -> 0 | L20: =+IFERROR(VLOOKUP(L$1,'[4]BD Sinu'!$A$5:$EI$35,7,0)/1000,0) -> 0 | M20: =+IFERROR(VLOOKUP(M$1,'[4]BD Sinu'!$A$5:$EI$35,7,0)/1000,0) -> 108 | N20: =+IFERROR(VLOOKUP(N$1,'[4]BD Sinu'!$A$5:$EI$35,7,0)/1000,0) -> 0 | O20: =+IFERROR(VLOOKUP(O$1,'[4]BD Sinu'!$A$5:$EI$35,7,0)/1000,0) -> 0 | P20: =+IFERROR(VLOOKUP(P$1,'[4]BD Sinu'!$A$5:$EI$35,7,0)/1000,0) -> 0 | Q20: =+J20+SUM(K20:P20) -> 1674 | R20: =+IFERROR(VLOOKUP(R$1,'[4]BD Sinu'!$A$5:$EI$35,7,0)/1000,0) -> 0 | S20: =+IFERROR(VLOOKUP(S$1,'[4]BD Sinu'!$A$5:$EI$35,7,0)/1000,0) -> 0 | T20: =+IFERROR(VLOOKUP(T$1,'[4]BD Sinu'!$A$5:$EI$35,7,0)/1000,0) -> 0 | U20: =+IFERROR(VLOOKUP(U$1,'[4]BD Sinu'!$A$5:$EI$35,7,0)/1000,0) -> 0 | V20: =+IFERROR(VLOOKUP(V$1,'[4]BD Sinu'!$A$5:$EI$35,7,0)/1000,0) -> 0 | W20: =+IFERROR(VLOOKUP(W$1,'[4]BD Sinu'!$A$5:$EI$35,7,0)/1000,0) -> 0 | X20: =+IFERROR(VLOOKUP(X$1,'[4]BD Sinu'!$A$5:$EI$35,7,0)/1000,0) -> 0 | Y20: =+Q20+SUM(R20:X20) -> 1674 | Z20: =+IFERROR(VLOOKUP(Z$1,'[4]BD Sinu'!$A$5:$EI$35,7,0)/1000,0) -> 0 | AA20: =+IFERROR(VLOOKUP(AA$1,'[4]BD Sinu'!$A$5:$EI$35,7,0)/1000,0) -> 0 | AB20: =+IFERROR(VLOOKUP(AB$1,'[4]BD Sinu'!$A$5:$EI$35,7,0)/1000,0) -> 0 | AC20: =+IFERROR(VLOOKUP(AC$1,'[4]BD Sinu'!$A$5:$EI$35,7,0)/1000,0) -> 0 | AD20: =+IFERROR(VLOOKUP(AD$1,'[4]BD Sinu'!$A$5:$EI$35,7,0)/1000,0) -> 0 | AE20: =+IFERROR(VLOOKUP(AE$1,'[4]BD Sinu'!$A$5:$EI$35,7,0)/1000,0) -> 0 | AF20: =+IFERROR(VLOOKUP(AF$1,'[4]BD Sinu'!$A$5:$EI$35,7,0)/1000,0) -> 0 | AG20: =+Y20+SUM(Z20:AF20) -> 1674 | AH20: =+IFERROR(VLOOKUP(AH$1,'[4]BD Sinu'!$A$5:$EI$35,7,0)/1000,0) -> 0 | AI20: =+IFERROR(VLOOKUP(AI$1,'[4]BD Sinu'!$A$5:$EI$35,7,0)/1000,0) -> 0 | AJ20: =+IFERROR(VLOOKUP(AJ$1,'[4]BD Sinu'!$A$5:$EI$35,7,0)/1000,0) -> 0 | AK20: =+AG20+SUM(AH20:AJ20) -> 1674 | AL20: =+AG20/AG19 -> 0.35769231
A21: CPO | B21: =+IFERROR(VLOOKUP(B$1,'[4]BD Sinu'!$A$5:$EI$35,5,0)/1000,0) -> 0 | C21: =+IFERROR(VLOOKUP(C$1,'[4]BD Sinu'!$A$5:$EI$35,5,0)/1000,0) -> 52.166 | D21: =+IFERROR(VLOOKUP(D$1,'[4]BD Sinu'!$A$5:$EI$35,5,0)/1000,0) -> 27.033 | E21: =+IFERROR(VLOOKUP(E$1,'[4]BD Sinu'!$A$5:$EI$35,5,0)/1000,0) -> 74.626 | F21: =+IFERROR(VLOOKUP(F$1,'[4]BD Sinu'!$A$5:$EI$35,5,0)/1000,0) -> 66.634 | G21: =+IFERROR(VLOOKUP(G$1,'[4]BD Sinu'!$A$5:$EI$35,5,0)/1000,0) -> 82.781 | H21: =+IFERROR(VLOOKUP(H$1,'[4]BD Sinu'!$A$5:$EI$35,5,0)/1000,0) -> 0 | I21: =+IFERROR(VLOOKUP(I$1,'[4]BD Sinu'!$A$5:$EI$35,5,0)/1000,0) -> 0 | J21: =+SUM(B21:I21) -> 303.24 | K21: =+IFERROR(VLOOKUP(K$1,'[4]BD Sinu'!$A$5:$EI$35,5,0)/1000,0) -> 0 | L21: =+IFERROR(VLOOKUP(L$1,'[4]BD Sinu'!$A$5:$EI$35,5,0)/1000,0) -> 0 | M21: =+IFERROR(VLOOKUP(M$1,'[4]BD Sinu'!$A$5:$EI$35,5,0)/1000,0) -> 7.396 | N21: =+IFERROR(VLOOKUP(N$1,'[4]BD Sinu'!$A$5:$EI$35,5,0)/1000,0) -> 0 | O21: =+IFERROR(VLOOKUP(O$1,'[4]BD Sinu'!$A$5:$EI$35,5,0)/1000,0) -> 0 | P21: =+IFERROR(VLOOKUP(P$1,'[4]BD Sinu'!$A$5:$EI$35,5,0)/1000,0) -> 0 | Q21: =+J21+SUM(K21:P21) -> 310.636 | R21: =+IFERROR(VLOOKUP(R$1,'[4]BD Sinu'!$A$5:$EI$35,5,0)/1000,0) -> 0 | S21: =+IFERROR(VLOOKUP(S$1,'[4]BD Sinu'!$A$5:$EI$35,5,0)/1000,0) -> 0 | T21: =+IFERROR(VLOOKUP(T$1,'[4]BD Sinu'!$A$5:$EI$35,5,0)/1000,0) -> 0 | U21: =+IFERROR(VLOOKUP(U$1,'[4]BD Sinu'!$A$5:$EI$35,5,0)/1000,0) -> 0 | V21: =+IFERROR(VLOOKUP(V$1,'[4]BD Sinu'!$A$5:$EI$35,5,0)/1000,0) -> 0 | W21: =+IFERROR(VLOOKUP(W$1,'[4]BD Sinu'!$A$5:$EI$35,5,0)/1000,0) -> 0 | X21: =+IFERROR(VLOOKUP(X$1,'[4]BD Sinu'!$A$5:$EI$35,5,0)/1000,0) -> 0 | Y21: =+Q21+SUM(R21:X21) -> 310.636 | Z21: =+IFERROR(VLOOKUP(Z$1,'[4]BD Sinu'!$A$5:$EI$35,5,0)/1000,0) -> 0 | AA21: =+IFERROR(VLOOKUP(AA$1,'[4]BD Sinu'!$A$5:$EI$35,5,0)/1000,0) -> 0 | AB21: =+IFERROR(VLOOKUP(AB$1,'[4]BD Sinu'!$A$5:$EI$35,5,0)/1000,0) -> 0 | AC21: =+IFERROR(VLOOKUP(AC$1,'[4]BD Sinu'!$A$5:$EI$35,5,0)/1000,0) -> 0 | AD21: =+IFERROR(VLOOKUP(AD$1,'[4]BD Sinu'!$A$5:$EI$35,5,0)/1000,0) -> 0 | AE21: =+IFERROR(VLOOKUP(AE$1,'[4]BD Sinu'!$A$5:$EI$35,5,0)/1000,0) -> 0 | AF21: =+IFERROR(VLOOKUP(AF$1,'[4]BD Sinu'!$A$5:$EI$35,5,0)/1000,0) -> 0 | AG21: =+Y21+SUM(Z21:AF21) -> 310.636 | AH21: =+IFERROR(VLOOKUP(AH$1,'[4]BD Sinu'!$A$5:$EI$35,5,0)/1000,0) -> 0 | AI21: =+IFERROR(VLOOKUP(AI$1,'[4]BD Sinu'!$A$5:$EI$35,5,0)/1000,0) -> 0 | AJ21: =+IFERROR(VLOOKUP(AJ$1,'[4]BD Sinu'!$A$5:$EI$35,5,0)/1000,0) -> 0 | AK21: =+AG21+SUM(AH21:AJ21) -> 310.636
A22: =+_xlfn.CONCAT("TEA% ", B47,"%") -> TEA% 22% | B22: =IFERROR(+B21/B20,0) -> 0 | C22: =IFERROR(+C21/C20,0) -> 0.16100617 | D22: =IFERROR(+D21/D20,0) -> 0.1820404 | E22: =IFERROR(+E21/E20,0) -> 0.19061558 | F22: =IFERROR(+F21/F20,0) -> 0.18984046 | G22: =IFERROR(+G21/G20,0) -> 0.2358433 | H22: =IFERROR(+H21/H20,0) -> 0 | I22: =IFERROR(+I21/I20,0) -> 0 | ... AK22: =IFERROR(+AK21/AK20,0) -> 0.18556511
A23: A&G Proyección | B23: =+HLOOKUP(B$1,'[1]RFF Resumen'!$C$16:$AG$153,77,0) -> 490.09901 | C23: =+HLOOKUP(C$1,'[1]RFF Resumen'!$C$16:$AG$153,77,0) -> 740.59406 | D23: =+HLOOKUP(D$1,'[1]RFF Resumen'!$C$16:$AG$153,77,0) -> 914.85149 | E23: =+HLOOKUP(E$1,'[1]RFF Resumen'!$C$16:$AG$153,77,0) -> 936.63366 | F23: =+HLOOKUP(F$1,'[1]RFF Resumen'!$C$16:$AG$153,77,0) -> 882.17822 | G23: =+HLOOKUP(G$1,'[1]RFF Resumen'!$C$16:$AG$153,77,0) -> 838.61386 | H23: =+HLOOKUP(H$1,'[1]RFF Resumen'!$C$16:$AG$153,77,0) -> 185.14851 | I23: =+HLOOKUP(I$1,'[1]RFF Resumen'!$C$16:$AG$153,77,0) -> 141.58416 | J23: =+SUM(B23:I23) -> 5129.703 | K23: =+HLOOKUP(K$1,'[1]RFF Resumen'!$C$16:$AG$153,77,0) -> 773.26733 | L23: =+HLOOKUP(L$1,'[1]RFF Resumen'!$C$16:$AG$153,77,0) -> 1034.6535 | M23: =+HLOOKUP(M$1,'[1]RFF Resumen'!$C$16:$AG$153,77,0) -> 1198.0198 | N23: =+HLOOKUP(N$1,'[1]RFF Resumen'!$C$16:$AG$153,77,0) -> 1143.5644 | O23: =+HLOOKUP(O$1,'[1]RFF Resumen'!$C$16:$AG$153,77,0) -> 991.08911 | P23: =+HLOOKUP(P$1,'[1]RFF Resumen'!$C$16:$AG$153,77,0) -> 152.47525 | Q23: =+J23+SUM(K23:P23) -> 10422.772 | R23: =+HLOOKUP(R$1,'[1]RFF Resumen'!$C$16:$AG$153,77,0) -> 490.09901 | S23: =+HLOOKUP(S$1,'[1]RFF Resumen'!$C$16:$AG$153,77,0) -> 805.94059 | T23: =+HLOOKUP(T$1,'[1]RFF Resumen'!$C$16:$AG$153,77,0) -> 1110.8911 | U23: =+HLOOKUP(U$1,'[1]RFF Resumen'!$C$16:$AG$153,77,0) -> 1089.1089 | V23: =+HLOOKUP(V$1,'[1]RFF Resumen'!$C$16:$AG$153,77,0) -> 1056.4356 | W23: =+HLOOKUP(W$1,'[1]RFF Resumen'!$C$16:$AG$153,77,0) -> 1001.9802 | X23: =+HLOOKUP(X$1,'[1]RFF Resumen'!$C$16:$AG$153,77,0) -> 185.14851 | Y23: =+Q23+SUM(R23:X23) -> 16162.376 | Z23: =+HLOOKUP(Z$1,'[1]RFF Resumen'!$C$16:$AG$153,77,0) -> 511.88119 | AA23: =+HLOOKUP(AA$1,'[1]RFF Resumen'!$C$16:$AG$153,77,0) -> 980.19802 | AB23: =+HLOOKUP(AB$1,'[1]RFF Resumen'!$C$16:$AG$153,77,0) -> 599.0099 | AC23: =+HLOOKUP(AC$1,'[1]RFF Resumen'!$C$16:$AG$153,77,0) -> 163.36634 | AD23: =+HLOOKUP(AD$1,'[1]RFF Resumen'!$C$16:$AG$153,77,0) -> 653.46535 | AE23: =+HLOOKUP(AE$1,'[1]RFF Resumen'!$C$16:$AG$153,77,0) -> 1034.6535 | AF23: =+HLOOKUP(AF$1,'[1]RFF Resumen'!$C$16:$AG$153,77,0) -> 163.36634 | AG23: =+Y23+SUM(Z23:AF23) -> 20268.317 | AH23: =+HLOOKUP(AH$1,'[1]RFF Resumen'!$C$16:$AG$153,77,0) -> 544.55446 | AI23: =+HLOOKUP(AI$1,'[1]RFF Resumen'!$C$16:$AG$153,77,0) -> 1001.9802 | AJ23: =+HLOOKUP(AJ$1,'[1]RFF Resumen'!$C$16:$AG$153,77,0) -> 185.14851 | AK23: =+AG23+SUM(AH23:AJ23) -> 22000
A24: A&G Real | B24: =IFERROR(VLOOKUP(B$1,[2]Hoja1!$A$2:$E$32,3,0)/1000,0) -> 455.3 | C24: =IFERROR(VLOOKUP(C$1,[2]Hoja1!$A$2:$E$32,3,0)/1000,0) -> 605.61 | D24: =IFERROR(VLOOKUP(D$1,[2]Hoja1!$A$2:$E$32,3,0)/1000,0) -> 799.38 | E24: =IFERROR(VLOOKUP(E$1,[2]Hoja1!$A$2:$E$32,3,0)/1000,0) -> 708.73 | F24: =IFERROR(VLOOKUP(F$1,[2]Hoja1!$A$2:$E$32,3,0)/1000,0) -> 742.49 | G24: =IFERROR(VLOOKUP(G$1,[2]Hoja1!$A$2:$E$32,3,0)/1000,0) -> 907.6 | H24: =IFERROR(VLOOKUP(H$1,[2]Hoja1!$A$2:$E$32,3,0)/1000,0) -> 306.72 | I24: =IFERROR(VLOOKUP(I$1,[2]Hoja1!$A$2:$E$32,3,0)/1000,0) -> 151.32 | J24: =+SUM(B24:I24) -> 4677.15 | K24: =IFERROR(VLOOKUP(K$1,[2]Hoja1!$A$2:$E$32,3,0)/1000,0) -> 754.27 | L24: =IFERROR(VLOOKUP(L$1,[2]Hoja1!$A$2:$E$32,3,0)/1000,0) -> 721.26 | M24: =IFERROR(VLOOKUP(M$1,[2]Hoja1!$A$2:$E$32,3,0)/1000,0) -> 610.6 | N24: =IFERROR(VLOOKUP(N$1,[2]Hoja1!$A$2:$E$32,3,0)/1000,0) -> 0 | O24: =IFERROR(VLOOKUP(O$1,[2]Hoja1!$A$2:$E$32,3,0)/1000,0) -> 0 | P24: =IFERROR(VLOOKUP(P$1,[2]Hoja1!$A$2:$E$32,3,0)/1000,0) -> 0 | Q24: =+J24+SUM(K24:P24) -> 6763.28 | R24: =IFERROR(VLOOKUP(R$1,[2]Hoja1!$A$2:$E$32,3,0)/1000,0) -> 0 | S24: =IFERROR(VLOOKUP(S$1,[2]Hoja1!$A$2:$E$32,3,0)/1000,0) -> 0 | T24: =IFERROR(VLOOKUP(T$1,[2]Hoja1!$A$2:$E$32,3,0)/1000,0) -> 0 | U24: =IFERROR(VLOOKUP(U$1,[2]Hoja1!$A$2:$E$32,3,0)/1000,0) -> 0 | V24: =IFERROR(VLOOKUP(V$1,[2]Hoja1!$A$2:$E$32,3,0)/1000,0) -> 0 | W24: =IFERROR(VLOOKUP(W$1,[2]Hoja1!$A$2:$E$32,3,0)/1000,0) -> 0 | X24: =IFERROR(VLOOKUP(X$1,[2]Hoja1!$A$2:$E$32,3,0)/1000,0) -> 0 | Y24: =+Q24+SUM(R24:X24) -> 6763.28 | Z24: =IFERROR(VLOOKUP(Z$1,[2]Hoja1!$A$2:$E$32,3,0)/1000,0) -> 0 | AA24: =IFERROR(VLOOKUP(AA$1,[2]Hoja1!$A$2:$E$32,3,0)/1000,0) -> 0 | AB24: =IFERROR(VLOOKUP(AB$1,[2]Hoja1!$A$2:$E$32,3,0)/1000,0) -> 0 | AC24: =IFERROR(VLOOKUP(AC$1,[2]Hoja1!$A$2:$E$32,3,0)/1000,0) -> 0 | AD24: =IFERROR(VLOOKUP(AD$1,[2]Hoja1!$A$2:$E$32,3,0)/1000,0) -> 0 | AE24: =IFERROR(VLOOKUP(AE$1,[2]Hoja1!$A$2:$E$32,3,0)/1000,0) -> 0 | AF24: =IFERROR(VLOOKUP(AF$1,[2]Hoja1!$A$2:$E$32,3,0)/1000,0) -> 0 | AG24: =+Y24+SUM(Z24:AF24) -> 6763.28 | AH24: =IFERROR(VLOOKUP(AH$1,[2]Hoja1!$A$2:$E$32,3,0)/1000,0) -> 0 | AI24: =IFERROR(VLOOKUP(AI$1,[2]Hoja1!$A$2:$E$32,3,0)/1000,0) -> 0 | AJ24: =IFERROR(VLOOKUP(AJ$1,[2]Hoja1!$A$2:$E$32,3,0)/1000,0) -> 0 | AK24: =+AG24+SUM(AH24:AJ24) -> 6763.28
A25: % Cumplimiento | B25: =IFERROR(+B24/B23,0) -> 0.92899596 | C25: =IFERROR(+C24/C23,0) -> 0.81773543 | D25: =IFERROR(+D24/D23,0) -> 0.87378117 | E25: =IFERROR(+E24/E23,0) -> 0.75667791 | F25: =IFERROR(+F24/F23,0) -> 0.84165533 | G25: =IFERROR(+G24/G23,0) -> 1.0822621 | H25: =IFERROR(+H24/H23,0) -> 1.656616 | I25: =IFERROR(+I24/I23,0) -> 1.0687636 | ... AK25: =IFERROR(+AK24/AK23,0) -> 0.30742182
A26: Ext A&GC Proy | B26: =+HLOOKUP(B$1,[3]Resumen!$B$1:$AH$27,8,0) -> 700 | C26: =+HLOOKUP(C$1,[3]Resumen!$B$1:$AH$27,8,0) -> 850 | D26: =+HLOOKUP(D$1,[3]Resumen!$B$1:$AH$27,8,0) -> 850 | E26: =+HLOOKUP(E$1,[3]Resumen!$B$1:$AH$27,8,0) -> 850 | F26: =+HLOOKUP(F$1,[3]Resumen!$B$1:$AH$27,8,0) -> 850 | G26: =+HLOOKUP(G$1,[3]Resumen!$B$1:$AH$27,8,0) -> 850 | H26: =+HLOOKUP(H$1,[3]Resumen!$B$1:$AH$27,8,0) -> 500 | I26: =+HLOOKUP(I$1,[3]Resumen!$B$1:$AH$27,8,0) -> 0 | J26: =+SUM(B26:I26) -> 5450 | K26: =+HLOOKUP(K$1,[3]Resumen!$B$1:$AH$27,8,0) -> 850 | L26: =+HLOOKUP(L$1,[3]Resumen!$B$1:$AH$27,8,0) -> 850 | M26: =+HLOOKUP(M$1,[3]Resumen!$B$1:$AH$27,8,0) -> 850 | N26: =+HLOOKUP(N$1,[3]Resumen!$B$1:$AH$27,8,0) -> 850 | O26: =+HLOOKUP(O$1,[3]Resumen!$B$1:$AH$27,8,0) -> 850 | P26: =+HLOOKUP(P$1,[3]Resumen!$B$1:$AH$27,8,0) -> 850 | Q26: =+J26+SUM(K26:P26) -> 10550 | R26: =+HLOOKUP(R$1,[3]Resumen!$B$1:$AH$27,8,0) -> 850 | S26: =+HLOOKUP(S$1,[3]Resumen!$B$1:$AH$27,8,0) -> 850 | T26: =+HLOOKUP(T$1,[3]Resumen!$B$1:$AH$27,8,0) -> 850 | U26: =+HLOOKUP(U$1,[3]Resumen!$B$1:$AH$27,8,0) -> 850 | V26: =+HLOOKUP(V$1,[3]Resumen!$B$1:$AH$27,8,0) -> 850 | W26: =+HLOOKUP(W$1,[3]Resumen!$B$1:$AH$27,8,0) -> 850 | X26: =+HLOOKUP(X$1,[3]Resumen!$B$1:$AH$27,8,0) -> 850 | Y26: =+Q26+SUM(R26:X26) -> 16500 | Z26: =+HLOOKUP(Z$1,[3]Resumen!$B$1:$AH$27,8,0) -> 400 | AA26: =+HLOOKUP(AA$1,[3]Resumen!$B$1:$AH$27,8,0) -> 850 | AB26: =+HLOOKUP(AB$1,[3]Resumen!$B$1:$AH$27,8,0) -> 850 | AC26: =+HLOOKUP(AC$1,[3]Resumen!$B$1:$AH$27,8,0) -> 0 | AD26: =+HLOOKUP(AD$1,[3]Resumen!$B$1:$AH$27,8,0) -> 850 | AE26: =+HLOOKUP(AE$1,[3]Resumen!$B$1:$AH$27,8,0) -> 850 | AF26: =+HLOOKUP(AF$1,[3]Resumen!$B$1:$AH$27,8,0) -> 500 | AG26: =+Y26+SUM(Z26:AF26) -> 20800 | AH26: =+HLOOKUP(AH$1,[3]Resumen!$B$1:$AH$27,8,0) -> 400 | AI26: =+HLOOKUP(AI$1,[3]Resumen!$B$1:$AH$27,8,0) -> 850 | AJ26: =+HLOOKUP(AJ$1,[3]Resumen!$B$1:$AH$27,8,0) -> 0 | AK26: =+AG26+SUM(AH26:AJ26) -> 22050
A27: Ext A&GC Real | B27: =+IFERROR(VLOOKUP(B$1,'[4]Base de Datos'!$A$5:$EI$35,21,0)/1000,0) -> 511.504 | C27: =+IFERROR(VLOOKUP(C$1,'[4]Base de Datos'!$A$5:$EI$35,21,0)/1000,0) -> 349.349 | D27: =+IFERROR(VLOOKUP(D$1,'[4]Base de Datos'!$A$5:$EI$35,21,0)/1000,0) -> 605.22 | E27: =+IFERROR(VLOOKUP(E$1,'[4]Base de Datos'!$A$5:$EI$35,21,0)/1000,0) -> 714.168 | F27: =+IFERROR(VLOOKUP(F$1,'[4]Base de Datos'!$A$5:$EI$35,21,0)/1000,0) -> 706.706 | G27: =+IFERROR(VLOOKUP(G$1,'[4]Base de Datos'!$A$5:$EI$35,21,0)/1000,0) -> 668.972 | H27: =+IFERROR(VLOOKUP(H$1,'[4]Base de Datos'!$A$5:$EI$35,21,0)/1000,0) -> 504.79 | I27: =+IFERROR(VLOOKUP(I$1,'[4]Base de Datos'!$A$5:$EI$35,21,0)/1000,0) -> 723.142 | J27: =+SUM(B27:I27) -> 4783.851 | K27: =+IFERROR(VLOOKUP(K$1,'[4]Base de Datos'!$A$5:$EI$35,21,0)/1000,0) -> 607.422 | L27: =+IFERROR(VLOOKUP(L$1,'[4]Base de Datos'!$A$5:$EI$35,21,0)/1000,0) -> 431.965 | M27: =+IFERROR(VLOOKUP(M$1,'[4]Base de Datos'!$A$5:$EI$35,21,0)/1000,0) -> 670.44 | N27: =+IFERROR(VLOOKUP(N$1,'[4]Base de Datos'!$A$5:$EI$35,21,0)/1000,0) -> 0 | O27: =+IFERROR(VLOOKUP(O$1,'[4]Base de Datos'!$A$5:$EI$35,21,0)/1000,0) -> 0 | P27: =+IFERROR(VLOOKUP(P$1,'[4]Base de Datos'!$A$5:$EI$35,21,0)/1000,0) -> 0 | Q27: =+J27+SUM(K27:P27) -> 6493.678 | R27: =+IFERROR(VLOOKUP(R$1,'[4]Base de Datos'!$A$5:$EI$35,21,0)/1000,0) -> 0 | S27: =+IFERROR(VLOOKUP(S$1,'[4]Base de Datos'!$A$5:$EI$35,21,0)/1000,0) -> 0 | T27: =+IFERROR(VLOOKUP(T$1,'[4]Base de Datos'!$A$5:$EI$35,21,0)/1000,0) -> 0 | U27: =+IFERROR(VLOOKUP(U$1,'[4]Base de Datos'!$A$5:$EI$35,21,0)/1000,0) -> 0 | V27: =+IFERROR(VLOOKUP(V$1,'[4]Base de Datos'!$A$5:$EI$35,21,0)/1000,0) -> 0 | W27: =+IFERROR(VLOOKUP(W$1,'[4]Base de Datos'!$A$5:$EI$35,21,0)/1000,0) -> 0 | X27: =+IFERROR(VLOOKUP(X$1,'[4]Base de Datos'!$A$5:$EI$35,21,0)/1000,0) -> 0 | Y27: =+Q27+SUM(R27:X27) -> 6493.678 | Z27: =+IFERROR(VLOOKUP(Z$1,'[4]Base de Datos'!$A$5:$EI$35,21,0)/1000,0) -> 0 | AA27: =+IFERROR(VLOOKUP(AA$1,'[4]Base de Datos'!$A$5:$EI$35,21,0)/1000,0) -> 0 | AB27: =+IFERROR(VLOOKUP(AB$1,'[4]Base de Datos'!$A$5:$EI$35,21,0)/1000,0) -> 0 | AC27: =+IFERROR(VLOOKUP(AC$1,'[4]Base de Datos'!$A$5:$EI$35,21,0)/1000,0) -> 0 | AD27: =+IFERROR(VLOOKUP(AD$1,'[4]Base de Datos'!$A$5:$EI$35,21,0)/1000,0) -> 0 | AE27: =+IFERROR(VLOOKUP(AE$1,'[4]Base de Datos'!$A$5:$EI$35,21,0)/1000,0) -> 0 | AF27: =+IFERROR(VLOOKUP(AF$1,'[4]Base de Datos'!$A$5:$EI$35,21,0)/1000,0) -> 0 | AG27: =+Y27+SUM(Z27:AF27) -> 6493.678 | AH27: =+IFERROR(VLOOKUP(AH$1,'[4]Base de Datos'!$A$5:$EI$35,21,0)/1000,0) -> 0 | AI27: =+IFERROR(VLOOKUP(AI$1,'[4]Base de Datos'!$A$5:$EI$35,21,0)/1000,0) -> 0 | AJ27: =+IFERROR(VLOOKUP(AJ$1,'[4]Base de Datos'!$A$5:$EI$35,21,0)/1000,0) -> 0 | AK27: =+AG27+SUM(AH27:AJ27) -> 6493.678 | AL27: =+AG27/AG26 -> 0.31219606
A28: CPO | B28: =+IFERROR(VLOOKUP(B$1,'[4]Base de Datos'!$A$5:$EI$35,19,0)/1000,0) -> 120.3 | C28: =+IFERROR(VLOOKUP(C$1,'[4]Base de Datos'!$A$5:$EI$35,19,0)/1000,0) -> 78.136 | D28: =+IFERROR(VLOOKUP(D$1,'[4]Base de Datos'!$A$5:$EI$35,19,0)/1000,0) -> 149.477 | E28: =+IFERROR(VLOOKUP(E$1,'[4]Base de Datos'!$A$5:$EI$35,19,0)/1000,0) -> 167.895 | F28: =+IFERROR(VLOOKUP(F$1,'[4]Base de Datos'!$A$5:$EI$35,19,0)/1000,0) -> 167.42 | G28: =+IFERROR(VLOOKUP(G$1,'[4]Base de Datos'!$A$5:$EI$35,19,0)/1000,0) -> 158.212 | H28: =+IFERROR(VLOOKUP(H$1,'[4]Base de Datos'!$A$5:$EI$35,19,0)/1000,0) -> 108.704 | I28: =+IFERROR(VLOOKUP(I$1,'[4]Base de Datos'!$A$5:$EI$35,19,0)/1000,0) -> 171.567 | J28: =+SUM(B28:I28) -> 1121.711 | K28: =+IFERROR(VLOOKUP(K$1,'[4]Base de Datos'!$A$5:$EI$35,19,0)/1000,0) -> 154.342 | L28: =+IFERROR(VLOOKUP(L$1,'[4]Base de Datos'!$A$5:$EI$35,19,0)/1000,0) -> 87.544 | M28: =+IFERROR(VLOOKUP(M$1,'[4]Base de Datos'!$A$5:$EI$35,19,0)/1000,0) -> 152.958 | N28: =+IFERROR(VLOOKUP(N$1,'[4]Base de Datos'!$A$5:$EI$35,19,0)/1000,0) -> 0 | O28: =+IFERROR(VLOOKUP(O$1,'[4]Base de Datos'!$A$5:$EI$35,19,0)/1000,0) -> 0 | P28: =+IFERROR(VLOOKUP(P$1,'[4]Base de Datos'!$A$5:$EI$35,19,0)/1000,0) -> 0 | Q28: =+J28+SUM(K28:P28) -> 1516.555 | R28: =+IFERROR(VLOOKUP(R$1,'[4]Base de Datos'!$A$5:$EI$35,19,0)/1000,0) -> 0 | S28: =+IFERROR(VLOOKUP(S$1,'[4]Base de Datos'!$A$5:$EI$35,19,0)/1000,0) -> 0 | T28: =+IFERROR(VLOOKUP(T$1,'[4]Base de Datos'!$A$5:$EI$35,19,0)/1000,0) -> 0 | U28: =+IFERROR(VLOOKUP(U$1,'[4]Base de Datos'!$A$5:$EI$35,19,0)/1000,0) -> 0 | V28: =+IFERROR(VLOOKUP(V$1,'[4]Base de Datos'!$A$5:$EI$35,19,0)/1000,0) -> 0 | W28: =+IFERROR(VLOOKUP(W$1,'[4]Base de Datos'!$A$5:$EI$35,19,0)/1000,0) -> 0 | X28: =+IFERROR(VLOOKUP(X$1,'[4]Base de Datos'!$A$5:$EI$35,19,0)/1000,0) -> 0 | Y28: =+Q28+SUM(R28:X28) -> 1516.555 | Z28: =+IFERROR(VLOOKUP(Z$1,'[4]Base de Datos'!$A$5:$EI$35,19,0)/1000,0) -> 0 | AA28: =+IFERROR(VLOOKUP(AA$1,'[4]Base de Datos'!$A$5:$EI$35,19,0)/1000,0) -> 0 | AB28: =+IFERROR(VLOOKUP(AB$1,'[4]Base de Datos'!$A$5:$EI$35,19,0)/1000,0) -> 0 | AC28: =+IFERROR(VLOOKUP(AC$1,'[4]Base de Datos'!$A$5:$EI$35,19,0)/1000,0) -> 0 | AD28: =+IFERROR(VLOOKUP(AD$1,'[4]Base de Datos'!$A$5:$EI$35,19,0)/1000,0) -> 0 | AE28: =+IFERROR(VLOOKUP(AE$1,'[4]Base de Datos'!$A$5:$EI$35,19,0)/1000,0) -> 0 | AF28: =+IFERROR(VLOOKUP(AF$1,'[4]Base de Datos'!$A$5:$EI$35,19,0)/1000,0) -> 0 | AG28: =+Y28+SUM(Z28:AF28) -> 1516.555 | AH28: =+IFERROR(VLOOKUP(AH$1,'[4]Base de Datos'!$A$5:$EI$35,19,0)/1000,0) -> 0 | AI28: =+IFERROR(VLOOKUP(AI$1,'[4]Base de Datos'!$A$5:$EI$35,19,0)/1000,0) -> 0 | AJ28: =+IFERROR(VLOOKUP(AJ$1,'[4]Base de Datos'!$A$5:$EI$35,19,0)/1000,0) -> 0 | AK28: =+AG28+SUM(AH28:AJ28) -> 1516.555
A29: =+_xlfn.CONCAT("TEA% ", B46,"%") -> TEA% 23.5% | B29: =IFERROR(+B28/B27,0) -> 0.23518878 | C29: =IFERROR(+C28/C27,0) -> 0.22366173 | D29: =IFERROR(+D28/D27,0) -> 0.24697961 | E29: =IFERROR(+E28/E27,0) -> 0.23509174 | F29: =IFERROR(+F28/F27,0) -> 0.23690191 | G29: =IFERROR(+G28/G27,0) -> 0.23650018 | H29: =IFERROR(+H28/H27,0) -> 0.21534499 | I29: =IFERROR(+I28/I27,0) -> 0.23725216 | ... Y29: =IFERROR(+Y28/Y27,0) -> 0.2335433 | Z29: =+Y29 -> 0.2335433 | AA29: =+Y29 -> 0.2335433 | AB29: =IFERROR(+AB28/AB27,0) -> 0 | AC29: =IFERROR(+AC28/AC27,0) -> 0 | AD29: =IFERROR(+AD28/AD27,0) -> 0 | AE29: =IFERROR(+AE28/AE27,0) -> 0 | AF29: =IFERROR(+AF28/AF27,0) -> 0 | AG29: =IFERROR(+AG28/AG27,0) -> 0.2335433 | AH29: =IFERROR(+AH28/AH27,0) -> 0 | AI29: =IFERROR(+AI28/AI27,0) -> 0 | ... AK29: =IFERROR(+AK28/AK27,0) -> 0.2335433
A30: TOTAL Proyección | B30: =B2+B9+B16+B23 -> 1149.2934 | C30: =C2+C9+C16+C23 -> 1598.7829 | D30: =D2+D9+D16+D23 -> 1991.9959 | E30: =E2+E9+E16+E23 -> 2067.4818 | F30: =F2+F9+F16+F23 -> 2081.7245 | G30: =G2+G9+G16+G23 -> 2104.6685 | H30: =H2+H9+H16+H23 -> 553.82456 | I30: =I2+I9+I16+I23 -> 226.49566 | J30: =+SUM(B30:I30) -> 11774.267 | K30: =K2+K9+K16+K23 -> 1622.9334 | L30: =L2+L9+L16+L23 -> 2147.594 | M30: =M2+M9+M16+M23 -> 2374.6374 | N30: =N2+N9+N16+N23 -> 2487.5383 | O30: =O2+O9+O16+O23 -> 2128.0663 | P30: =P2+P9+P16+P23 -> 813.03409 | Q30: =+J30+SUM(K30:P30) -> 23348.071 | R30: =R2+R9+R16+R23 -> 1440.0631 | S30: =S2+S9+S16+S23 -> 1907.3005 | T30: =T2+T9+T16+T23 -> 2300.1866 | U30: =U2+U9+U16+U23 -> 2305.0972 | V30: =V2+V9+V16+V23 -> 2314.6431 | W30: =W2+W9+W16+W23 -> 2308.2443 | X30: =X2+X9+X16+X23 -> 707.87812 | Y30: =+Q30+SUM(R30:X30) -> 36631.484 | Z30: =Z2+Z9+Z16+Z23 -> 1540.2251 | AA30: =AA2+AA9+AA16+AA23 -> 2362.8786 | AB30: =AB2+AB9+AB16+AB23 -> 1323.2032 | AC30: =AC2+AC9+AC16+AC23 -> 229.28151 | AD30: =AD2+AD9+AD16+AD23 -> 1722.0578 | AE30: =AE2+AE9+AE16+AE23 -> 2308.6184 | AF30: =AF2+AF9+AF16+AF23 -> 874.3996 | AG30: =+Y30+SUM(Z30:AF30) -> 46992.148 | AH30: =AH2+AH9+AH16+AH23 -> 1633.5162 | AI30: =AI2+AI9+AI16+AI23 -> 2448.4676 | AJ30: =AJ2+AJ9+AJ16+AJ23 -> 693.59204 | AK30: =+AG30+SUM(AH30:AJ30) -> 51767.724 | AL30: =+AK33-AK19 -> 47300 | AM30: Proyección inicio mes Fruta procesada sin Sinú
A31: TOTAL Real | B31: =B3+B10+B17+B24 -> 997.894 | C31: =C3+C10+C17+C24 -> 1441.616 | D31: =D3+D10+D17+D24 -> 2130.517 | E31: =E3+E10+E17+E24 -> 1996.817 | F31: =F3+F10+F17+F24 -> 2175.668 | G31: =G3+G10+G17+G24 -> 2115.35 | H31: =H3+H10+H17+H24 -> 1098.11 | I31: =I3+I10+I17+I24 -> 373.255 | J31: =+SUM(B31:I31) -> 12329.227 | K31: =K3+K10+K17+K24 -> 1276.69 | L31: =L3+L10+L17+L24 -> 1784.986 | M31: =M3+M10+M17+M24 -> 2012.22 | N31: =N3+N10+N17+N24 -> 0 | O31: =O3+O10+O17+O24 -> 0 | P31: =P3+P10+P17+P24 -> 0 | Q31: =+J31+SUM(K31:P31) -> 17403.123 | R31: =R3+R10+R17+R24 -> 0 | S31: =S3+S10+S17+S24 -> 0 | T31: =T3+T10+T17+T24 -> 0 | U31: =U3+U10+U17+U24 -> 0 | V31: =V3+V10+V17+V24 -> 0 | W31: =W3+W10+W17+W24 -> 0 | X31: =X3+X10+X17+X24 -> 0 | Y31: =+Q31+SUM(R31:X31) -> 17403.123 | Z31: =Z3+Z10+Z17+Z24 -> 0 | AA31: =AA3+AA10+AA17+AA24 -> 0 | AB31: =AB3+AB10+AB17+AB24 -> 0 | AC31: =AC3+AC10+AC17+AC24 -> 0 | AD31: =AD3+AD10+AD17+AD24 -> 0 | AE31: =AE3+AE10+AE17+AE24 -> 0 | AF31: =AF3+AF10+AF17+AF24 -> 0 | AG31: =+Y31+SUM(Z31:AF31) -> 17403.123 | AH31: =AH3+AH10+AH17+AH24 -> 0 | AI31: =AI3+AI10+AI17+AI24 -> 0 | AJ31: =AJ3+AJ10+AJ17+AJ24 -> 0 | AK31: =+AG31+SUM(AH31:AJ31) -> 17403.123 | AL31: =+AK34-AK20 -> 15505.047 | AM31: Cierre Fruta procesada sin Sinú
A32: % Cumplimiento | B32: =IFERROR(+B31/B30,0) -> 0.86826737 | C32: =IFERROR(+C31/C30,0) -> 0.90169589 | D32: =IFERROR(+D31/D30,0) -> 1.0695389 | E32: =IFERROR(+E31/E30,0) -> 0.96582084 | F32: =IFERROR(+F31/F30,0) -> 1.0451277 | G32: =IFERROR(+G31/G30,0) -> 1.0050751 | H32: =IFERROR(+H31/H30,0) -> 1.9827759 | I32: =IFERROR(+I31/I30,0) -> 1.6479565 | ... AK32: =IFERROR(+AK31/AK30,0) -> 0.33617709 | AL32: =+AL31-AL30 -> -31794.953 | AM32: Diferencia
A33: TOTAL Proyección | B33: =B5+B12+B19+B26 -> 1550 | C33: =C5+C12+C19+C26 -> 1800 | D33: =D5+D12+D19+D26 -> 1900 | E33: =E5+E12+E19+E26 -> 2000 | F33: =F5+F12+F19+F26 -> 2000 | G33: =G5+G12+G19+G26 -> 2150 | H33: =H5+H12+H19+H26 -> 800 | I33: =I5+I12+I19+I26 -> 0 | J33: =+SUM(B33:I33) -> 12200 | K33: =K5+K12+K19+K26 -> 1350 | L33: =L5+L12+L19+L26 -> 1950 | M33: =M5+M12+M19+M26 -> 2100 | N33: =N5+N12+N19+N26 -> 2270 | O33: =O5+O12+O19+O26 -> 2270 | P33: =P5+P12+P19+P26 -> 1550 | Q33: =+J33+SUM(K33:P33) -> 23690 | R33: =R5+R12+R19+R26 -> 1600 | S33: =S5+S12+S19+S26 -> 2050 | T33: =T5+T12+T19+T26 -> 2100 | U33: =U5+U12+U19+U26 -> 2150 | V33: =V5+V12+V19+V26 -> 2150 | W33: =W5+W12+W19+W26 -> 2150 | X33: =X5+X12+X19+X26 -> 1250 | Y33: =+Q33+SUM(R33:X33) -> 37140 | Z33: =Z5+Z12+Z19+Z26 -> 1250 | AA33: =AA5+AA12+AA19+AA26 -> 2200 | AB33: =AB5+AB12+AB19+AB26 -> 1780 | AC33: =AC5+AC12+AC19+AC26 -> 0 | AD33: =AD5+AD12+AD19+AD26 -> 2170 | AE33: =AE5+AE12+AE19+AE26 -> 2170 | AF33: =AF5+AF12+AF19+AF26 -> 1050 | AG33: =+Y33+SUM(Z33:AF33) -> 47760 | AH33: =AH5+AH12+AH19+AH26 -> 1350 | AI33: =AI5+AI12+AI19+AI26 -> 2220 | AJ33: =AJ5+AJ12+AJ19+AJ26 -> 1100 | AK33: =+AG33+SUM(AH33:AJ33) -> 52430 | AL33: =+AK5+AK12+AK19+AK26 -> 52430
A34: RFF Procesada | B34: =+B27+B13+B20+B6 -> 1212.754 | C34: =+C27+C13+C20+C6 -> 1323.849 | D34: =+D27+D13+D20+D6 -> 1795.92 | E34: =+E27+E13+E20+E6 -> 2220.978 | F34: =+F27+F13+F20+F6 -> 1979.906 | G34: =+G27+G13+G20+G6 -> 1861.072 | H34: =+H27+H13+H20+H6 -> 1335.29 | I34: =+I27+I13+I20+I6 -> 1250.751 | J34: =+SUM(B34:I34) -> 12980.52 | K34: =+K27+K13+K20+K6 -> 937.222 | L34: =+L27+L13+L20+L6 -> 1402.215 | M34: =+M27+M13+M20+M6 -> 1859.09 | N34: =+N27+N13+N20+N6 -> 0 | O34: =+O27+O13+O20+O6 -> 0 | P34: =+P27+P13+P20+P6 -> 0 | Q34: =+J34+SUM(K34:P34) -> 17179.047 | R34: =+R27+R13+R20+R6 -> 0 | S34: =+S27+S13+S20+S6 -> 0 | T34: =+T27+T13+T20+T6 -> 0 | U34: =+U27+U13+U20+U6 -> 0 | V34: =+V27+V13+V20+V6 -> 0 | W34: =+W27+W13+W20+W6 -> 0 | X34: =+X27+X13+X20+X6 -> 0 | Y34: =+Q34+SUM(R34:X34) -> 17179.047 | Z34: =+Z27+Z13+Z20+Z6 -> 0 | AA34: =+AA27+AA13+AA20+AA6 -> 0 | AB34: =+AB27+AB13+AB20+AB6 -> 0 | AC34: =+AC27+AC13+AC20+AC6 -> 0 | AD34: =+AD27+AD13+AD20+AD6 -> 0 | AE34: =+AE27+AE13+AE20+AE6 -> 0 | AF34: =+AF27+AF13+AF20+AF6 -> 0 | AG34: =+Y34+SUM(Z34:AF34) -> 17179.047 | AH34: =+AH27+AH13+AH20+AH6 -> 0 | AI34: =+AI27+AI13+AI20+AI6 -> 0 | AJ34: =+AJ27+AJ13+AJ20+AJ6 -> 0 | AK34: =+AG34+SUM(AH34:AJ34) -> 17179.047 | AL34: =+AK6+AK13+AK20+AK27 -> 17179.047
